Workbook
Name \1: #REF!
Name \A: #REF!
Name \b: #N/A
Name \c: #N/A
Name \f: #N/A
Name \g: #REF!
Name \LL: #REF!
Name \O: #REF!
Name \p: #REF!
Name \PP: #N/A
Name \q: #REF!
Name \R: #REF!
Name \w: #REF!
Name \x: #REF!
Name _?쾴?: #REF!
Name _?쾴?_?: #REF!
Name _?쾴?___P: #REF!
Name _?쾴?_T: #REF!
Name __?쾴?: #REF!
Name __?쾴?_?: #REF!
Name __?쾴?___P: #REF!
Name __?쾴?_T: #REF!
Name ___?쾴?: #REF!
Name ___?쾴?_?: #REF!
Name ___?쾴?___P: #REF!
Name ___?쾴?_T: #REF!
Name ____?쾴?: #REF!
Name ____?쾴?_?: #REF!
Name ____?쾴?___P: #REF!
Name ____?쾴?_T: #REF!
Name _____?쾴?: #REF!
Name _____?쾴?_?: #REF!
Name _____?쾴?___P: #REF!
Name _____?쾴?_T: #REF!
Name ______?쾴?: #REF!
Name ______?쾴?_?: #REF!
Name ______?쾴?___P: #REF!
Name ______?쾴?_T: #REF!
Name _______?쾴?: #REF!
Name _______?쾴?_?: #REF!
Name _______?쾴?___P: #REF!
Name _______?쾴?_T: #REF!
Name ________?쾴?: #REF!
Name ________?쾴?_?: #REF!
Name ________?쾴?___P: #REF!
Name ________?쾴?_T: #REF!
Name _________?쾴?: #REF!
Name _________?쾴?_?: #REF!
Name _________?쾴?___P: #REF!
Name _________?쾴?_T: #REF!
Name ___________?쾴?: #REF!
Name ___________?쾴?_?: #REF!
Name ___________?쾴?___P: #REF!
Name ___________?쾴?_T: #REF!
Name ____________?쾴?: #REF!
Name ____________?쾴?_?: #REF!
Name ____________?쾴?___P: #REF!
Name ____________?쾴?_T: #REF!
Name ______________?쾴?: #REF!
Name ______________?쾴?_?: #REF!

Sheet OP
A2: OBRAS PROVISIONALES
A4: Presupuesto | B4: =#REF! -> #REF!
A5: Subpresupuesto | B5: =$A$2 -> OBRAS PROVISIONALES
A6: Cliente | B6: =#REF! -> #REF!
A7: Lugar | B7: =#REF! -> #REF!
A8: Fecha | B8: =#REF! -> #REF!
A12: ITEM | B12: DESCRIPCION | C12: UND | D12: CANTIDAD | E12: P.U. (PEN) | F12: P.U. (USD) | G12: P.U. (TOTAL) | H12: PRECIO PARCIAL (PEN) | I12: PRECIO PARCIAL (USD) | J12: PRECIO TOTAL (PEN) | K12: TOTAL
A13: 01 | B13: OBRAS PROVISIONALES, TRABAJOS PRELIMINARES
A14: =A13+0.01 -> 1.01 | B14: CONSTRUCCIONES PROVISIONALES | G14: =IFERROR(IF(D14=0,"",(E14+F14*TC)),"") | H14: =IFERROR(IF(D14=0,"",$D14*E14),"") | I14: =IFERROR(IF(D14=0,"",$D14*F14),"") | J14: =IFERROR(IF(D14<>0,(D14*G14)," "),0) | K14: =SUM(J15:J44) -> #REF!
A15: =GG!A13+0.0001 -> 12.0101 | B15: OFICINA DE OBRA PARA CONTRATISTA | C15: glb | D15: 1 | E15: 8315.79 | G15: =IFERROR(IF(D15=0,"",(E15+F15*TC)),"") | H15: =+ROUND(D15*E15,2) -> 8315.79 | I15: =+ROUND(D15*F15,2) -> 0 | J15: =+ROUND(H15+I15*TC,2) -> #REF!
A16: =A15+0.0001 -> 12.0102 | B16: OFICINA DE OBRA PARA SUPERVISIÓN | C16: glb | D16: 0 | G16: =IFERROR(IF(D16=0,"",(E16+F16*TC)),"") | H16: =+ROUND(D16*E16,2) -> 0 | I16: =+ROUND(D16*F16,2) -> 0 | J16: =+ROUND(H16+I16*TC,2) -> #REF!
A17: =A16+0.0001 -> 12.0103 | B17: OFICINA SALA DE REUNIONES | C17: glb | D17: 1 | E17: 3246.71 | G17: =IFERROR(IF(D17=0,"",(E17+F17*TC)),"") | H17: =+ROUND(D17*E17,2) -> 3246.71 | I17: =+ROUND(D17*F17,2) -> 0 | J17: =+ROUND(H17+I17*TC,2) -> #REF!
A18: =A17+0.0001 -> 12.0104 | B18: ALMACEN DE OBRA | C18: glb | D18: 1 | E18: 10690.24 | G18: =IFERROR(IF(D18=0,"",(E18+F18*TC)),"") | H18: =+ROUND(D18*E18,2) -> 10690.24 | I18: =+ROUND(D18*F18,2) -> 0 | J18: =+ROUND(H18+I18*TC,2) -> #REF!
A19: =A18+0.0001 -> 12.0105 | B19: COMEDOR PERSONAL OBRERO | C19: glb | D19: 1 | E19: 6229.18 | G19: =IFERROR(IF(D19=0,"",(E19+F19*TC)),"") | H19: =+ROUND(D19*E19,2) -> 6229.18 | I19: =+ROUND(D19*F19,2) -> 0 | J19: =+ROUND(H19+I19*TC,2) -> #REF!
A20: =A19+0.0001 -> 12.0106 | B20: VESTUARIO PARA OBREROS | C20: glb | D20: 1 | E20: 6906.27 | G20: =IFERROR(IF(D20=0,"",(E20+F20*TC)),"") | H20: =+ROUND(D20*E20,2) -> 6906.27 | I20: =+ROUND(D20*F20,2) -> 0 | J20: =+ROUND(H20+I20*TC,2) -> #REF!
A21: =A20+0.0001 -> 12.0107 | B21: TRASLADO DE CAMPAMENTO PROVISIONAL A SOTANOS | C21: und | D21: 1 | E21: 5282.76 | G21: =IFERROR(IF(D21=0,"",(E21+F21*TC)),"") | H21: =+ROUND(D21*E21,2) -> 5282.76 | I21: =+ROUND(D21*F21,2) -> 0 | J21: =+ROUND(H21+I21*TC,2) -> #REF!
A22: =A21+0.0001 -> 12.0108 | B22: CASETA PARA GUARDIANIA | C22: glb | D22: 1 | E22: 850 | G22: =IFERROR(IF(D22=0,"",(E22+F22*TC)),"") | H22: =+ROUND(D22*E22,2) -> 850 | I22: =+ROUND(D22*F22,2) -> 0 | J22: =+ROUND(H22+I22*TC,2) -> #REF!
A23: =A22+0.0001 -> 12.0109 | B23: BAÑOS PORTATILES DE OBRA PARA PERSONAL STAFF Y SUPERVISION COMPARTIDOS | C23: mes | D23: 10.5 | E23: 780 | G23: =IFERROR(IF(D23=0,"",(E23+F23*TC)),"") | H23: =+ROUND(D23*E23,2) -> 8190 | I23: =+ROUND(D23*F23,2) -> 0 | J23: =+ROUND(H23+I23*TC,2) -> #REF!
A24: =A23+0.0001 -> 12.011 | B24: CONSTRUCCION DE SSHH (1ER NIVEL) | C24: glb | D24: 1 | E24: 9936.3 | G24: =IFERROR(IF(D24=0,"",(E24+F24*TC)),"") | H24: =+ROUND(D24*E24,2) -> 9936.3 | I24: =+ROUND(D24*F24,2) -> 0 | J24: =+ROUND(H24+I24*TC,2) -> #REF!
A25: =A24+0.0001 -> 12.0111 | B25: SSHH PORTATILES PARA OBREROS | C25: glb | D25: 1 | E25: 7590 | G25: =IFERROR(IF(D25=0,"",(E25+F25*TC)),"") | H25: =+ROUND(D25*E25,2) -> 7590 | I25: =+ROUND(D25*F25,2) -> 0 | J25: =+ROUND(H25+I25*TC,2) -> #REF!
A26: =A25+0.0001 -> 12.0112 | B26: DUCHAS PORTATILES PARA OBREROS | C26: mes | D26: 10.5 | E26: 560 | G26: =IFERROR(IF(D26=0,"",(E26+F26*TC)),"") | H26: =+ROUND(D26*E26,2) -> 5880 | I26: =+ROUND(D26*F26,2) -> 0 | J26: =+ROUND(H26+I26*TC,2) -> #REF!
A27: =A26+0.0001 -> 12.0113 | B27: ALQUILER LAVAMANOS PARA OBREROS | C27: mes | D27: 13.5 | E27: 660 | G27: =IFERROR(IF(D27=0,"",(E27+F27*TC)),"") | H27: =+ROUND(D27*E27,2) -> 8910 | I27: =+ROUND(D27*F27,2) -> 0 | J27: =+ROUND(H27+I27*TC,2) -> #REF!
A28: =A27+0.0001 -> 12.0114 | B28: ESCUADRAS METALICAS PARA LAS OFICINAS EN MUROS ANCLADOS | F28: 0 | G28: =IFERROR(IF(D28=0,"",(E28+F28*TC)),"") | H28: =+ROUND(D28*E28,2) -> 0 | I28: =+ROUND(D28*F28,2) -> 0 | J28: =+ROUND(H28+I28*TC,2) -> #REF!
A29: =A28+0.0001 -> 12.0115 | B29: ALQUILER DE ESCUADRAS METÁLICAS | C29: ml | D29: 52 | E29: 712.5 | G29: =IFERROR(IF(D29=0,"",(E29+F29*TC)),"") | H29: =+ROUND(D29*E29,2) -> 37050 | I29: =+ROUND(D29*F29,2) -> 0 | J29: =+ROUND(H29+I29*TC,2) -> #REF!
A30: =A29+0.0001 -> 12.0116 | B30: INSTALACIÓN DE ESCUADRAS METÁLICAS | C30: ml | D30: 52 | E30: 118.82 | G30: =IFERROR(IF(D30=0,"",(E30+F30*TC)),"") | H30: =+ROUND(D30*E30,2) -> 6178.64 | I30: =+ROUND(D30*F30,2) -> 0 | J30: =+ROUND(H30+I30*TC,2) -> #REF!
A31: =A30+0.0001 -> 12.0117 | B31: PERNOS DE EXPANSIÓN | C31: und | D31: 416 | F31: 8.7 | G31: =IFERROR(IF(D31=0,"",(E31+F31*TC)),"") | H31: =+ROUND(D31*E31,2) -> 0 | I31: =+ROUND(D31*F31,2) -> 3619.2 | J31: =+ROUND(H31+I31*TC,2) -> #REF!
A32: =A31+0.0001 -> 12.0118 | B32: DESISTALACION DE ESCUADRAS METÁLICAS | C32: ml | D32: 52 | E32: 46.66 | G32: =IFERROR(IF(D32=0,"",(E32+F32*TC)),"") | H32: =+ROUND(D32*E32,2) -> 2426.32 | I32: =+ROUND(D32*F32,2) -> 0 | J32: =+ROUND(H32+I32*TC,2) -> #REF!
A33: =A32+0.0001 -> 12.0119 | B33: MADERA CACHIMBO 2" X 12" X 10´, SOBRE ESCUADRAS METÁLICAS | C33: und | D33: 112 | E33: 127.5 | G33: =IFERROR(IF(D33=0,"",(E33+F33*TC)),"") | H33: =+ROUND(D33*E33,2) -> 14280 | I33: =+ROUND(D33*F33,2) -> 0 | J33: =+ROUND(H33+I33*TC,2) -> #REF!
A34: =A33+0.0001 -> 12.012 | B34: INSTALACIÓN Y DESISTALACIÓN DE MADERA, SOBRE ESCUADRAS METÁLICAS | C34: ml | D34: 52 | E34: 87.76 | G34: =IFERROR(IF(D34=0,"",(E34+F34*TC)),"") | H34: =+ROUND(D34*E34,2) -> 4563.52 | I34: =+ROUND(D34*F34,2) -> 0 | J34: =+ROUND(H34+I34*TC,2) -> #REF!
A35: =A34+0.0001 -> 12.0121 | B35: VENTILACION PROVISIONAL EN SOTANOS | C35: glb | D35: 1 | E35: 7350 | G35: =IFERROR(IF(D35=0,"",(E35+F35*TC)),"") | H35: =+ROUND(D35*E35,2) -> 7350 | I35: =+ROUND(D35*F35,2) -> 0 | J35: =+ROUND(H35+I35*TC,2) -> #REF!
A36: =A35+0.0001 -> 12.0122 | B36: PROTECCIÓN DE VECINOS CON MALLA RASCHEL (ENCAPSULADO) | C36: glb | D36: 1 | E36: 28599.53 | G36: =IFERROR(IF(D36=0,"",(E36+F36*TC)),"") | H36: =+ROUND(D36*E36,2) -> 28599.53 | I36: =+ROUND(D36*F36,2) -> 0 | J36: =+ROUND(H36+I36*TC,2) -> #REF!
A37: =A36+0.0001 -> 12.0123 | B37: RENOVACIÓN DE MALLA RACHEL | C37: glb | D37: 0 | E37: 3324.88 | G37: =IFERROR(IF(D37=0,"",(E37+F37*TC)),"") | H37: =+ROUND(D37*E37,2) -> 0 | I37: =+ROUND(D37*F37,2) -> 0 | J37: =+ROUND(H37+I37*TC,2) -> #REF!
A38: =A37+0.0001 -> 12.0124 | B38: CERCO METALICO DE OBRA | C38: ml | D38: 0 | E38: 475 | G38: =IFERROR(IF(D38=0,"",(E38+F38*TC)),"") | H38: =+ROUND(D38*E38,2) -> 0 | I38: =+ROUND(D38*F38,2) -> 0 | J38: =+ROUND(H38+I38*TC,2) -> #REF!
A39: =A38+0.0001 -> 12.0125 | B39: BASTIDORES METALICOS PARA FIJAR MALLA DE PROTECCION + MALLA RACHELL | C39: ml | D39: 0 | E39: 98.89 | G39: =IFERROR(IF(D39=0,"",(E39+F39*TC)),"") | H39: =+ROUND(D39*E39,2) -> 0 | I39: =+ROUND(D39*F39,2) -> 0 | J39: =+ROUND(H39+I39*TC,2) -> #REF!
A40: =A39+0.0001 -> 12.0126 | B40: MANTENIMIENTO A MITAD DE OBRA DE CERCO PROVISIONAL DE OBRA | C40: ml | D40: 0 | E40: 74.4 | G40: =IFERROR(IF(D40=0,"",(E40+F40*TC)),"") | H40: =+ROUND(D40*E40,2) -> 0 | I40: =+ROUND(D40*F40,2) -> 0 | J40: =+ROUND(H40+I40*TC,2) -> #REF!
A41: =A40+0.0001 -> 12.0127 | B41: DESMONTAJE DE CERCO PROVISIONAL DE OBRA | C41: ml | D41: 26 | E41: 80.7 | G41: =IFERROR(IF(D41=0,"",(E41+F41*TC)),"") | H41: =+ROUND(D41*E41,2) -> 2098.2 | I41: =+ROUND(D41*F41,2) -> 0 | J41: =+ROUND(H41+I41*TC,2) -> #REF!
A42: =A41+0.0001 -> 12.0128 | B42: PROTECCION PERIMETRAL INICIAL VERTICAL DE VECINOS | C42: glb | D42: 1 | E42: 3250 | G42: =IFERROR(IF(D42=0,"",(E42+F42*TC)),"") | H42: =+ROUND(D42*E42,2) -> 3250 | I42: =+ROUND(D42*F42,2) -> 0 | J42: =+ROUND(H42+I42*TC,2) -> #REF!
A43: =A42+0.0001 -> 12.0129 | B43: PROTECCION HORIZONTAL INICIAL DE VECINOS | C43: glb | D43: 1 | E43: 3000 | G43: =IFERROR(IF(D43=0,"",(E43+F43*TC)),"") | H43: =+ROUND(D43*E43,2) -> 3000 | I43: =+ROUND(D43*F43,2) -> 0 | J43: =+ROUND(H43+I43*TC,2) -> #REF!
A44: =A43+0.0001 -> 12.013 | B44: CARTEL DE OBRA (INC CARTEL PUBLICITARIO EN TORRE GRUA) | C44: glb | D44: 1 | E44: 1400 | G44: =IFERROR(IF(D44=0,"",(E44+F44*TC)),"") | H44: =+ROUND(D44*E44,2) -> 1400 | I44: =+ROUND(D44*F44,2) -> 0 | J44: =+ROUND(H44+I44*TC,2) -> #REF!
A45: =A14+0.01 -> 1.02 | B45: CAMPAMENTO Y SALA DE VENTAS CLIENTE - NO SE CONSIDERA | F45: 0 | K45: =SUM(J46:J49) -> #REF!
...

Sheet SEG
A2: SEGURIDAD Y SALUD
A4: Presupuesto | B4: =#REF! -> #REF!
A5: Subpresupuesto | B5: =$A$2 -> SEGURIDAD Y SALUD
A6: Cliente | B6: =#REF! -> #REF!
A7: Lugar | B7: =#REF! -> #REF!
A8: Fecha | B8: =#REF! -> #REF!
A10: ITEM | B10: DESCRIPCION | C10: UND | D10: CANTIDAD | E10: P.U. (PEN) | F10: PARCIAL | G10: TOTAL
A11: 02 | B11: SEGURIDAD Y SALUD
A12: =A11+0.01 -> 2.01 | B12: ELABORACIÓN, IMPLEMENTACIÓN Y ADMINISTRACIÓN DEL PLAN DE SEGURIDAD Y SALUD EN EL TRABAJO | G12: =SUM(F13:F20) -> 569835.75
A13: =A12+0.0001 -> 2.0101 | B13: EQUIPOS DE PROTECCION INDIVIDUAL (STAFF Y OBREROS) | C13: glb | D13: 1 | E13: 145377.82 | F13: =+ROUND(D13*E13,2) -> 145377.82
A14: =A13+0.0001 -> 2.0102 | B14: EQUIPOS DE PROTECCION COLECTIVA | C14: glb | D14: 1 | E14: 162292.96 | F14: =+ROUND(D14*E14,2) -> 162292.96
A15: =A14+0.0001 -> 2.0103 | B15: MONITOREO DE AIRE Y RUIDO EN LA CONSTRUCCION (@ 6 MESES) | C15: und | D15: 4 | E15: 900 | F15: =+ROUND(D15*E15,2) -> 3600
A16: =A15+0.0001 -> 2.0104 | B16: CONTROL DE POLVOS EN MOVIMIENTO DE TIERRAS (EXIGENCIA LEED) | C16: mes | D16: 0 | E16: 1505 | F16: =+ROUND(D16*E16,2) -> 0
A17: =A16+0.0001 -> 2.0105 | B17: EXAMEN MÉDICO PRE-OCUPACIONAL | C17: und | D17: 190 | E17: 130 | F17: =+ROUND(D17*E17,2) -> 24700
A18: =A17+0.0001 -> 2.0106 | B18: MALLA ANTICAIDAS (PERIMETRO EDIFICIO) | C18: glb | D18: 1 | E18: 84895.8 | F18: =+ROUND(D18*E18,2) -> 84895.8
A19: =A18+0.0001 -> 2.0107 | B19: MALLA ANTICAIDAS (DUCTO DE ASCENSOR) | C19: glb | D19: 1 | E19: 12734.37 | F19: =+ROUND(D19*E19,2) -> 12734.37
A20: =A19+0.0001 -> 2.0108 | B20: DESVIO DE TRANSITO (02 SEÑALERO x FRENTE) | C20: mes | D20: 20.5 | E20: 6645.6 | F20: =+ROUND(D20*E20,2) -> 136234.8
A21: =A12+0.01 -> 2.02 | B21: PREVENCIONISTAS | G21: =SUM(F22:F24) -> 157853.28
A22: =A21+0.0001 -> 2.0201 | B22: ASISTENTES DE PDR (01) | C22: mes | D22: 20.5 | E22: 4236.96 | F22: =+ROUND(D22*E22,2) -> 86857.68
A23: =A22+0.0001 -> 2.0202 | B23: AYUDANTE DE PDR N°1 (01) | C23: mes | D23: 10 | E23: 3837.6 | F23: =+ROUND(D23*E23,2) -> 38376
A24: =A23+0.0001 -> 2.0203 | B24: AYUDANTE DE PDR N°2 (01) | C24: mes | D24: 8.5 | E24: 3837.6 | F24: =+ROUND(D24*E24,2) -> 32619.6
A25: =A21+0.01 -> 2.03 | B25: SEGURIDAD POLICIAL | G25: =SUM(F26:F27) -> 7857.5
A26: =A25+0.0001 -> 2.0301 | B26: CAMARAS DE SEGURIDAD | C26: glb | D26: 1 | E26: 5500 | F26: =+ROUND(D26*E26,2) -> 5500
A27: =A26+0.0001 -> 2.0302 | B27: SERVICIO MENSUAL MANTENIMIENTO | C27: mes | D27: 20.5 | E27: 115 | F27: =+ROUND(D27*E27,2) -> 2357.5
D28: COSTO DIRECTO | G28: =SUM(G12:G27) -> 735546.53
F30: S10 | G30: 735546.53
G31: =+G28-G30 -> 0

Sheet GG
A2: GASTOS GENERALES
A4: Presupuesto | B4: =#REF! -> #REF!
A5: Subpresupuesto | B5: =A2 -> GASTOS GENERALES
A6: Cliente | B6: =#REF! -> #REF!
A7: Lugar | B7: =#REF! -> #REF!
A8: Fecha | B8: =#REF! -> #REF!
A11: ITEM | B11: DESCRIPCION | C11: UND | D11: CANTIDAD | E11: MESES | F11: PRECIO (PEN) | H11: PARCIAL | I11: TOTAL
A12: 12 | B12: GASTOS GENERALES
A13: =A12+0.01 -> 12.01 | B13: PERSONAL STAFF | I13: =SUM(H14:H24) -> 1627787.2
A14: =A13+0.0001 -> 12.0101 | B14: GERENTE DE PROYECTOS | C14: mes | D14: 1 | E14: 20.5 | F14: 16200 | H14: =+ROUND(D14*E14*F14,2) -> 332100 | J14: =+D14*E14 -> 20.5
A15: =A14+0.0001 -> 12.0102 | B15: INGENIERO RESIDENTE | C15: mes | D15: 1 | E15: 21.5 | F15: 10500 | H15: =+ROUND(D15*E15*F15,2) -> 225750 | J15: =+D15*E15 -> 21.5
A16: =A15+0.0001 -> 12.0103 | B16: INGENIERO DE OFICINA TECNICA | C16: mes | D16: 1 | E16: 21.5 | F16: 10500.004 | H16: =+ROUND(D16*E16*F16,2) -> 225750.09 | J16: =+D16*E16 -> 21.5
A17: =A16+0.0001 -> 12.0104 | B17: INGENIERO DE CAMPO | C17: mes | D17: 1 | E17: 17.5 | F17: 7500 | H17: =+ROUND(D17*E17*F17,2) -> 131250 | J17: =+D17*E17 -> 17.5
A18: =A17+0.0001 -> 12.0105 | B18: INGENIERO DE CALIDAD | C18: mes | D18: 1 | E18: 13.5 | F18: 7500 | H18: =+ROUND(D18*E18*F18,2) -> 101250 | J18: =+D18*E18 -> 13.5
B19: INGENIERO DE CALIDAD JUNIOR | C19: mes | D19: 1 | E19: 7 | F19: 5250 | H19: =+ROUND(D19*E19*F19,2) -> 36750 | J19: =+D19*E19 -> 7
A20: =A18+0.0001 -> 12.0106 | B20: INGENIERO ELECTROMECANICO | C20: mes | D20: 0.5 | E20: 13.5 | F20: 10500.004 | H20: =+ROUND(D20*E20*F20,2) -> 70875.03 | J20: =+D20*E20 -> 6.75
A21: =A20+0.0001 -> 12.0107 | B21: ARQUITECTO DE ACABADOS | C21: mes | D21: 1 | E21: 13.5 | F21: 9000 | H21: =+ROUND(D21*E21*F21,2) -> 121500 | J21: =+D21*E21 -> 13.5
A22: =A21+0.0001 -> 12.0108 | B22: PREVENCIONISTA DE RIEGOS - SUBJEFE DE PDR | C22: mes | D22: 1 | E22: 20.5 | F22: 6750 | H22: =+ROUND(D22*E22*F22,2) -> 138375 | J22: =+D22*E22 -> 20.5
A23: =A22+0.0001 -> 12.0109 | B23: ADMINISTRADOR DE OBRA | C23: mes | D23: 1 | E23: 21.5 | F23: 6491.2603 | H23: =+ROUND(D23*E23*F23,2) -> 139562.1 | J23: =+D23*E23 -> 21.5
A24: =A23+0.0001 -> 12.011 | B24: INGENIERO BIM | C24: mes | D24: 1 | E24: 15.5 | F24: 6750 | H24: =+ROUND(D24*E24*F24,2) -> 104625 | J24: =+D24*E24 -> 15.5
A25: =A13+0.01 -> 12.02 | B25: PERSONAL TECNICO | H25: =+ROUND(D25*E25*F25,2) -> 0 | I25: =SUM(H26:H32) -> 599894.77 | J25: =+D25*E25 -> 0
A26: =A25+0.0001 -> 12.0201 | B26: ASISTENTE (CAMPO/CALIDAD/ARQ) | C26: mes | D26: 2 | E26: 13.5 | F26: 3990 | H26: =+ROUND(D26*E26*F26,2) -> 107730 | J26: =+D26*E26 -> 27
A27: =A26+0.0001 -> 12.0202 | B27: MAESTRO DE OBRA | C27: mes | D27: 1 | E27: 13.5 | F27: 8102.46 | H27: =+ROUND(D27*E27*F27,2) -> 109383.21 | J27: =+D27*E27 -> 13.5
A28: =A27+0.0001 -> 12.0203 | B28: CAPATAZ DE OBRA ESTRUCTURAS | C28: mes | D28: 1 | E28: 6.5 | F28: 6757.92 | H28: =+ROUND(D28*E28*F28,2) -> 43926.48 | J28: =+D28*E28 -> 6.5
A29: =A28+0.0001 -> 12.0204 | B29: CAPATAZ DE OBRA ARQUITECTURA N°1 | C29: mes | D29: 1 | E29: 11.5 | F29: 6757.92 | H29: =+ROUND(D29*E29*F29,2) -> 77716.08 | J29: =+D29*E29 -> 11.5
A30: =A29+0.0001 -> 12.0205 | B30: JEFE DE ALMACEN | C30: mes | D30: 1 | E30: 21.5 | F30: 5586 | H30: =+ROUND(D30*E30*F30,2) -> 120099 | J30: =+D30*E30 -> 21.5
A31: =A30+0.0001 -> 12.0206 | B31: GUARDIAN DE OBRA Y PORTERIA | C31: mes | D31: 1 | E31: 20.5 | F31: 6880 | H31: =+ROUND(D31*E31*F31,2) -> 141040 | J31: =+D31*E31 -> 20.5
A32: =A31+0.0001 -> 12.0207 | B32: VIGILANTE POLICIAL DE CIVIL (TURNO NOCHE) - SERA COBRADO COMO ADICIONAL | C32: mes | D32: 0 | E32: 11 | F32: 6880 | H32: =+ROUND(D32*E32*F32,2) -> 0 | J32: =+D32*E32 -> 0
A33: =A25+0.01 -> 12.03 | B33: EQUIPO DE OFICINA DE LA OBRA | I33: =SUM(H34:H71) -> 67463.62 | J33: =+D33*E33 -> 0
A34: =A33+0.0001 -> 12.0301 | B34: COMPUTADORAS | C34: mes | H34: =SUM(G36:G49) -> 20607.37 | J34: =+D34*E34 -> 0
A35: =A34+0.0001 -> 12.0302 | B35: DISGREGADO DE COMPUTADORAS | J35: =+D35*E35 -> 0
A36: 12.03.02.01 | B36: =+B15 -> INGENIERO RESIDENTE | C36: und | D36: 1 | E36: 21.5 | F36: 92.30625 | G36: =+D36*E36*F36 -> 1984.5844 | J36: =+D36*E36 -> 21.5
A37: 12.03.02.02 | B37: =+B16 -> INGENIERO DE OFICINA TECNICA | C37: und | D37: 1 | E37: 21.5 | F37: 92.30625 | G37: =+D37*E37*F37 -> 1984.5844 | J37: =+D37*E37 -> 21.5
A38: 12.03.02.03 | B38: =+B17 -> INGENIERO DE CAMPO | C38: und | D38: 1 | E38: 17.5 | F38: 92.30625 | G38: =+D38*E38*F38 -> 1615.3594 | J38: =+D38*E38 -> 17.5
A39: 12.03.02.05 | B39: =+B18 -> INGENIERO DE CALIDAD | C39: und | D39: 1 | E39: 13.5 | F39: 92.30625 | G39: =+D39*E39*F39 -> 1246.1344 | J39: =+D39*E39 -> 13.5
B40: INGENIERO DE CALIDAD JUNIOR | C40: und | D40: 1 | E40: 7 | F40: 92.30625 | G40: =+D40*E40*F40 -> 646.14375 | J40: =+D40*E40 -> 7
A41: 12.03.02.07 | B41: =+B20 -> INGENIERO ELECTROMECANICO | C41: und | D41: 0.5 | E41: 13.5 | F41: 92.30625 | G41: =+D41*E41*F41 -> 623.06719 | J41: =+D41*E41 -> 6.75
A42: 12.03.02.09 | B42: =+B21 -> ARQUITECTO DE ACABADOS | C42: und | D42: 1 | E42: 13.5 | F42: 92.30625 | G42: =+D42*E42*F42 -> 1246.1344 | J42: =+D42*E42 -> 13.5
A43: 12.03.02.12 | B43: =+B22 -> PREVENCIONISTA DE RIEGOS - SUBJEFE DE PDR | C43: und | D43: 1 | E43: 20.5 | F43: 92.30625 | G43: =+D43*E43*F43 -> 1892.2781 | J43: =+D43*E43 -> 20.5
A44: 12.03.02.15 | B44: =+B23 -> ADMINISTRADOR DE OBRA | C44: und | D44: 1 | E44: 21.5 | F44: 92.30625 | G44: =+D44*E44*F44 -> 1984.5844 | J44: =+D44*E44 -> 21.5
...

Sheet EST SOTANO
C2: ESTRUCTURAS SÓTANOS
C4: Presupuesto | D4: =OP!$B$4 -> #REF!
C5: Subpresupuesto | D5: =+$C$2 -> ESTRUCTURAS SÓTANOS
C6: Cliente | D6: =OP!$B$6 -> #REF!
C7: Lugar | D7: =OP!$B$7 -> #REF!
C8: Fecha | D8: =#REF! -> #REF!
C10: ITEM | D10: DESCRIPCION | E10: UND | F10: METRADO | G10: P.U. (PEN) | H10: P.U. (USD) | I10: P.U. TOTAL (PEN) | J10: PRECIO PARCIAL (PEN) | K10: PRECIO PARCIAL (USD) | L10: PRECIO TOTAL (PEN) | M10: TOTAL
C11: 03 | D11: =$C$2 -> ESTRUCTURAS SÓTANOS
C12: =C11+0.01 -> 3.01 | D12: OBRAS PRELIMINARES MOVIMIENTOS DE TIERRA | I12: =IFERROR(IF(E12<>0,G12+H12*TC," ")," ") | J12: =IFERROR(IF($F12=0,"",$F12*G12),"") | K12: =IFERROR(IF($F12=0,"",$F12*H12),"") | L12: =IFERROR(IF(F12<>0,(F12*I12)," "),0) | M12: =SUM(J12:J17)+SUM(K12:K17)*TC -> #REF!
C13: =C12+0.0001 -> 3.0101 | D13: MOVILIZACION Y DESMOVILIZACION DE EQUIPOS MOVIMIENTO TIERRAS | E13: glb | F13: 1 | G13: 6000 | I13: =+ROUND(G13+H13*TC,2) -> #REF! | J13: =+ROUND(F13*G13,2) -> 6000 | K13: =+ROUND(F13*H13,2) -> 0 | L13: =+ROUND(J13+K13*TC,2) -> #REF!
C14: =C13+0.0001 -> 3.0102 | D14: EXTRACCION DE 2 MAQUINAS EXCAVADORAS (IZAJE) | E14: glb | F14: 2 | G14: 6000 | I14: =+ROUND(G14+H14*TC,2) -> #REF! | J14: =+ROUND(F14*G14,2) -> 12000 | K14: =+ROUND(F14*H14,2) -> 0 | L14: =+ROUND(J14+K14*TC,2) -> #REF!
C15: =C14+0.0001 -> 3.0103 | D15: INSTALACION Y DESISTALACION DE PLATAFORMA | E15: glb | F15: 1 | G15: 11000 | I15: =+ROUND(G15+H15*TC,2) -> #REF! | J15: =+ROUND(F15*G15,2) -> 11000 | K15: =+ROUND(F15*H15,2) -> 0 | L15: =+ROUND(J15+K15*TC,2) -> #REF!
C16: =C15+0.0001 -> 3.0104 | D16: EXTRACCION DE EQUIPOS PERFORACION CON GRUAS | E16: glb | F16: 4 | H16: 720 | I16: =+ROUND(G16+H16*TC,2) -> #REF! | J16: =+ROUND(F16*G16,2) -> 0 | K16: =+ROUND(F16*H16,2) -> 2880 | L16: =+ROUND(J16+K16*TC,2) -> #REF!
C17: =C16+0.0001 -> 3.0105 | D17: CONTROL DE POLVOS (AGUA EN CISTERNA) | E17: vje | F17: 13 | G17: 340 | I17: =+ROUND(G17+H17*TC,2) -> #REF! | J17: =+ROUND(F17*G17,2) -> 4420 | K17: =+ROUND(F17*H17,2) -> 0 | L17: =+ROUND(J17+K17*TC,2) -> #REF!
C18: =C12+0.01 -> 3.02 | D18: MOVIMIENTO DE TIERRAS | M18: =SUM(J18:J44)+SUM(K18:K44)*TC -> #REF!
C19: =C18+0.0001 -> 3.0201 | D19: EXCAVACIÓN Y ELIMINACIÓN MASIVA POR NIVEL
C20: =C19+0.000001 -> 3.020101 | D20: CORTE Y ELIMINACION DE +0.00 a -3.57 (SOTANO 01) | E20: m3 | F20: 2878.06 | G20: 23 | I20: =+ROUND(G20+H20*TC,2) -> #REF! | J20: =+ROUND(F20*G20,2) -> 66195.38 | K20: =+ROUND(F20*H20,2) -> 0 | L20: =+ROUND(J20+K20*TC,2) -> #REF!
C21: =C20+0.000001 -> 3.020102 | D21: CORTE Y ELIMINACION DE -3.57 a -6.38 (SOTANO 02) | E21: m3 | F21: 2265.37 | G21: 24 | I21: =+ROUND(G21+H21*TC,2) -> #REF! | J21: =+ROUND(F21*G21,2) -> 54368.88 | K21: =+ROUND(F21*H21,2) -> 0 | L21: =+ROUND(J21+K21*TC,2) -> #REF!
C22: =C21+0.000001 -> 3.020103 | D22: CORTE Y ELIMINACION DE -6.38 a -9.08 (SOTANO 03) | E22: m3 | F22: 2176.69 | G22: 25 | I22: =+ROUND(G22+H22*TC,2) -> #REF! | J22: =+ROUND(F22*G22,2) -> 54417.25 | K22: =+ROUND(F22*H22,2) -> 0 | L22: =+ROUND(J22+K22*TC,2) -> #REF!
C23: =C22+0.000001 -> 3.020104 | D23: CORTE Y ELIMINACION DE -9.08 a -11.78 (SOTANO 04) | E23: m3 | F23: 2176.69 | G23: 26 | I23: =+ROUND(G23+H23*TC,2) -> #REF! | J23: =+ROUND(F23*G23,2) -> 56593.94 | K23: =+ROUND(F23*H23,2) -> 0 | L23: =+ROUND(J23+K23*TC,2) -> #REF!
C24: =C23+0.000001 -> 3.020105 | D24: CORTE Y ELIMINACION DE -11.78 a -14.48 (SOTANO 05) | E24: m3 | F24: 2176.69 | G24: 27 | I24: =+ROUND(G24+H24*TC,2) -> #REF! | J24: =+ROUND(F24*G24,2) -> 58770.63 | K24: =+ROUND(F24*H24,2) -> 0 | L24: =+ROUND(J24+K24*TC,2) -> #REF!
C25: =C24+0.000001 -> 3.020106 | D25: CORTE Y ELIMINACION DE -14.48 a -17.84 (SOTANO 06) CON GRUA Y BALDE | E25: m3 | F25: 1918.76 | G25: 40 | I25: =+ROUND(G25+H25*TC,2) -> #REF! | J25: =+ROUND(F25*G25,2) -> 76750.4 | K25: =+ROUND(F25*H25,2) -> 0 | L25: =+ROUND(J25+K25*TC,2) -> #REF!
C26: =C19+0.0001 -> 3.0202 | D26: EXCAVACIÓN Y ELIMINACIÓN LOCALIZADA
C27: =C26+0.000001 -> 3.020201 | D27: EXCAVACION Y ELIIMINACION DE ZAPATAS, FALSAS ZAPATAS Y CIMIENTOS (N -20.60) | E27: m3 | F27: 783.45 | G27: 40 | I27: =+ROUND(G27+H27*TC,2) -> #REF! | J27: =+ROUND(F27*G27,2) -> 31338 | K27: =+ROUND(F27*H27,2) -> 0 | L27: =+ROUND(J27+K27*TC,2) -> #REF!
C28: =C27+0.000001 -> 3.020202 | D28: EXCAVACION Y ELIIMINACION DE CISTERNA Y CUARTO DE BOMBAS (N -19.7) | E28: m3 | F28: 993.48 | G28: 40 | I28: =+ROUND(G28+H28*TC,2) -> #REF! | J28: =+ROUND(F28*G28,2) -> 39739.2 | K28: =+ROUND(F28*H28,2) -> 0 | L28: =+ROUND(J28+K28*TC,2) -> #REF!
C29: =C28+0.000001 -> 3.020203 | D29: EXCAVACION LOCALIZADA PARA VIGAS DE CIMENTACION | E29: m3 | F29: 7.56 | G29: 38.75 | I29: =+ROUND(G29+H29*TC,2) -> #REF! | J29: =+ROUND(F29*G29,2) -> 292.95 | K29: =+ROUND(F29*H29,2) -> 0 | L29: =+ROUND(J29+K29*TC,2) -> #REF!
C30: =C29+0.000001 -> 3.020204 | D30: EXCAVACION LOCALIZADA PARA CIMIENTOS (BATEA DE CIMENTACION) | E30: m3 | F30: 13.36 | G30: 38.75 | I30: =+ROUND(G30+H30*TC,2) -> #REF! | J30: =+ROUND(F30*G30,2) -> 517.7 | K30: =+ROUND(F30*H30,2) -> 0 | L30: =+ROUND(J30+K30*TC,2) -> #REF!
C31: =C30+0.000001 -> 3.020205 | D31: EXCAVACION LOCALIZADA PARA POZO SUMIDERO Y TRAMPA DE GRASA | E31: m3 | F31: 6.62 | G31: 38.75 | I31: =+ROUND(G31+H31*TC,2) -> #REF! | J31: =+ROUND(F31*G31,2) -> 256.53 | K31: =+ROUND(F31*H31,2) -> 0 | L31: =+ROUND(J31+K31*TC,2) -> #REF!
C32: =C31+0.000001 -> 3.020206 | D32: ACARREO Y ELIMINACION DE MATERIAL EXCEDENTE | E32: m3 | F32: 35.8 | G32: 38.08 | I32: =+ROUND(G32+H32*TC,2) -> #REF! | J32: =+ROUND(F32*G32,2) -> 1363.26 | K32: =+ROUND(F32*H32,2) -> 0 | L32: =+ROUND(J32+K32*TC,2) -> #REF!
C33: =C26+0.0001 -> 3.0203 | D33: ELIMINACIÓN DE CIMENTACIÓN EXISTENTE (NO SE CONSIDERA)
C34: =C33+0.000001 -> 3.020301 | D34: DEMOLICIÓN DE CIMENTACIÓN DE VECINOS | E34: ml | F34: 0 | G34: 80 | I34: =+ROUND(G34+H34*TC,2) -> #REF! | J34: =+ROUND(F34*G34,2) -> 0 | K34: =+ROUND(F34*H34,2) -> 0 | L34: =+ROUND(J34+K34*TC,2) -> #REF!
C35: =C34+0.000001 -> 3.020302 | D35: ELIMINACIÓN DE CIMENTACIÓN | E35: m3 | F35: 0 | G35: 35 | I35: =+ROUND(G35+H35*TC,2) -> #REF! | J35: =+ROUND(F35*G35,2) -> 0 | K35: =+ROUND(F35*H35,2) -> 0 | L35: =+ROUND(J35+K35*TC,2) -> #REF!
C36: =C33+0.0001 -> 3.0204 | D36: RELLENO Y COMPACTACIÓN
C37: =C36+0.000001 -> 3.020401 | D37: RELLENO COMPACTADO CON MATERIAL PROPIO | E37: m3 | F37: 144.49 | G37: 52 | I37: =+ROUND(G37+H37*TC,2) -> #REF! | J37: =+ROUND(F37*G37,2) -> 7513.48 | K37: =+ROUND(F37*H37,2) -> 0 | L37: =+ROUND(J37+K37*TC,2) -> #REF!
C38: =C37+0.000001 -> 3.020402 | D38: RELLENO BAJO RAMPA CON MATERIAL PROPIO | E38: m3 | F38: 13.25 | G38: 52 | I38: =+ROUND(G38+H38*TC,2) -> #REF! | J38: =+ROUND(F38*G38,2) -> 689 | K38: =+ROUND(F38*H38,2) -> 0 | L38: =+ROUND(J38+K38*TC,2) -> #REF!
C39: =C36+0.0001 -> 3.0205 | D39: NIVELACIÓN, APISONADO Y BASE DE AFIRMADO | I39: =+ROUND(G39+H39*TC,2) -> #REF! | J39: =+ROUND(F39*G39,2) -> 0 | K39: =+ROUND(F39*H39,2) -> 0 | L39: =+ROUND(J39+K39*TC,2) -> #REF!
C40: =C39+0.000001 -> 3.020501 | D40: NIVELACION Y COMPACTACION DE SUBRASANTE | E40: m2 | F40: 698.47 | G40: 6.39 | I40: =+ROUND(G40+H40*TC,2) -> #REF! | J40: =+ROUND(F40*G40,2) -> 4463.22 | K40: =+ROUND(F40*H40,2) -> 0 | L40: =+ROUND(J40+K40*TC,2) -> #REF!
C41: =C40+0.000001 -> 3.020502 | D41: BASE DE AFIRMADO COMPACTADO, E=15CM (conforme a EMS) | E41: m2 | F41: 698.47 | G41: 38.21 | I41: =+ROUND(G41+H41*TC,2) -> #REF! | J41: =+ROUND(F41*G41,2) -> 26688.54 | K41: =+ROUND(F41*H41,2) -> 0 | L41: =+ROUND(J41+K41*TC,2) -> #REF!
C42: =C39+0.0001 -> 3.0206 | D42: OTROS | I42: =+ROUND(G42+H42*TC,2) -> #REF! | J42: =+ROUND(F42*G42,2) -> 0 | K42: =+ROUND(F42*H42,2) -> 0 | L42: =+ROUND(J42+K42*TC,2) -> #REF!
C43: =C42+0.000001 -> 3.020601 | D43: ALQUILER DE EXCAVADORA MOVIMIENTO DE DADOS, RAMPA, ETC | E43: hm | F43: 550 | G43: 250 | I43: =+ROUND(G43+H43*TC,2) -> #REF! | J43: =+ROUND(F43*G43,2) -> 137500 | K43: =+ROUND(F43*H43,2) -> 0 | L43: =+ROUND(J43+K43*TC,2) -> #REF!
...

Sheet EST TORRE
C2: ESTRUCTURAS TORRE
C4: Presupuesto | D4: =#REF! -> #REF!
C5: Subpresupuesto | D5: =+$C$2 -> ESTRUCTURAS TORRE
C6: Cliente | D6: =#REF! -> #REF!
C7: Lugar | D7: =#REF! -> #REF!
C8: Fecha | D8: =#REF! -> #REF!
C10: ITEM | D10: DESCRIPCION | E10: UND | F10: METRADO | G10: P.U. (PEN) | H10: P.U. (USD) | I10: P.U. TOTAL (PEN) | J10: PRECIO PARCIAL (PEN) | K10: PRECIO PARCIAL (USD) | L10: PRECIO TOTAL (PEN) | M10: TOTAL
C11: 04 | D11: =$C$2 -> ESTRUCTURAS TORRE
C12: =C11+0.01 -> 4.01 | D12: CONCRETO ARMADO | I12: =IFERROR(IF(E12<>0,G12+H12*TC," ")," ") | L12: =IFERROR(IF(F12<>0,(F12*I12)," "),0) | M12: =SUM(J12:J135)+SUM(K12:K135)*TC -> #REF!
C13: =C12+0.0001 -> 4.0101 | D13: PLACAS | I13: =IFERROR(IF(E13<>0,(G13+H13*TC)," ")," ") | J13: =IFERROR(IF($F13=0,"",$F13*G13),"") | K13: =IFERROR(IF($F13=0,"",$F13*H13),"") | L13: =IFERROR(IF(F13<>0,(F13*I13)," "),0)
A14: C | B14: CASCO TORRE | C14: =C13+0.000001 -> 4.010101 | D14: CONCRETO PREMEZCLADO, CEMENTO TIPO I, PLACAS f'c=210 kg/cm2 | E14: m3 | F14: 276.82 | G14: 383.31 | I14: =+ROUND(G14+H14*TC,2) -> #REF! | J14: =+ROUND(F14*G14,2) -> 106107.87 | K14: =+ROUND(F14*H14,2) -> 0 | L14: =+ROUND(J14+K14*TC,2) -> #REF!
A15: C | B15: CASCO TORRE | C15: =C14+0.000001 -> 4.010102 | D15: CONCRETO PREMEZCLADO, CEMENTO TIPO I, PLACAS f'c=280 kg/cm2 | E15: m3 | F15: 266.26 | G15: 412.45 | I15: =+ROUND(G15+H15*TC,2) -> #REF! | J15: =+ROUND(F15*G15,2) -> 109818.94 | K15: =+ROUND(F15*H15,2) -> 0 | L15: =+ROUND(J15+K15*TC,2) -> #REF!
A16: C | B16: CASCO TORRE | C16: =C15+0.000001 -> 4.010103 | D16: CONCRETO PREMEZCLADO, CEMENTO TIPO I, PLACAS f'c=350 kg/cm2 | E16: m3 | F16: 298.75 | G16: 451.34 | I16: =+ROUND(G16+H16*TC,2) -> #REF! | J16: =+ROUND(F16*G16,2) -> 134837.83 | K16: =+ROUND(F16*H16,2) -> 0 | L16: =+ROUND(J16+K16*TC,2) -> #REF!
A17: C | B17: CASCO TORRE | C17: =C16+0.000001 -> 4.010104 | D17: CONCRETO PREMEZCLADO, CEMENTO TIPO I, PLACAS f'c=420 kg/cm2 | E17: m3 | F17: 329.7 | G17: 466.93 | I17: =+ROUND(G17+H17*TC,2) -> #REF! | J17: =+ROUND(F17*G17,2) -> 153946.82 | K17: =+ROUND(F17*H17,2) -> 0 | L17: =+ROUND(J17+K17*TC,2) -> #REF!
A18: E | C18: =C15+0.000001 -> 4.010103 | D18: ENCOFRADO Y DESENCOFRADO DE MUROS Y PLACAS | E18: m2 | F18: 9197.56 | G18: 43.7 | I18: =+ROUND(G18+H18*TC,2) -> #REF! | J18: =+ROUND(F18*G18,2) -> 401933.37 | K18: =+ROUND(F18*H18,2) -> 0 | L18: =+ROUND(J18+K18*TC,2) -> #REF!
A19: E | C19: =C18+0.000001 -> 4.010104 | D19: ENCOFRADO Y DESENCOFRADO DE MUROS Y PLACAS DOBLE ALTURA | E19: m2 | F19: 650.41 | G19: 51.7 | I19: =+ROUND(G19+H19*TC,2) -> #REF! | J19: =+ROUND(F19*G19,2) -> 33626.2 | K19: =+ROUND(F19*H19,2) -> 0 | L19: =+ROUND(J19+K19*TC,2) -> #REF!
A20: A | C20: =C18+0.000001 -> 4.010104 | D20: ACERO DE REFUERZO FY= 4200 kg/cm2, GRADO 60 | E20: kg | F20: 148445.43 | G20: 1.19 | H20: 0.91 | I20: =+ROUND(G20+H20*TC,2) -> #REF! | J20: =+ROUND(F20*G20,2) -> 176650.06 | K20: =+ROUND(F20*H20,2) -> 135085.34 | L20: =+ROUND(J20+K20*TC,2) -> #REF!
C21: =C20+0.000001 -> 4.010105 | D21: CURADO DE ELEMENTOS ESTRUCTURALES EXPUESTOS | E21: m2 | F21: 9847.97 | G21: 1.44 | I21: =+ROUND(G21+H21*TC,2) -> #REF! | J21: =+ROUND(F21*G21,2) -> 14181.08 | K21: =+ROUND(F21*H21,2) -> 0 | L21: =+ROUND(J21+K21*TC,2) -> #REF!
C22: =C13+0.0001 -> 4.0102 | D22: MUROS P/ JARDINERAS - CORTES TECHO SOTANO 01 | F22: 0
A23: C | B23: CASCO TORRE | C23: =C22+0.000001 -> 4.010201 | D23: CONCRETO PREMEZCLADO, CEMENTO TIPO I, PISCINA f'c=280 kg/cm2 (W/C=0.50).Por procedimiento constructivo | E23: m3 | F23: 0 | G23: 479.16 | I23: =+ROUND(G23+H23*TC,2) -> #REF! | J23: =+ROUND(F23*G23,2) -> 0 | K23: =+ROUND(F23*H23,2) -> 0 | L23: =+ROUND(J23+K23*TC,2) -> #REF!
A24: E | C24: =C23+0.000001 -> 4.010202 | D24: ENCOFRADO Y DESENCOFRADO DE MUROS Y PLACAS | E24: m2 | F24: 0 | G24: 43.7 | I24: =+ROUND(G24+H24*TC,2) -> #REF! | J24: =+ROUND(F24*G24,2) -> 0 | K24: =+ROUND(F24*H24,2) -> 0 | L24: =+ROUND(J24+K24*TC,2) -> #REF!
A25: A | C25: =C24+0.000001 -> 4.010203 | D25: ACERO DE REFUERZO FY= 4200 kg/cm2, GRADO 60 | E25: kg | F25: 0 | G25: 1.19 | H25: 0.91 | I25: =+ROUND(G25+H25*TC,2) -> #REF! | J25: =+ROUND(F25*G25,2) -> 0 | K25: =+ROUND(F25*H25,2) -> 0 | L25: =+ROUND(J25+K25*TC,2) -> #REF!
C26: =C25+0.000001 -> 4.010204 | D26: CURADO DE ELEMENTOS ESTRUCTURALES EXPUESTOS | E26: m2 | F26: 0 | G26: 1.44 | I26: =+ROUND(G26+H26*TC,2) -> #REF! | J26: =+ROUND(F26*G26,2) -> 0 | K26: =+ROUND(F26*H26,2) -> 0 | L26: =+ROUND(J26+K26*TC,2) -> #REF!
C27: =C22+0.0001 -> 4.0103 | D27: COLUMNAS | F27: 0
A28: C | B28: CASCO TORRE | C28: =C27+0.000001 -> 4.010301 | D28: CONCRETO PREMEZCLADO, CEMENTO TIPO I, COLUMNAS f'c=210 kg/cm2 | E28: m3 | F28: 16.48 | G28: 385.05 | I28: =+ROUND(G28+H28*TC,2) -> #REF! | J28: =+ROUND(F28*G28,2) -> 6345.62 | K28: =+ROUND(F28*H28,2) -> 0 | L28: =+ROUND(J28+K28*TC,2) -> #REF!
A29: C | B29: CASCO TORRE | C29: =C28+0.000001 -> 4.010302 | D29: CONCRETO PREMEZCLADO, CEMENTO TIPO I, COLUMNAS f'c=280 kg/cm2 | E29: m3 | F29: 17.13 | G29: 414.19 | I29: =+ROUND(G29+H29*TC,2) -> #REF! | J29: =+ROUND(F29*G29,2) -> 7095.07 | K29: =+ROUND(F29*H29,2) -> 0 | L29: =+ROUND(J29+K29*TC,2) -> #REF!
A30: C | B30: CASCO TORRE | C30: =C29+0.000001 -> 4.010303 | D30: CONCRETO PREMEZCLADO, CEMENTO TIPO I, COLUMNAS f'c=350 kg/cm2 | E30: m3 | F30: 16.65 | G30: 453.08 | I30: =+ROUND(G30+H30*TC,2) -> #REF! | J30: =+ROUND(F30*G30,2) -> 7543.78 | K30: =+ROUND(F30*H30,2) -> 0 | L30: =+ROUND(J30+K30*TC,2) -> #REF!
A31: C | C31: =C30+0.000001 -> 4.010304 | D31: CONCRETO PREMEZCLADO, CEMENTO TIPO I, COLUMNAS f'c=420 kg/cm2 | E31: m3 | F31: 18.52 | G31: 468.67 | I31: =+ROUND(G31+H31*TC,2) -> #REF! | J31: =+ROUND(F31*G31,2) -> 8679.77 | K31: =+ROUND(F31*H31,2) -> 0 | L31: =+ROUND(J31+K31*TC,2) -> #REF!
A32: E | C32: =C31+0.000001 -> 4.010305 | D32: ENCOFRADO Y DESENCOFRADO DE COLUMNAS | E32: m2 | F32: 486 | G32: 44.1 | I32: =+ROUND(G32+H32*TC,2) -> #REF! | J32: =+ROUND(F32*G32,2) -> 21432.6 | K32: =+ROUND(F32*H32,2) -> 0 | L32: =+ROUND(J32+K32*TC,2) -> #REF!
A33: E | C33: =C32+0.000001 -> 4.010306 | D33: ENCOFRADO Y DESENCOFRADO DE COLUMNAS DOBLE ALTURA | E33: m2 | F33: 41.71 | G33: 52.1 | I33: =+ROUND(G33+H33*TC,2) -> #REF! | J33: =+ROUND(F33*G33,2) -> 2173.09 | K33: =+ROUND(F33*H33,2) -> 0 | L33: =+ROUND(J33+K33*TC,2) -> #REF!
A34: A | C34: =C33+0.000001 -> 4.010307 | D34: ACERO DE REFUERZO FY= 4200 kg/cm2, GRADO 60 | E34: kg | F34: 11853.06 | G34: 1.19 | H34: 0.91 | I34: =+ROUND(G34+H34*TC,2) -> #REF! | J34: =+ROUND(F34*G34,2) -> 14105.14 | K34: =+ROUND(F34*H34,2) -> 10786.28 | L34: =+ROUND(J34+K34*TC,2) -> #REF!
C35: =C34+0.000001 -> 4.010308 | D35: CURADO DE ELEMENTOS ESTRUCTURALES EXPUESTOS | E35: m2 | F35: 527.71 | G35: 1.44 | I35: =+ROUND(G35+H35*TC,2) -> #REF! | J35: =+ROUND(F35*G35,2) -> 759.9 | K35: =+ROUND(F35*H35,2) -> 0 | L35: =+ROUND(J35+K35*TC,2) -> #REF!
C36: =C27+0.0001 -> 4.0104 | D36: VIGAS | F36: 0
A37: C | B37: CASCO TORRE | C37: =C36+0.000001 -> 4.010401 | D37: CONCRETO PREMEZCLADO, CEMENTO TIPO I, VIGAS TORRE f'c=245 kg/cm2 | E37: m3 | F37: 813.69 | G37: 396.14 | I37: =+ROUND(G37+H37*TC,2) -> #REF! | J37: =+ROUND(F37*G37,2) -> 322335.16 | K37: =+ROUND(F37*H37,2) -> 0 | L37: =+ROUND(J37+K37*TC,2) -> #REF!
A38: C | B38: CASCO TORRE | C38: =C37+0.000001 -> 4.010402 | D38: CONCRETO PREMEZCLADO, CEMENTO TIPO I, VIGAS TORRE f'c=350 kg/cm2 (NUCLEOS) | E38: m3 | F38: 31.27 | G38: 449.73 | I38: =+ROUND(G38+H38*TC,2) -> #REF! | J38: =+ROUND(F38*G38,2) -> 14063.06 | K38: =+ROUND(F38*H38,2) -> 0 | L38: =+ROUND(J38+K38*TC,2) -> #REF!
A39: C | B39: CASCO TORRE | C39: =C38+0.000001 -> 4.010403 | D39: CONCRETO PREMEZCLADO, CEMENTO TIPO I, VIGAS TORRE f'c=420 kg/cm2 (NUCLEOS) | E39: m3 | F39: 31 | G39: 465.98 | I39: =+ROUND(G39+H39*TC,2) -> #REF! | J39: =+ROUND(F39*G39,2) -> 14445.38 | K39: =+ROUND(F39*H39,2) -> 0 | L39: =+ROUND(J39+K39*TC,2) -> #REF!
A40: E | C40: =C38+0.000001 -> 4.010403 | D40: ENCOFRADO Y DESENCOFRADO DE VIGAS | E40: m2 | F40: 3986.27 | G40: 54.1 | I40: =+ROUND(G40+H40*TC,2) -> #REF! | J40: =+ROUND(F40*G40,2) -> 215657.21 | K40: =+ROUND(F40*H40,2) -> 0 | L40: =+ROUND(J40+K40*TC,2) -> #REF!
A41: E | C41: =C40+0.000001 -> 4.010404 | D41: ENCOFRADO Y DESENCOFRADO DE VIGAS DOBLE ALTURA | E41: m2 | F41: 191.82 | G41: 62.1 | I41: =+ROUND(G41+H41*TC,2) -> #REF! | J41: =+ROUND(F41*G41,2) -> 11912.02 | K41: =+ROUND(F41*H41,2) -> 0 | L41: =+ROUND(J41+K41*TC,2) -> #REF!
A42: A | C42: =C41+0.000001 -> 4.010405 | D42: ACERO DE REFUERZO FY= 4200 kg/cm2, GRADO 60 | E42: kg | F42: 131302.91 | G42: 1.19 | H42: 0.91 | I42: =+ROUND(G42+H42*TC,2) -> #REF! | J42: =+ROUND(F42*G42,2) -> 156250.46 | K42: =+ROUND(F42*H42,2) -> 119485.65 | L42: =+ROUND(J42+K42*TC,2) -> #REF!
C43: =C42+0.000001 -> 4.010406 | D43: CURADO DE ELEMENTOS ESTRUCTURALES EXPUESTOS | E43: m2 | F43: 4785.96 | G43: 1.44 | I43: =+ROUND(G43+H43*TC,2) -> #REF! | J43: =+ROUND(F43*G43,2) -> 6891.78 | K43: =+ROUND(F43*H43,2) -> 0 | L43: =+ROUND(J43+K43*TC,2) -> #REF!
...

Sheet ARQ SOT
B2: ARQUITECTURA SÓTANOS
B4: Presupuesto | C4: EDIFICIO MULTIFAMILIAR SALAVERRY 2431
B5: Subpresupuesto | C5: =$B$2 -> ARQUITECTURA SÓTANOS
B6: Cliente | C6: V&V BRAVO INMOBILIARIA
B7: Lugar | C7: SAN ISIDRO
B8: Fecha | C8: =#REF! -> #REF!
B10: ITEM | C10: DESCRIPCION | D10: UND | E10: METRADO | F10: P.U. (PEN) | G10: P.U. (USD) | H10: P.U. TOTAL (PEN) | I10: PRECIO PARCIAL (PEN) | J10: PRECIO PARCIAL (USD) | K10: PARCIAL TOTAL (PEN) | L10: TOTAL
B11: 05 | C11: =$B$2 -> ARQUITECTURA SÓTANOS
B12: =B11+0.01 -> 5.01 | C12: MUROS Y TABIQUES | H12: =IFERROR(IF(D12<>0,(F12+G12*TC)," ")," ") | I12: =IFERROR(IF($E12=0,"",$E12*F12),"") | J12: =IFERROR(IF($E12=0,"",$E12*G12),"") | K12: =IFERROR(IF(E12<>0,(E12*H12)," "),0) | L12: =SUM(I12:I49)+SUM(J12:J49)*TC -> #REF!
B13: =B12+0.0001 -> 5.0101 | C13: MUROS Y TABIQUES SILICO CALCAREOS | H13: =IFERROR(IF(D13<>0,(F13+G13*TC)," ")," ") | I13: =IFERROR(IF($E13=0,"",$E13*F13),"") | J13: =IFERROR(IF($E13=0,"",$E13*G13),"") | K13: =IFERROR(IF(E13<>0,(E13*H13)," "),0)
B14: =B12+0.0001 -> 5.0101 | C14: ALTURA < 2.60 | H14: =IFERROR(IF(D14<>0,(F14+G14*TC)," ")," ") | I14: =IFERROR(IF($E14=0,"",$E14*F14),"") | J14: =IFERROR(IF($E14=0,"",$E14*G14),"") | K14: =IFERROR(IF(E14<>0,(E14*H14)," "),0)
B15: =B14+0.000001 -> 5.010101 | C15: LADRILLO SILICO CALCAREO TIPO P7 H<2.6M | D15: m2 | E15: 533.66 | F15: 96.71 | H15: =+ROUND(F15+G15*TC,2) -> #REF! | I15: =+ROUND(E15*F15,2) -> 51610.26 | J15: =+ROUND(E15*G15,2) -> 0 | K15: =+ROUND(I15+J15*TC,2) -> #REF!
B16: =B15+0.000001 -> 5.010102 | C16: LADRILLO SILICO CALCAREO TIPO P10 H<2.6M | D16: m2 | E16: 17.75 | F16: 103.71 | H16: =+ROUND(F16+G16*TC,2) -> #REF! | I16: =+ROUND(E16*F16,2) -> 1840.85 | J16: =+ROUND(E16*G16,2) -> 0 | K16: =+ROUND(I16+J16*TC,2) -> #REF!
B17: =B15+0.000001 -> 5.010102 | C17: LADRILLO SILICO CALCAREO TIPO P12 H<2.6M | D17: m2 | E17: 32.35 | F17: 109.71 | H17: =+ROUND(F17+G17*TC,2) -> #REF! | I17: =+ROUND(E17*F17,2) -> 3549.12 | J17: =+ROUND(E17*G17,2) -> 0 | K17: =+ROUND(I17+J17*TC,2) -> #REF!
B18: =B17+0.000001 -> 5.010103 | C18: LADRILLO SILICO CALCAREO TIPO P14 H<2.6M | D18: m2 | E18: 21.64 | F18: 118.21 | H18: =+ROUND(F18+G18*TC,2) -> #REF! | I18: =+ROUND(E18*F18,2) -> 2558.06 | J18: =+ROUND(E18*G18,2) -> 0 | K18: =+ROUND(I18+J18*TC,2) -> #REF!
B19: =B14+0.0001 -> 5.0102 | C19: ALTURA > 2.60
B20: =B19+0.000001 -> 5.010201 | C20: LADRILLO SILICO CALCAREO TIPO P7 H>2.6M | D20: m2 | E20: 73.58 | F20: 104.71 | H20: =+ROUND(F20+G20*TC,2) -> #REF! | I20: =+ROUND(E20*F20,2) -> 7704.56 | J20: =+ROUND(E20*G20,2) -> 0 | K20: =+ROUND(I20+J20*TC,2) -> #REF!
B21: =B20+0.000001 -> 5.010202 | C21: LADRILLO SILICO CALCAREO TIPO P10 H>2.6M | D21: m2 | E21: 28.17 | F21: 111.71 | H21: =+ROUND(F21+G21*TC,2) -> #REF! | I21: =+ROUND(E21*F21,2) -> 3146.87 | J21: =+ROUND(E21*G21,2) -> 0 | K21: =+ROUND(I21+J21*TC,2) -> #REF!
B22: =B21+0.000001 -> 5.010203 | C22: LADRILLO SILICO CALCAREO TIPO P12 H>2.6M | D22: m2 | E22: 37.22 | F22: 117.71 | H22: =+ROUND(F22+G22*TC,2) -> #REF! | I22: =+ROUND(E22*F22,2) -> 4381.17 | J22: =+ROUND(E22*G22,2) -> 0 | K22: =+ROUND(I22+J22*TC,2) -> #REF!
B23: =B22+0.000001 -> 5.010204 | C23: LADRILLO SILICO CALCAREO TIPO P14 H>2.6M | D23: m2 | E23: 9.99 | F23: 126.21 | H23: =+ROUND(F23+G23*TC,2) -> #REF! | I23: =+ROUND(E23*F23,2) -> 1260.84 | J23: =+ROUND(E23*G23,2) -> 0 | K23: =+ROUND(I23+J23*TC,2) -> #REF!
B24: =B19+0.0001 -> 5.0103 | C24: CORTAFUEGO < 2.60 | E24: 0
B25: =B23+0.000001 -> 5.010205 | C25: LADRILLO SILICO CALCAREO TIPO P7 RF:2 HRS H<2.6M (ALVEOLOS COMPLETAMENTE LLENO) | D25: m2 | E25: 6.07 | F25: 106.71 | H25: =+ROUND(F25+G25*TC,2) -> #REF! | I25: =+ROUND(E25*F25,2) -> 647.73 | J25: =+ROUND(E25*G25,2) -> 0 | K25: =+ROUND(I25+J25*TC,2) -> #REF!
B26: =B24+0.000001 -> 5.010301 | C26: LADRILLO SILICO CALCAREO TIPO P10 RF:2 HRS H<2.6M (ALVEOLOS COMPLETAMENTE LLENO) | D26: m2 | E26: 7.82 | F26: 113.71 | H26: =+ROUND(F26+G26*TC,2) -> #REF! | I26: =+ROUND(E26*F26,2) -> 889.21 | J26: =+ROUND(E26*G26,2) -> 0 | K26: =+ROUND(I26+J26*TC,2) -> #REF!
B27: =B26+0.000001 -> 5.010302 | C27: LADRILLO SILICO CALCAREO TIPO P12 RF:2 HRS H<2.6M (ALVEOLOS PARCIALMENTE LLENO) | D27: m2 | E27: 143.68 | F27: 109.71 | H27: =+ROUND(F27+G27*TC,2) -> #REF! | I27: =+ROUND(E27*F27,2) -> 15763.13 | J27: =+ROUND(E27*G27,2) -> 0 | K27: =+ROUND(I27+J27*TC,2) -> #REF!
B28: =B24+0.0001 -> 5.0104 | C28: CORTAFUEGO > 2.60
B29: =B27+0.000001 -> 5.010303 | C29: LADRILLO SILICO CALCAREO TIPO P7 RF:2 HRS H>2.6M (ALVEOLOS COMPLETAMENTE LLENO) | D29: m2 | E29: 4.92 | F29: 114.71 | H29: =+ROUND(F29+G29*TC,2) -> #REF! | I29: =+ROUND(E29*F29,2) -> 564.37 | J29: =+ROUND(E29*G29,2) -> 0 | K29: =+ROUND(I29+J29*TC,2) -> #REF!
B30: =B28+0.000001 -> 5.010401 | C30: LADRILLO SILICO CALCAREO TIPO P10 RF:2 HRS H>2.6M (ALVEOLOS COMPLETAMENTE LLENO) | D30: m2 | E30: 46.38 | F30: 121.71 | H30: =+ROUND(F30+G30*TC,2) -> #REF! | I30: =+ROUND(E30*F30,2) -> 5644.91 | J30: =+ROUND(E30*G30,2) -> 0 | K30: =+ROUND(I30+J30*TC,2) -> #REF!
B31: =B30+0.000001 -> 5.010402 | C31: LADRILLO SILICO CALCAREO TIPO P12 RF:2 HRS H>2.6M (ALVEOLOS PARCIALMENTE LLENO) | D31: m2 | E31: 129.77 | F31: 117.71 | H31: =+ROUND(F31+G31*TC,2) -> #REF! | I31: =+ROUND(E31*F31,2) -> 15275.23 | J31: =+ROUND(E31*G31,2) -> 0 | K31: =+ROUND(I31+J31*TC,2) -> #REF!
B32: =B31+0.000001 -> 5.010403 | C32: LADRILLO SILICO CALCAREO TIPO P14 RF:2 HRS H>2.6M (ALVEOLOS PARCIALMENTE LLENO) | D32: m2 | E32: 11.36 | F32: 126.21 | H32: =+ROUND(F32+G32*TC,2) -> #REF! | I32: =+ROUND(E32*F32,2) -> 1433.75 | J32: =+ROUND(E32*G32,2) -> 0 | K32: =+ROUND(I32+J32*TC,2) -> #REF!
B33: =B28+0.0001 -> 5.0105 | C33: ACERO DE REFUERZO
B34: =B33+0.000001 -> 5.010501 | C34: ACERO DE REFUERZO FY= 4200 kg/cm2 GRADO 60 PARA TABIQUERÍA | D34: kg | E34: 1656.54 | F34: 0 | G34: 0.91 | H34: =+ROUND(F34+G34*TC,2) -> #REF! | I34: =+ROUND(E34*F34,2) -> 0 | J34: =+ROUND(E34*G34,2) -> 1507.45 | K34: =+ROUND(I34+J34*TC,2) -> #REF!
B35: =B33+0.0001 -> 5.0106 | C35: DINTELES
B36: =B35+0.000001 -> 5.010601 | C36: DINTELES DE LADRILLOS SILICO CALCAREO | D36: und | E36: 103 | F36: 120 | H36: =+ROUND(F36+G36*TC,2) -> #REF! | I36: =+ROUND(E36*F36,2) -> 12360 | J36: =+ROUND(E36*G36,2) -> 0 | K36: =+ROUND(I36+J36*TC,2) -> #REF!
B37: =B36+0.000001 -> 5.010602 | C37: DINTELES DE LADRILLO SILICO CALCAREO RF | D37: und | E37: 6 | F37: 125 | H37: =+ROUND(F37+G37*TC,2) -> #REF! | I37: =+ROUND(E37*F37,2) -> 750 | J37: =+ROUND(E37*G37,2) -> 0 | K37: =+ROUND(I37+J37*TC,2) -> #REF!
B38: =B35+0.0001 -> 5.0107 | C38: TRABAJOS COMPLEMENTARIOS DE TABIQUERIA
B39: =B38+0.000001 -> 5.010701 | C39: PASES DE MANGUERA (0.20x20M) DOBLE PLACA DE ROCA DE YESO | D39: und | E39: 6 | F39: 80 | H39: =+ROUND(F39+G39*TC,2) -> #REF! | I39: =+ROUND(E39*F39,2) -> 480 | J39: =+ROUND(E39*G39,2) -> 0 | K39: =+ROUND(I39+J39*TC,2) -> #REF!
B40: =B13+0.0001 -> 5.0102 | C40: TABIQUERIA DE DRYWALL | H40: =IFERROR(IF(D40<>0,(F40+G40*TC)," ")," ") | I40: =IFERROR(IF($E40=0,"",$E40*F40),"") | J40: =IFERROR(IF($E40=0,"",$E40*G40),"") | K40: =IFERROR(IF(E40<>0,(E40*H40)," "),0)
B41: =B40+0.00001 -> 5.01021 | C41: MUROS DE DRYWALL | H41: =IFERROR(IF(D41<>0,(F41+G41*TC)," ")," ") | I41: =IFERROR(IF($E41=0,"",$E41*F41),"") | J41: =IFERROR(IF($E41=0,"",$E41*G41),"") | K41: =IFERROR(IF(E41<>0,(E41*H41)," "),0)
C42: FALSO MURO DRYWALL - GRUPO ELECTRÓGENO | D42: m2 | E42: 5.09 | F42: 145 | H42: =+ROUND(F42+G42*TC,2) -> #REF! | I42: =+ROUND(E42*F42,2) -> 738.05 | J42: =+ROUND(E42*G42,2) -> 0 | K42: =+ROUND(I42+J42*TC,2) -> #REF!
B43: =B41+0.0001 -> 5.01031 | C43: DINTELES DE DRYWALL
...

Sheet ARQ TORRE
B2: ARQUITECTURA TORRE
B4: Presupuesto | C4: =OP!$B$4 -> #REF!
B5: Subpresupuesto | C5: =$B$2 -> ARQUITECTURA TORRE
B6: Cliente | C6: =OP!$B$6 -> #REF!
B7: Lugar | C7: =OP!$B$7 -> #REF!
B8: Fecha | C8: =#REF! -> #REF!
B10: ITEM | C10: DESCRIPCION | D10: UND | E10: METRADO | F10: P.U. (PEN) | G10: P.U. (USD) | H10: P.U. TOTAL (PEN) | I10: PRECIO PARCIAL (PEN) | J10: PRECIO PARCIAL (USD) | K10: PARCIAL TOTAL (PEN) | L10: TOTAL
B11: 06 | C11: =$B$2 -> ARQUITECTURA TORRE
B12: =B11+0.01 -> 6.01 | C12: MUROS Y TABIQUES | H12: =IFERROR(IF(D12<>0,F12+G12*TC," ")," ") | I12: =IFERROR(IF($E12=0,"",$E12*F12),"") | J12: =IFERROR(IF($E12=0,"",$E12*G12),"") | K12: =IFERROR(IF(E12<>0,(E12*H12)," "),0) | L12: =SUM(I12:I88)+SUM(J12:J88)*TC -> #REF! | M12: =+L12+L124+L128 -> #REF!
B13: =B12+0.0001 -> 6.0101 | C13: MUROS Y TABIQUES SILICO CALCAREOS, ALBAÑILERIA , CONCRETO | H13: =IFERROR(IF(D13<>0,(F13+G13*TC)," ")," ") | I13: =IFERROR(IF($E13=0,"",$E13*F13),"") | J13: =IFERROR(IF($E13=0,"",$E13*G13),"") | K13: =IFERROR(IF(E13<>0,(E13*H13)," "),0)
B14: =B13+0.000001 -> 6.010101 | C14: ALTURA < 2.60 | H14: =IFERROR(IF(D14<>0,(F14+G14*TC)," ")," ") | I14: =IFERROR(IF($E14=0,"",$E14*F14),"") | J14: =IFERROR(IF($E14=0,"",$E14*G14),"") | K14: =IFERROR(IF(E14<>0,(E14*H14)," "),0)
B15: =B14+0.00000001 -> 6.010101 | C15: LADRILLO SILICO CALCAREO TIPO P7 H<2.6M | D15: m2 | E15: 1192.22 | F15: 96.71 | H15: =+ROUND(F15+G15*TC,2) -> #REF! | I15: =+ROUND(E15*F15,2) -> 115299.6 | J15: =+ROUND(E15*G15,2) -> 0 | K15: =+ROUND(I15+J15*TC,2) -> #REF!
B16: =B15+0.00000001 -> 6.010101 | C16: LADRILLO SILICO CALCAREO TIPO P10 H<2.6M | D16: m2 | E16: 3804.01 | F16: 103.71 | H16: =+ROUND(F16+G16*TC,2) -> #REF! | I16: =+ROUND(E16*F16,2) -> 394513.88 | J16: =+ROUND(E16*G16,2) -> 0 | K16: =+ROUND(I16+J16*TC,2) -> #REF!
B17: =B16+0.00000001 -> 6.010101 | C17: LADRILLO SILICO CALCAREO TIPO P12 H<2.6M | D17: m2 | E17: 659.47 | F17: 109.71 | H17: =+ROUND(F17+G17*TC,2) -> #REF! | I17: =+ROUND(E17*F17,2) -> 72350.45 | J17: =+ROUND(E17*G17,2) -> 0 | K17: =+ROUND(I17+J17*TC,2) -> #REF!
B18: =B17+0.00000001 -> 6.010101 | C18: LADRILLO SILICO CALCAREO TIPO P14 H<2.6M | D18: m2 | E18: 1505.43 | F18: 118.21 | H18: =+ROUND(F18+G18*TC,2) -> #REF! | I18: =+ROUND(E18*F18,2) -> 177956.88 | J18: =+ROUND(E18*G18,2) -> 0 | K18: =+ROUND(I18+J18*TC,2) -> #REF!
B19: =B17+0.00000001 -> 6.010101 | C19: LADRILLO SILICO CALCAREO TIPO P20 H<2.6M | D19: m2 | E19: 34.05 | F19: 199.21 | H19: =+ROUND(F19+G19*TC,2) -> #REF! | I19: =+ROUND(E19*F19,2) -> 6783.1 | J19: =+ROUND(E19*G19,2) -> 0 | K19: =+ROUND(I19+J19*TC,2) -> #REF!
B20: =B18+0.00000001 -> 6.010101 | C20: LADRILLO SILICO CALCAREO TIPO P25 H<2.6M | D20: m2 | E20: 55.4 | F20: 211.21 | H20: =+ROUND(F20+G20*TC,2) -> #REF! | I20: =+ROUND(E20*F20,2) -> 11701.03 | J20: =+ROUND(E20*G20,2) -> 0 | K20: =+ROUND(I20+J20*TC,2) -> #REF!
B21: =B18+0.00000001 -> 6.010101 | C21: LADRILLO SILICO CALCAREO TIPO P30 H<2.6M | D21: m2 | E21: 49.5 | F21: 211.21 | H21: =+ROUND(F21+G21*TC,2) -> #REF! | I21: =+ROUND(E21*F21,2) -> 10454.9 | J21: =+ROUND(E21*G21,2) -> 0 | K21: =+ROUND(I21+J21*TC,2) -> #REF!
B22: =B21+0.00000001 -> 6.0101011 | C22: LADRILLO SILICO CALCAREO TIPO P40 H<2.6M | D22: m2 | E22: 4.09 | F22: 211.21 | H22: =+ROUND(F22+G22*TC,2) -> #REF! | I22: =+ROUND(E22*F22,2) -> 863.85 | J22: =+ROUND(E22*G22,2) -> 0 | K22: =+ROUND(I22+J22*TC,2) -> #REF!
B23: =B14+0.000001 -> 6.010102 | C23: ALTURA > 2.60 | E23: 0
B24: =B23+0.00000001 -> 6.010102 | C24: LADRILLO SILICO CALCAREO TIPO P7 H>2.6M | D24: m2 | E24: 36.46 | F24: 104.71 | H24: =+ROUND(F24+G24*TC,2) -> #REF! | I24: =+ROUND(E24*F24,2) -> 3817.73 | J24: =+ROUND(E24*G24,2) -> 0 | K24: =+ROUND(I24+J24*TC,2) -> #REF!
B25: =B23+0.00000001 -> 6.010102 | C25: LADRILLO SILICO CALCAREO TIPO P10 H>2.6M | D25: m2 | E25: 153.89 | F25: 111.71 | H25: =+ROUND(F25+G25*TC,2) -> #REF! | I25: =+ROUND(E25*F25,2) -> 17191.05 | J25: =+ROUND(E25*G25,2) -> 0 | K25: =+ROUND(I25+J25*TC,2) -> #REF!
B26: =B25+0.00000001 -> 6.010102 | C26: LADRILLO SILICO CALCAREO TIPO P12 H>2.6M | D26: m2 | E26: 184.69 | F26: 117.71 | H26: =+ROUND(F26+G26*TC,2) -> #REF! | I26: =+ROUND(E26*F26,2) -> 21739.86 | J26: =+ROUND(E26*G26,2) -> 0 | K26: =+ROUND(I26+J26*TC,2) -> #REF!
B27: =B26+0.00000001 -> 6.010102 | C27: LADRILLO SILICO CALCAREO TIPO P14 H>2.6M | D27: m2 | E27: 157.51 | F27: 126.21 | H27: =+ROUND(F27+G27*TC,2) -> #REF! | I27: =+ROUND(E27*F27,2) -> 19879.34 | J27: =+ROUND(E27*G27,2) -> 0 | K27: =+ROUND(I27+J27*TC,2) -> #REF!
B28: =B27+0.00000001 -> 6.010102 | C28: LADRILLO SILICO CALCAREO TIPO P20 H>2.6M | D28: m2 | E28: 0.95 | F28: 215.21 | H28: =+ROUND(F28+G28*TC,2) -> #REF! | I28: =+ROUND(E28*F28,2) -> 204.45 | J28: =+ROUND(E28*G28,2) -> 0 | K28: =+ROUND(I28+J28*TC,2) -> #REF!
B29: =B28+0.00000001 -> 6.010102 | C29: LADRILLO SILICO CALCAREO TIPO P25 H>2.6M | D29: m2 | E29: 5.18 | F29: 227.21 | H29: =+ROUND(F29+G29*TC,2) -> #REF! | I29: =+ROUND(E29*F29,2) -> 1176.95 | J29: =+ROUND(E29*G29,2) -> 0 | K29: =+ROUND(I29+J29*TC,2) -> #REF!
B30: =B28+0.00000001 -> 6.010102 | C30: LADRILLO SILICO CALCAREO TIPO P35 H>2.6M | D30: m2 | E30: 3.66 | F30: 227.21 | H30: =+ROUND(F30+G30*TC,2) -> #REF! | I30: =+ROUND(E30*F30,2) -> 831.59 | J30: =+ROUND(E30*G30,2) -> 0 | K30: =+ROUND(I30+J30*TC,2) -> #REF!
B31: =B23+0.000001 -> 6.010103 | C31: CORTAFUEGO < 2.60 | E31: 0
B32: =B31+0.00000001 -> 6.010103 | C32: LADRILLO SILICO CALCAREO TIPO P10 RF:2 HRS H<2.6M (ALVEOLOS COMPLETAMENTE LLENO) | D32: m2 | E32: 1455.53 | F32: 113.71 | H32: =+ROUND(F32+G32*TC,2) -> #REF! | I32: =+ROUND(E32*F32,2) -> 165508.32 | J32: =+ROUND(E32*G32,2) -> 0 | K32: =+ROUND(I32+J32*TC,2) -> #REF!
B33: =B32+0.00000001 -> 6.010103 | C33: LADRILLO SILICO CALCAREO TIPO P12 RF:2 HRS H<2.6M (ALVEOLOS PARCIALMENTE LLENO) | D33: m2 | E33: 4994.87 | F33: 109.71 | H33: =+ROUND(F33+G33*TC,2) -> #REF! | I33: =+ROUND(E33*F33,2) -> 547987.19 | J33: =+ROUND(E33*G33,2) -> 0 | K33: =+ROUND(I33+J33*TC,2) -> #REF!
B34: =B33+0.00000001 -> 6.010103 | C34: LADRILLO SILICO CALCAREO TIPO P14 RF:2 HRS H<2.6M (ALVEOLOS PARCIALMENTE LLENO) | D34: m2 | E34: 548.37 | F34: 118.21 | H34: =+ROUND(F34+G34*TC,2) -> #REF! | I34: =+ROUND(E34*F34,2) -> 64822.82 | J34: =+ROUND(E34*G34,2) -> 0 | K34: =+ROUND(I34+J34*TC,2) -> #REF!
B35: =B33+0.00000001 -> 6.010103 | C35: LADRILLO SILICO CALCAREO TIPO P20 RF:2 HRS H<2.6M (ALVEOLOS PARCIALMENTE LLENO) | D35: m2 | E35: 91.37 | F35: 219.21 | H35: =+ROUND(F35+G35*TC,2) -> #REF! | I35: =+ROUND(E35*F35,2) -> 20029.22 | J35: =+ROUND(E35*G35,2) -> 0 | K35: =+ROUND(I35+J35*TC,2) -> #REF!
B36: =B34+0.00000001 -> 6.010103 | C36: LADRILLO SILICO CALCAREO TIPO P25 RF:2 HRS H<2.6M (ALVEOLOS PARCIALMENTE LLENO) | D36: m2 | E36: 164.22 | F36: 211.21 | H36: =+ROUND(F36+G36*TC,2) -> #REF! | I36: =+ROUND(E36*F36,2) -> 34684.91 | J36: =+ROUND(E36*G36,2) -> 0 | K36: =+ROUND(I36+J36*TC,2) -> #REF!
B37: =B34+0.00000001 -> 6.010103 | C37: LADRILLO SILICO CALCAREO TIPO P30 RF:2 HRS H<2.6M (ALVEOLOS PARCIALMENTE LLENO) | D37: m2 | E37: 2 | F37: 211.21 | H37: =+ROUND(F37+G37*TC,2) -> #REF! | I37: =+ROUND(E37*F37,2) -> 422.42 | J37: =+ROUND(E37*G37,2) -> 0 | K37: =+ROUND(I37+J37*TC,2) -> #REF!
B38: =B31+0.000001 -> 6.010104 | C38: CORTAFUEGO > 2.60 | E38: 0
B39: =B38+0.00000001 -> 6.010104 | C39: LADRILLO SILICO CALCAREO TIPO P10 RF:2 HRS H>2.6M (ALVEOLOS COMPLETAMENTE LLENO) | D39: m2 | E39: 141.64 | F39: 121.71 | H39: =+ROUND(F39+G39*TC,2) -> #REF! | I39: =+ROUND(E39*F39,2) -> 17239 | J39: =+ROUND(E39*G39,2) -> 0 | K39: =+ROUND(I39+J39*TC,2) -> #REF!
B40: =B39+0.00000001 -> 6.010104 | C40: LADRILLO SILICO CALCAREO TIPO P12 RF:2 HRS H>2.6M (ALVEOLOS PARCIALMENTE LLENO) | D40: m2 | E40: 313.86 | F40: 117.71 | H40: =+ROUND(F40+G40*TC,2) -> #REF! | I40: =+ROUND(E40*F40,2) -> 36944.46 | J40: =+ROUND(E40*G40,2) -> 0 | K40: =+ROUND(I40+J40*TC,2) -> #REF!
B41: =B40+0.00000001 -> 6.010104 | C41: LADRILLO SILICO CALCAREO TIPO P14 RF:2 HRS H>2.6M (ALVEOLOS PARCIALMENTE LLENO) | D41: m2 | E41: 48.25 | F41: 126.21 | H41: =+ROUND(F41+G41*TC,2) -> #REF! | I41: =+ROUND(E41*F41,2) -> 6089.63 | J41: =+ROUND(E41*G41,2) -> 0 | K41: =+ROUND(I41+J41*TC,2) -> #REF!
B42: =B41+0.00000001 -> 6.010104 | C42: LADRILLO SILICO CALCAREO TIPO P20 RF:2 HRS H>2.6M (ALVEOLOS COMPLETAMENTE LLENO) | D42: m2 | E42: 2.24 | F42: 235.21 | H42: =+ROUND(F42+G42*TC,2) -> #REF! | I42: =+ROUND(E42*F42,2) -> 526.87 | J42: =+ROUND(E42*G42,2) -> 0 | K42: =+ROUND(I42+J42*TC,2) -> #REF!
B43: =B42+0.00000001 -> 6.010104 | C43: LADRILLO SILICO CALCAREO TIPO P25 RF:2 HRS H>2.6M (ALVEOLOS COMPLETAMENTE LLENO) | D43: m2 | E43: 10.63 | F43: 235.21 | H43: =+ROUND(F43+G43*TC,2) -> #REF! | I43: =+ROUND(E43*F43,2) -> 2500.28 | J43: =+ROUND(E43*G43,2) -> 0 | K43: =+ROUND(I43+J43*TC,2) -> #REF!
...

Sheet OBRA CIVIL ASCENSOR
B2: DESCRIPCIÓN | C2: UND | D2: CANTIDAD | E2: PRECIO | F2: PARCIAL | G2: TOTAL
B3: ASCENSORES | G3: =SUM(F5:F6) -> 29000
B4: OBRAS CIVILES
B5: OBRAS CIVILES PARA LA COLOCACIÓN DE ASCENSOR | C5: und | D5: 1 | E5: 29000 | F5: =+E5*D5 -> 29000
B6: ESTRUCTURAS (DINTELES METÁLICOS/COLUMNAS METÁLICAS) - INCLUIDAS EN COTI ASCENSOR | C6: glb | D6: 0 | E6: 90335 | F6: =+E6*D6 -> 0

Sheet IISS
A2: INSTALACIONES SANITARIAS
H3: T.C | I3: 3.75
A4: Presupuesto | B4: PARDO 669
A5: Subpresupuesto | B5: INSTALACIONES SANITARIAS
A6: Cliente | B6: : V&V Bravo S.A.C | F6: Costo al | G6: 45394
A7: Lugar
A8: ITEM | B8: DESCRIPCION | C8: UND | D8: CANTIDAD | E8: P.U (S/.) | F8: P.U ($.) | G8: PARCIAL (S/.) | H8: PARCIAL ($) | I8: TOTAL
A9: 01 | B9: INSTALACIONES SANITARIAS | G9: =SUM(G10:G143) -> 1240575.8 | H9: =SUM(H10:H143) -> 42657.42 | I9: =SUM(I10:I143) -> 1400541.2
A10: 01.01 | B10: SISTEMA DE AGUA FRÍA | J10: =SUM(I12:I64) -> 419601.08
A11: 01.01.01 | B11: SALIDAS DE AGUA FRIA (EN POLIPROPILENO)
A12: 01.01.01.01 | B12: SALIDA AGUA FRIA PPR 20mm (Ø1/2") | C12: pto | D12: 1099 | E12: 57.25 | F12: 0 | G12: =+ROUND(E12*D12,2) -> 62917.75 | H12: =+ROUND(F12*D12,2) -> 0 | I12: =+ROUND(G12+(H12*$I$3),2) -> 62917.75
A13: 01.01.01.02 | B13: SALIDA AGUA FRIA PPR 25mm(3/4") | C13: pto | D13: 201 | E13: 59.35 | F13: 0 | G13: =+ROUND(E13*D13,2) -> 11929.35 | H13: =+ROUND(F13*D13,2) -> 0 | I13: =+ROUND(G13+(H13*$I$3),2) -> 11929.35
A14: 01.01.01.03 | B14: SALIDA AGUA FRIA PPR 50mm(1.1/2") | C14: pto | D14: 3 | E14: 132.29 | F14: 0 | G14: =+ROUND(E14*D14,2) -> 396.87 | H14: =+ROUND(F14*D14,2) -> 0 | I14: =+ROUND(G14+(H14*$I$3),2) -> 396.87
A15: 01.01.02 | B15: REDES DE DISTRIBUCION DE AGUA (EN POLIPROPILENO) | G15: =+ROUND(E15*D15,2) -> 0 | H15: =+ROUND(F15*D15,2) -> 0 | I15: =+ROUND(G15+(H15*$I$3),2) -> 0
A16: 01.01.02.01 | B16: TUBERIA PPR PN-10 EMPOTRADA DE 1/2" | C16: m | D16: 1100 | E16: 15.69 | F16: 0 | G16: =+ROUND(E16*D16,2) -> 17259 | H16: =+ROUND(F16*D16,2) -> 0 | I16: =+ROUND(G16+(H16*$I$3),2) -> 17259
A17: 01.01.02.02 | B17: TUBERIA PPR PN-10 EMPOTRADA DE 3/4" | C17: m | D17: 3150 | E17: 18.74 | F17: 0 | G17: =+ROUND(E17*D17,2) -> 59031 | H17: =+ROUND(F17*D17,2) -> 0 | I17: =+ROUND(G17+(H17*$I$3),2) -> 59031
A18: 01.01.02.03 | B18: TUBERIA PPR PN-10 EMPOTRADA DE 1" | C18: m | D18: 888.95 | E18: 24.44 | F18: 0 | G18: =+ROUND(E18*D18,2) -> 21725.94 | H18: =+ROUND(F18*D18,2) -> 0 | I18: =+ROUND(G18+(H18*$I$3),2) -> 21725.94
A19: 01.01.02.04 | B19: TUBERIA PPR PN-10 EMPOTRADA DE 1.1/4" | C19: m | D19: 2 | E19: 29.9 | F19: 0 | G19: =+ROUND(E19*D19,2) -> 59.8 | H19: =+ROUND(F19*D19,2) -> 0 | I19: =+ROUND(G19+(H19*$I$3),2) -> 59.8
A20: 01.01.02.05 | B20: TUBERIA PPR PN-10 EMPOTRADA DE 1.1/2" | C20: m | D20: 28.75 | E20: 40.1 | F20: 0 | G20: =+ROUND(E20*D20,2) -> 1152.88 | H20: =+ROUND(F20*D20,2) -> 0 | I20: =+ROUND(G20+(H20*$I$3),2) -> 1152.88
A21: 01.01.02.07 | B21: TUBERIA PPR PN-10 COLGADA DE 1/2" | C21: m | D21: 20 | E21: 24.17 | F21: 0 | G21: =+ROUND(E21*D21,2) -> 483.4 | H21: =+ROUND(F21*D21,2) -> 0 | I21: =+ROUND(G21+(H21*$I$3),2) -> 483.4
A22: 01.01.02.08 | B22: TUBERIA PPR PN-10 COLGADA DE 3/4" | C22: m | D22: 23 | E22: 26.43 | F22: 0 | G22: =+ROUND(E22*D22,2) -> 607.89 | H22: =+ROUND(F22*D22,2) -> 0 | I22: =+ROUND(G22+(H22*$I$3),2) -> 607.89
A23: 01.01.02.09 | B23: TUBERIA PPR PN-10 COLGADA DE 1" | C23: m | D23: 21 | E23: 33.41 | F23: 0 | G23: =+ROUND(E23*D23,2) -> 701.61 | H23: =+ROUND(F23*D23,2) -> 0 | I23: =+ROUND(G23+(H23*$I$3),2) -> 701.61
A24: 01.01.02.10 | B24: TUBERIA PPR PN-10 COLGADA DE 1.1/2" | C24: m | D24: 22.25 | E24: 47.86 | F24: 0 | G24: =+ROUND(E24*D24,2) -> 1064.89 | H24: =+ROUND(F24*D24,2) -> 0 | I24: =+ROUND(G24+(H24*$I$3),2) -> 1064.89
A25: 01.01.02.11 | B25: TUBERIA PPR PN-10 COLGADA DE 2" | C25: m | D25: 70.95 | E25: 57.45 | F25: 0 | G25: =+ROUND(E25*D25,2) -> 4076.08 | H25: =+ROUND(F25*D25,2) -> 0 | I25: =+ROUND(G25+(H25*$I$3),2) -> 4076.08
A26: 01.01.02.12 | B26: TUBERIA PPR PN-10 COLGADA DE 2 1/2" | C26: m | D26: 48.15 | E26: 88.16 | F26: 0 | G26: =+ROUND(E26*D26,2) -> 4244.9 | H26: =+ROUND(F26*D26,2) -> 0 | I26: =+ROUND(G26+(H26*$I$3),2) -> 4244.9
A27: 01.01.02.13 | B27: TUBERIA PPR PN-10 COLGADA DE 3" | C27: m | D27: 35.33 | E27: 108.03 | F27: 0 | G27: =+ROUND(E27*D27,2) -> 3816.7 | H27: =+ROUND(F27*D27,2) -> 0 | I27: =+ROUND(G27+(H27*$I$3),2) -> 3816.7
A28: 01.01.03 | B28: MONTANTE DE AGUA FRIA (EN POLIPROPILENO) | G28: =+ROUND(E28*D28,2) -> 0 | H28: =+ROUND(F28*D28,2) -> 0 | I28: =+ROUND(G28+(H28*$I$3),2) -> 0
A29: 01.01.03.01 | B29: TUBERIA PPR PN-10 ADOSADA DE 1.1/2" | C29: m | D29: 42 | E29: 47.86 | F29: 0 | G29: =+ROUND(E29*D29,2) -> 2010.12 | H29: =+ROUND(F29*D29,2) -> 0 | I29: =+ROUND(G29+(H29*$I$3),2) -> 2010.12
A30: 01.01.03.02 | B30: TUBERIA PPR PN-10 ADOSADA DE 2" | C30: m | D30: 96 | E30: 66.17 | F30: 0 | G30: =+ROUND(E30*D30,2) -> 6352.32 | H30: =+ROUND(F30*D30,2) -> 0 | I30: =+ROUND(G30+(H30*$I$3),2) -> 6352.32
A31: 01.01.03.03 | B31: TUBERIA PPR PN-10 ADOSADA DE 2.1/2" | C31: m | D31: 61 | E31: 88.16 | F31: 0 | G31: =+ROUND(E31*D31,2) -> 5377.76 | H31: =+ROUND(F31*D31,2) -> 0 | I31: =+ROUND(G31+(H31*$I$3),2) -> 5377.76
A32: 01.01.03.04 | B32: TUBERIA PPR PN-10 ADOSADA DE 3" | C32: m | D32: 101 | E32: 111.49 | F32: 0 | G32: =+ROUND(E32*D32,2) -> 11260.49 | H32: =+ROUND(F32*D32,2) -> 0 | I32: =+ROUND(G32+(H32*$I$3),2) -> 11260.49
A33: 01.01.03.05 | B33: TUBERIA PPR PN-10 ADOSADA DE 4" | C33: m | D33: 18 | E33: 151.68 | F33: 0 | G33: =+ROUND(E33*D33,2) -> 2730.24 | H33: =+ROUND(F33*D33,2) -> 0 | I33: =+ROUND(G33+(H33*$I$3),2) -> 2730.24
A34: 01.01.04 | B34: LLAVES Y VALVULAS - RED DE DESTRIBUCION (SIST. POLIPROPILENO) | G34: =+ROUND(E34*D34,2) -> 0 | H34: =+ROUND(F34*D34,2) -> 0 | I34: =+ROUND(G34+(H34*$I$3),2) -> 0
A35: 01.01.04.01 | B35: LLAVE DE PASO SIST. POLIPROPILENO 20mm (1/2") | C35: und | D35: 358 | E35: 63.61 | F35: 0 | G35: =+ROUND(E35*D35,2) -> 22772.38 | H35: =+ROUND(F35*D35,2) -> 0 | I35: =+ROUND(G35+(H35*$I$3),2) -> 22772.38
A36: 01.01.04.02 | B36: LLAVE DE PASO SIST. POLIPROPILENO 25mm (3/4") | C36: und | D36: 605 | E36: 72.44 | F36: 0 | G36: =+ROUND(E36*D36,2) -> 43826.2 | H36: =+ROUND(F36*D36,2) -> 0 | I36: =+ROUND(G36+(H36*$I$3),2) -> 43826.2
A37: 01.01.04.03 | B37: LLAVE DE PASO SIST. POLIPROPILENO 32mm (1") | C37: und | D37: 69 | E37: 136.35 | F37: 0 | G37: =+ROUND(E37*D37,2) -> 9408.15 | H37: =+ROUND(F37*D37,2) -> 0 | I37: =+ROUND(G37+(H37*$I$3),2) -> 9408.15
A38: 01.01.04.05 | B38: LLAVE DE PASO SIST. POLIPROPILENO (1.1/2") | C38: und | D38: 4 | E38: 359.62 | F38: 0 | G38: =+ROUND(E38*D38,2) -> 1438.48 | H38: =+ROUND(F38*D38,2) -> 0 | I38: =+ROUND(G38+(H38*$I$3),2) -> 1438.48
A39: 01.01.04.06 | B39: LLAVE DE PASO SIST. POLIPROPILENO 63mm (2") | C39: und | D39: 21 | E39: 395.26 | F39: 0 | G39: =+ROUND(E39*D39,2) -> 8300.46 | H39: =+ROUND(F39*D39,2) -> 0 | I39: =+ROUND(G39+(H39*$I$3),2) -> 8300.46
A40: 01.01.04.07 | B40: VALVULA DE AIRE EN MONTANTE | C40: und | D40: 6 | E40: 395.26 | F40: 0 | G40: =+ROUND(E40*D40,2) -> 2371.56 | H40: =+ROUND(F40*D40,2) -> 0 | I40: =+ROUND(G40+(H40*$I$3),2) -> 2371.56
A41: 01.01.05 | B41: PRUEBAS HIDRAULICAS | G41: =+ROUND(E41*D41,2) -> 0 | H41: =+ROUND(F41*D41,2) -> 0 | I41: =+ROUND(G41+(H41*$I$3),2) -> 0
...

Sheet IIEE
A2: INSTALACIONES ELECTRICAS
H3: T.C | I3: 3.75
A4: Presupuesto | B4: PARDO 669
A5: Subpresupuesto | B5: INSTALACIONES ELECTRICAS
A6: Cliente | B6: : V&V Bravo S.A.C | F6: Costo al | G6: 45394
A7: Lugar
A8: ITEM | B8: DESCRIPCION | C8: UND | D8: CANTIDAD | E8: P.U (S/.) | F8: P.U ($.) | G8: PARCIAL (S/.) | H8: PARCIAL ($) | I8: TOTAL
A9: 01 | B9: INSTALACIONES ELECTRICAS | G9: =SUM(G10:G189) -> 1471999.8 | H9: =SUM(H10:H189) -> 232473.31 | I9: =SUM(I10:I189) -> 2343774.8
A10: 01.01 | B10: SISTEMA DE ALUMBRADO | J10: =SUM(I12:I23,I124:I127,I135) -> 434173.61
A11: 01.01.01 | B11: SALIDAS DE ALUMBRADO
A12: 01.01.01.01 | B12: SALIDA PARA LUMINARIA EN TECHO | C12: pto | D12: 1973 | E12: 46.79 | F12: 7.9 | G12: =+ROUND(E12*D12,2) -> 92316.67 | H12: =+ROUND(F12*D12,2) -> 15586.7 | I12: =+ROUND(G12+(H12*$I$3),2) -> 150766.8
A13: 01.01.01.02 | B13: SALIDA PARA LUMINARIA DE EMERGENCIA | C13: pto | D13: 277 | E13: 46.79 | F13: 7.9 | G13: =+ROUND(E13*D13,2) -> 12960.83 | H13: =+ROUND(F13*D13,2) -> 2188.3 | I13: =+ROUND(G13+(H13*$I$3),2) -> 21166.96
A14: 01.01.01.03 | B14: SALIDA PARA LUMINARIA HERMETICA/FLUORESCENTE | C14: pto | D14: 228 | E14: 46.79 | F14: 7.9 | G14: =+ROUND(E14*D14,2) -> 10668.12 | H14: =+ROUND(F14*D14,2) -> 1801.2 | I14: =+ROUND(G14+(H14*$I$3),2) -> 17422.62
A15: 01.01.01.04 | B15: SALIDA PARA LUMINARIA TIPO ESTACA | C15: pto | D15: 37 | E15: 46.79 | F15: 7.9 | G15: =+ROUND(E15*D15,2) -> 1731.23 | H15: =+ROUND(F15*D15,2) -> 292.3 | I15: =+ROUND(G15+(H15*$I$3),2) -> 2827.36
