Workbook
Name tc: #REF!

Sheet OP
A2: OBRAS PROVISIONALES
A4: Presupuesto | B4: =#REF! -> #REF!
A5: Subpresupuesto | B5: =$A$2 -> OBRAS PROVISIONALES
A6: Cliente | B6: =#REF! -> #REF!
A7: Lugar | B7: =#REF! -> #REF!
A8: Fecha | B8: =#REF! -> #REF!
A12: ITEM | B12: DESCRIPCION | C12: UND | D12: CANTIDAD | E12: P.U. (PEN) | F12: P.U. (USD) | G12: P.U. (TOTAL) | H12: PRECIO PARCIAL (PEN) | I12: PRECIO PARCIAL (USD) | J12: PRECIO TOTAL (PEN) | K12: TOTAL
A13: 01 | B13: OBRAS PROVISIONALES, TRABAJOS PRELIMINARES
A14: =A13+0.01 -> 1.01 | B14: CONSTRUCCIONES PROVISIONALES | H14: =IFERROR(IF(D14=0,"",$D14*E14),"") | I14: =IFERROR(IF(D14=0,"",$D14*F14),"") | K14: 375184.22
A15: =GG!A13+0.0001 -> 12.0101 | B15: OFICINA DE OBRA PARA CONTRATISTA | C15: glb | D15: 1 | E15: 8532.17 | G15: 8532.17 | H15: =+ROUND(D15*E15,2) -> 8532.17 | I15: =+ROUND(D15*F15,2) -> 0 | J15: 8532.17
A16: =A15+0.0001 -> 12.0102 | B16: OFICINA DE OBRA PARA SUPERVISIÓN | C16: glb | D16: 1 | E16: 3318.85 | G16: 3318.85 | H16: =+ROUND(D16*E16,2) -> 3318.85 | I16: =+ROUND(D16*F16,2) -> 0 | J16: 3318.85
A17: =A16+0.0001 -> 12.0103 | B17: OFICINA SALA DE REUNIONES | C17: glb | D17: 1 | E17: 3318.85 | G17: 3318.85 | H17: =+ROUND(D17*E17,2) -> 3318.85 | I17: =+ROUND(D17*F17,2) -> 0 | J17: 3318.85
A18: =A17+0.0001 -> 12.0104 | B18: ALMACEN DE OBRA | C18: glb | D18: 1 | E18: 10767.51 | G18: 10767.51 | H18: =+ROUND(D18*E18,2) -> 10767.51 | I18: =+ROUND(D18*F18,2) -> 0 | J18: 10767.51
A19: =A18+0.0001 -> 12.0105 | B19: COMEDOR PERSONAL OBRERO | C19: glb | D19: 1 | E19: 6265.24 | G19: 6265.24 | H19: =+ROUND(D19*E19,2) -> 6265.24 | I19: =+ROUND(D19*F19,2) -> 0 | J19: 6265.24
A20: =A19+0.0001 -> 12.0106 | B20: VESTUARIO PARA OBREROS | C20: glb | D20: 1 | E20: 6960.37 | G20: 6960.37 | H20: =+ROUND(D20*E20,2) -> 6960.37 | I20: =+ROUND(D20*F20,2) -> 0 | J20: 6960.37
A21: =A20+0.0001 -> 12.0107 | B21: TRASLADO DE CAMPAMENTO PROVISIONAL A SOTANOS | C21: und | D21: 1 | E21: 5553.24 | G21: 5553.24 | H21: =+ROUND(D21*E21,2) -> 5553.24 | I21: =+ROUND(D21*F21,2) -> 0 | J21: 5553.24
A22: =A21+0.0001 -> 12.0108 | B22: CASETA PARA GUARDIANIA | C22: glb | D22: 1 | E22: 850 | G22: 850 | H22: =+ROUND(D22*E22,2) -> 850 | I22: =+ROUND(D22*F22,2) -> 0 | J22: 850
A23: =A22+0.0001 -> 12.0109 | B23: BAÑOS PORTATILES DE OBRA PARA PERSONAL STAFF Y SUPERVISION COMPARTIDOS | C23: mes | D23: 9.5 | E23: 780 | G23: 780 | H23: =+ROUND(D23*E23,2) -> 7410 | I23: =+ROUND(D23*F23,2) -> 0 | J23: 7410
A24: =A23+0.0001 -> 12.011 | B24: CONSTRUCCION DE SSHH (1ER NIVEL) | C24: glb | D24: 1 | E24: 10044.5 | G24: 10044.5 | H24: =+ROUND(D24*E24,2) -> 10044.5 | I24: =+ROUND(D24*F24,2) -> 0 | J24: 10044.5
A25: =A24+0.0001 -> 12.0111 | B25: SSHH PORTATILES PARA OBREROS | C25: mes | D25: 22 | E25: 330 | G25: 330 | H25: =+ROUND(D25*E25,2) -> 7260 | I25: =+ROUND(D25*F25,2) -> 0 | J25: 7260
A26: =A25+0.0001 -> 12.0112 | B26: DUCHAS PORTATILES PARA OBREROS | C26: mes | D26: 9.5 | E26: 560 | G26: 560 | H26: =+ROUND(D26*E26,2) -> 5320 | I26: =+ROUND(D26*F26,2) -> 0 | J26: 5320
A27: =A26+0.0001 -> 12.0113 | B27: ALQUILER LAVAMANOS PARA OBREROS | C27: mes | D27: 17 | E27: 660 | G27: 660 | H27: =+ROUND(D27*E27,2) -> 11220 | I27: =+ROUND(D27*F27,2) -> 0 | J27: 11220
A28: =A27+0.0001 -> 12.0114 | B28: ESCUADRAS METALICAS PARA LAS OFICINAS EN MUROS ANCLADOS | F28: 0 | H28: =+ROUND(D28*E28,2) -> 0 | I28: =+ROUND(D28*F28,2) -> 0 | J28: 0
A29: =A28+0.0001 -> 12.0115 | B29: ALQUILER DE ESCUADRAS METÁLICAS | C29: ml | D29: 65 | E29: 760 | G29: 760 | H29: =+ROUND(D29*E29,2) -> 49400 | I29: =+ROUND(D29*F29,2) -> 0 | J29: 49400
A30: =A29+0.0001 -> 12.0116 | B30: INSTALACIÓN DE ESCUADRAS METÁLICAS | C30: ml | D30: 65 | E30: 124.59 | G30: 124.59 | H30: =+ROUND(D30*E30,2) -> 8098.35 | I30: =+ROUND(D30*F30,2) -> 0 | J30: 8098.35
A31: =A30+0.0001 -> 12.0117 | B31: PERNOS DE EXPANSIÓN | C31: und | D31: 520 | F31: 8.7 | G31: 32.625 | H31: =+ROUND(D31*E31,2) -> 0 | I31: =+ROUND(D31*F31,2) -> 4524 | J31: 16965
A32: =A31+0.0001 -> 12.0118 | B32: DESISTALACION DE ESCUADRAS METÁLICAS | C32: ml | D32: 65 | E32: 49.06 | G32: 49.06 | H32: =+ROUND(D32*E32,2) -> 3188.9 | I32: =+ROUND(D32*F32,2) -> 0 | J32: 3188.9
A33: =A32+0.0001 -> 12.0119 | B33: MADERA CACHIMBO 2" X 12" X 10´, SOBRE ESCUADRAS METÁLICAS | C33: und | D33: 140 | E33: 127.5 | G33: 127.5 | H33: =+ROUND(D33*E33,2) -> 17850 | I33: =+ROUND(D33*F33,2) -> 0 | J33: 17850
A34: =A33+0.0001 -> 12.012 | B34: INSTALACIÓN Y DESISTALACIÓN DE MADERA, SOBRE ESCUADRAS METÁLICAS | C34: ml | D34: 65 | E34: 92.13 | G34: 92.13 | H34: =+ROUND(D34*E34,2) -> 5988.45 | I34: =+ROUND(D34*F34,2) -> 0 | J34: 5988.45
A35: =A34+0.0001 -> 12.0121 | B35: VENTILACION PROVISIONAL EN SOTANOS | C35: glb | D35: 1 | E35: 5250 | G35: 5250 | H35: =+ROUND(D35*E35,2) -> 5250 | I35: =+ROUND(D35*F35,2) -> 0 | J35: 5250
A36: =A35+0.0001 -> 12.0122 | B36: PROTECCIÓN DE VECINOS CON MALLA RASCHEL (ENCAPSULADO) | C36: glb | D36: 1 | E36: 104538.67 | G36: 104538.67 | H36: =+ROUND(D36*E36,2) -> 104538.67 | I36: =+ROUND(D36*F36,2) -> 0 | J36: 104538.67
A37: =A36+0.0001 -> 12.0123 | B37: RENOVACIÓN DE MALLA RACHEL | C37: glb | D37: 1 | E37: 11741.72 | G37: 11741.72 | H37: =+ROUND(D37*E37,2) -> 11741.72 | I37: =+ROUND(D37*F37,2) -> 0 | J37: 11741.72
A38: =A37+0.0001 -> 12.0124 | B38: CERCO METALICO DE OBRA | C38: ml | D38: 60 | E38: 475 | G38: 475 | H38: =+ROUND(D38*E38,2) -> 28500 | I38: =+ROUND(D38*F38,2) -> 0 | J38: 28500
A39: =A38+0.0001 -> 12.0125 | B39: BASTIDORES METALICOS PARA FIJAR MALLA DE PROTECCION + MALLA RACHELL | C39: ml | D39: 100 | E39: 100.8 | G39: 100.8 | H39: =+ROUND(D39*E39,2) -> 10080 | I39: =+ROUND(D39*F39,2) -> 0 | J39: 10080
A40: =A39+0.0001 -> 12.0126 | B40: MANTENIMIENTO A MITAD DE OBRA DE CERCO PROVISIONAL DE OBRA | C40: ml | D40: 100 | E40: 74.4 | G40: 74.4 | H40: =+ROUND(D40*E40,2) -> 7440 | I40: =+ROUND(D40*F40,2) -> 0 | J40: 7440
A41: =A40+0.0001 -> 12.0127 | B41: REUBICACION DE CERCO DE OBRA EXISTENTE | C41: ml | D41: 40 | E41: 97.21 | G41: 97.21 | H41: =+ROUND(D41*E41,2) -> 3888.4 | I41: =+ROUND(D41*F41,2) -> 0 | J41: 3888.4
A42: =A40+0.0001 -> 12.0127 | B42: DESMONTAJE DE CERCO PROVISIONAL DE OBRA | C42: ml | D42: 100 | E42: 84.84 | G42: 84.84 | H42: =+ROUND(D42*E42,2) -> 8484 | I42: =+ROUND(D42*F42,2) -> 0 | J42: 8484
A43: =A42+0.0001 -> 12.0128 | B43: PROTECCION PERIMETRAL INICIAL VERTICAL DE VECINOS | C43: glb | D43: 1 | E43: 3250 | G43: 3250 | H43: =+ROUND(D43*E43,2) -> 3250 | I43: =+ROUND(D43*F43,2) -> 0 | J43: 3250
A44: =A43+0.0001 -> 12.0129 | B44: PROTECCION HORIZONTAL INICIAL DE VECINOS | C44: glb | D44: 1 | E44: 3000 | G44: 3000 | H44: =+ROUND(D44*E44,2) -> 3000 | I44: =+ROUND(D44*F44,2) -> 0 | J44: 3000
A45: =A44+0.0001 -> 12.013 | B45: CARTEL DE OBRA | C45: glb | D45: 1 | E45: 700 | G45: 700 | H45: =+ROUND(D45*E45,2) -> 700 | I45: =+ROUND(D45*F45,2) -> 0 | J45: 700
...

Sheet SEG
A2: SEGURIDAD Y SALUD
A4: Presupuesto | B4: =#REF! -> #REF!
A5: Subpresupuesto | B5: =$A$2 -> SEGURIDAD Y SALUD
A6: Cliente | B6: =#REF! -> #REF!
A7: Lugar | B7: =#REF! -> #REF!
A8: Fecha | B8: =#REF! -> #REF!
A10: ITEM | B10: DESCRIPCION | C10: UND | D10: CANTIDAD | E10: P.U. (PEN) | F10: PARCIAL | G10: TOTAL
A11: 02 | B11: SEGURIDAD Y SALUD
A12: =A11+0.01 -> 2.01 | B12: ELABORACIÓN, IMPLEMENTACIÓN Y ADMINISTRACIÓN DEL PLAN DE SEGURIDAD Y SALUD EN EL TRABAJO | G12: =SUM(F13:F20) -> 768718.84
A13: =A12+0.0001 -> 2.0101 | B13: EQUIPOS DE PROTECCION INDIVIDUAL (STAFF Y OBREROS) | C13: glb | D13: 1 | E13: 153265.84 | F13: =+D13*E13 -> 153265.84
A14: =A13+0.0001 -> 2.0102 | B14: EQUIPOS DE PROTECCION COLECTIVA | C14: glb | D14: 1 | E14: 182518 | F14: =+D14*E14 -> 182518
A15: =A14+0.0001 -> 2.0103 | B15: MONITOREO DE AIRE Y RUIDO EN LA CONSTRUCCION (@ 6 MESES) | C15: und | D15: 4 | E15: 900 | F15: =+D15*E15 -> 3600
A16: =A15+0.0001 -> 2.0104 | B16: CONTROL DE POLVOS EN MOVIMIENTO DE TIERRAS (EXIGENCIA LEED) | C16: mes | D16: 0 | E16: 1505 | F16: =+D16*E16 -> 0
A17: =A16+0.0001 -> 2.0105 | B17: EXAMEN MÉDICO PRE-OCUPACIONAL | C17: und | D17: 190 | E17: 130 | F17: =+D17*E17 -> 24700
A18: =A17+0.0001 -> 2.0106 | B18: MALLA ANTICAIDAS (PERIMETRO EDIFICIO) | C18: glb | D18: 1 | E18: 92334 | F18: =+D18*E18 -> 92334
A19: =A18+0.0001 -> 2.0107 | B19: MALLA ANTICAIDAS (DUCTO DE ASCENSOR) | C19: glb | D19: 1 | E19: 13850.1 | F19: =+D19*E19 -> 13850.1
A20: =A19+0.0001 -> 2.0108 | B20: DESVIO DE TRANSITO (02 SEÑALERO x FRENTE) | C20: mes | D20: 22 | E20: 13565.95 | F20: =+D20*E20 -> 298450.9
A21: =A12+0.01 -> 2.02 | B21: PREVENCIONISTAS | G21: =SUM(F22:F24) -> 222950
A22: =A21+0.0001 -> 2.0201 | B22: ASISTENTES DE PDR (01) | C22: mes | D22: 17 | E22: 4455.36 | F22: =+D22*E22 -> 75741.12
A23: =A22+0.0001 -> 2.0202 | B23: AYUDANTE DE PDR N°1 (01) | C23: mes | D23: 22 | E23: 4033.12 | F23: =+D23*E23 -> 88728.64
A24: =A23+0.0001 -> 2.0203 | B24: AYUDANTE DE PDR N°2 (01) | C24: mes | D24: 14.5 | E24: 4033.12 | F24: =+D24*E24 -> 58480.24
A25: =A21+0.01 -> 2.03 | B25: SEGURIDAD POLICIAL | G25: =SUM(F26:F27) -> 8030
A26: =A25+0.0001 -> 2.0301 | B26: CAMARAS DE SEGURIDAD | C26: glb | D26: 1 | E26: 5500 | F26: =+D26*E26 -> 5500
A27: =A26+0.0001 -> 2.0302 | B27: SERVICIO MENSUAL MANTENIMIENTO | C27: mes | D27: 22 | E27: 115 | F27: =+D27*E27 -> 2530
D28: COSTO DIRECTO | G28: =SUM(G12:G27) -> 999698.84

Sheet GG
A2: GASTOS GENERALES
A4: Presupuesto | B4: =#REF! -> #REF!
A5: Subpresupuesto | B5: =A2 -> GASTOS GENERALES
A6: Cliente | B6: =#REF! -> #REF!
A7: Lugar | B7: =#REF! -> #REF!
A8: Fecha | B8: =#REF! -> #REF!
A11: ITEM | B11: DESCRIPCION | C11: UND | D11: CANTIDAD | E11: MESES | F11: PRECIO (PEN) | H11: PARCIAL | I11: TOTAL
A12: 12 | B12: GASTOS GENERALES
A13: =A12+0.01 -> 12.01 | B13: PERSONAL STAFF | I13: =SUM(H14:H28) -> 1962075
A14: =A13+0.0001 -> 12.0101 | B14: SUPERINTENDENCIA | C14: mes | D14: 1 | E14: 22 | F14: 6000 | H14: =+ROUND(D14*E14*F14,2) -> 132000
A15: =A14+0.0001 -> 12.0102 | B15: INGENIERO RESIDENTE | C15: mes | D15: 1 | E15: 23 | F15: 19500 | H15: =+ROUND(D15*E15*F15,2) -> 448500
A16: =A15+0.0001 -> 12.0103 | B16: INGENIERO DE OFICINA TECNICA | C16: mes | D16: 1 | E16: 23 | F16: 10500 | H16: =+ROUND(D16*E16*F16,2) -> 241500
A17: =A16+0.0001 -> 12.0104 | B17: INGENIERO DE CAMPO | C17: mes | D17: 1 | E17: 19 | F17: 10500 | H17: =+ROUND(D17*E17*F17,2) -> 199500
A18: =A17+0.0001 -> 12.0105 | B18: SUPERVISOR DE PROYECTOS | C18: mes | D18: 0 | E18: 22 | F18: 15000 | H18: =+ROUND(D18*E18*F18,2) -> 0
A19: =A18+0.0001 -> 12.0106 | B19: INGENIERO DE CALIDAD | C19: mes | D19: 1 | E19: 17 | F19: 8550 | H19: =+ROUND(D19*E19*F19,2) -> 145350
B20: INGENIERO DE CALIDAD JUNIOR | C20: mes | D20: 1 | E20: 6 | F20: 5250 | H20: =+ROUND(D20*E20*F20,2) -> 31500
A21: =A19+0.0001 -> 12.0107 | B21: INGENIERO ELECTROMECANICO | C21: mes | D21: 0.5 | E21: 17 | F21: 10500 | H21: =+ROUND(D21*E21*F21,2) -> 89250
A22: =A21+0.0001 -> 12.0108 | B22: ARQUITECTO DE ACABADOS | C22: mes | D22: 1 | E22: 17 | F22: 10500 | H22: =+ROUND(D22*E22*F22,2) -> 178500
B23: ARQUITECTO DE ACABADOS JUNIOR | C23: mes | D23: 1 | E23: 13.5 | F23: 5250 | H23: =+ROUND(D23*E23*F23,2) -> 70875
A24: =A22+0.0001 -> 12.0109 | B24: PREVENCIONISTA DE RIEGOS - SUBJEFE DE PDR | C24: mes | D24: 1 | E24: 22 | F24: 6750 | H24: =+ROUND(D24*E24*F24,2) -> 148500
B25: ASISTENTES DE PDR (01) | C25: mes | D25: 0 | E25: 17 | F25: 4455.36 | H25: =+ROUND(D25*E25*F25,2) -> 0
B26: AYUDANTE DE PDR N°1 (01) | C26: mes | D26: 0 | E26: 22 | F26: 4033.12 | H26: =+ROUND(D26*E26*F26,2) -> 0
A27: =A24+0.0001 -> 12.011 | B27: ADMINISTRADOR DE OBRA | C27: mes | D27: 1 | E27: 23 | F27: 6450 | H27: =+ROUND(D27*E27*F27,2) -> 148350
A28: =A27+0.0001 -> 12.0111 | B28: INGENIERO BIM | C28: mes | D28: 1 | E28: 19 | F28: 6750 | H28: =+ROUND(D28*E28*F28,2) -> 128250
A29: =A13+0.01 -> 12.02 | B29: PERSONAL TECNICO | I29: =SUM(H30:H40) -> 694399.6
A30: =A29+0.0001 -> 12.0201 | B30: ASISTENTE (CAMPO/CALIDAD/ARQ) | C30: mes | D30: 2 | E30: 12 | F30: 4200 | H30: =+ROUND(D30*E30*F30,2) -> 100800
A31: =A30+0.0001 -> 12.0202 | B31: MAESTRO DE OBRA | C31: mes | D31: 1 | E31: 15 | F31: 8010.5 | H31: =+ROUND(D31*E31*F31,2) -> 120157.5
A32: =A31+0.0001 -> 12.0203 | B32: CAPATAZ DE OBRA ESTRUCTURAS | C32: mes | D32: 1 | E32: 10 | F32: 7105.8 | H32: =+ROUND(D32*E32*F32,2) -> 71058
B33: CAPATAZ N°2 EST CASCO | C33: mes | D33: 0 | E33: 6.5 | F33: 7105.8 | H33: =+ROUND(D33*E33*F33,2) -> 0
A34: =A32+0.0001 -> 12.0204 | B34: CAPATAZ DE OBRA ARQUITECTURA N°1 | C34: mes | D34: 1 | E34: 14.5 | F34: 7105.8 | H34: =+ROUND(D34*E34*F34,2) -> 103034.1
B35: CAPATAZ DE OBRA ARQUITECTURA N°2 | C35: mes | D35: 0 | E35: 14.5 | F35: 7105.8 | H35: =+ROUND(D35*E35*F35,2) -> 0
B36: ASISTENTE DE INSTALACIONES | C36: mes | D36: 0 | E36: 17 | F36: 3100 | H36: =+ROUND(D36*E36*F36,2) -> 0
A37: =A34+0.0001 -> 12.0205 | B37: JEFE DE ALMACEN | C37: mes | D37: 1 | E37: 23 | F37: 5550 | H37: =+ROUND(D37*E37*F37,2) -> 127650
B38: ASISTENTE DE ALMACEN | C38: mes | D38: 1 | E38: 8 | F38: 4500 | H38: =+ROUND(D38*E38*F38,2) -> 36000
A39: =A37+0.0001 -> 12.0206 | B39: GUARDIAN DE OBRA Y PORTERIA | C39: mes | D39: 1 | E39: 23 | F39: 5900 | H39: =+ROUND(D39*E39*F39,2) -> 135700
B40: VIGILANTE POLICIAL DE CIVIL (TURNO NOCHE) - SERA COBRADO COMO ADICIONAL | C40: mes | D40: 0 | E40: 13.5 | F40: 6880 | H40: =+D40*E40*F40 -> 0
A41: =A29+0.01 -> 12.03 | B41: EQUIPO DE OFICINA DE LA OBRA | I41: =SUM(H42:H100) -> 71560.93
A42: =A41+0.0001 -> 12.0301 | B42: COMPUTADORAS | C42: mes | H42: =ROUND(SUM(G44:G67),2) -> 24185.22
A43: =A42+0.0001 -> 12.0302 | B43: DISGREGADO DE COMPUTADORAS
A44: 12.03.02.01 | B44: =+B15 -> INGENIERO RESIDENTE | C44: und | D44: 1 | E44: 23 | F44: 92.31 | G44: 2123.13
...

Sheet EST SOTANO
A2: ESTRUCTURAS SÓTANOS
A4: Presupuesto | B4: =OP!$B$4 -> #REF!
A5: Subpresupuesto | B5: =+$A$2 -> ESTRUCTURAS SÓTANOS
A6: Cliente | B6: =OP!$B$6 -> #REF!
A7: Lugar | B7: =OP!$B$7 -> #REF!
A8: Fecha | B8: =#REF! -> #REF!
L9: PARTIDAS ABIERTAS
A10: ITEM | B10: DESCRIPCION | C10: UND | D10: METRADO | E10: P.U. (PEN) | F10: P.U. (USD) | G10: P.U. TOTAL (PEN) | H10: PRECIO PARCIAL (PEN) | I10: PRECIO PARCIAL (USD) | J10: PRECIO TOTAL (PEN) | K10: TOTAL | L10: P.U. (PEN) | M10: PRECIO PARCIAL (PEN) | N10: P.U. (PEN) | O10: PRECIO PARCIAL (PEN) | P10: P.U. (USD) | Q10: PRECIO PARCIAL (USD)
A11: 03 | B11: =$A$2 -> ESTRUCTURAS SÓTANOS
A12: =A11+0.01 -> 3.01 | B12: OBRAS PRELIMINARES MOVIMIENTOS DE TIERRA | H12: =IFERROR(IF($D12=0,"",$D12*E12),"") | I12: =IFERROR(IF($D12=0,"",$D12*F12),"") | K12: 47280
A13: =A12+0.0001 -> 3.0101 | B13: MOVILIZACION Y DESMOVILIZACION DE EQUIPOS MOVIMIENTO TIERRAS | C13: glb | D13: 1 | E13: 6000 | G13: 6000 | H13: =+ROUND(D13*E13,2) -> 6000 | I13: =+ROUND(D13*F13,2) -> 0 | J13: 6000
A14: =A13+0.0001 -> 3.0102 | B14: EXTRACCION DE EQUIPOS MOVIMIENTO TIERRAS CON GRUAS | C14: glb | D14: 2 | E14: 6000 | G14: 6000 | H14: =+ROUND(D14*E14,2) -> 12000 | I14: =+ROUND(D14*F14,2) -> 0 | J14: 12000
A15: =A14+0.0001 -> 3.0103 | B15: INSTALACION Y DESISTALACION DE PLATAFORMA | C15: glb | D15: 1 | E15: 11000 | G15: 11000 | H15: =+ROUND(D15*E15,2) -> 11000 | I15: =+ROUND(D15*F15,2) -> 0 | J15: 11000
A16: =A15+0.0001 -> 3.0104 | B16: EXTRACCION DE EQUIPOS PERFORACION CON GRUAS | C16: glb | D16: 4 | F16: 720 | G16: 2700 | H16: =+ROUND(D16*E16,2) -> 0 | I16: =+ROUND(D16*F16,2) -> 2880 | J16: 10800
A17: =A16+0.0001 -> 3.0105 | B17: CONTROL DE POLVOS (AGUA EN CISTERNA) | C17: vje | D17: 22 | E17: 340 | G17: 340 | H17: =+ROUND(D17*E17,2) -> 7480 | I17: =+ROUND(D17*F17,2) -> 0 | J17: 7480
A18: =A12+0.01 -> 3.02 | B18: MOVIMIENTO DE TIERRAS | K18: 937375.07
A19: =A18+0.0001 -> 3.0201 | B19: EXCAVACIÓN Y ELIMINACIÓN MASIVA POR NIVEL
A20: =A19+0.000001 -> 3.020101 | B20: CORTE Y ELIMINACION DE +0.00 a -3.80 (SOTANO 01) | C20: m3 | D20: 5291.24 | E20: 23 | G20: 23 | H20: =+ROUND(D20*E20,2) -> 121698.52 | I20: =+ROUND(D20*F20,2) -> 0 | J20: 121698.52
A21: =A20+0.000001 -> 3.020102 | B21: CORTE Y ELIMINACION DE -3.88 a -6.68 (SOTANO 02) | C21: m3 | D21: 3823.35 | E21: 24 | G21: 24 | H21: =+ROUND(D21*E21,2) -> 91760.4 | I21: =+ROUND(D21*F21,2) -> 0 | J21: 91760.4
A22: =A21+0.000001 -> 3.020103 | B22: CORTE Y ELIMINACION DE -6.68 a -9.40 (SOTANO 03) | C22: m3 | D22: 3823.35 | E22: 25 | G22: 25 | H22: =+ROUND(D22*E22,2) -> 95583.75 | I22: =+ROUND(D22*F22,2) -> 0 | J22: 95583.75
A23: =A22+0.000001 -> 3.020104 | B23: CORTE Y ELIMINACION DE -9.40 a -12.20 (SOTANO 04) | C23: m3 | D23: 3823.35 | E23: 28 | G23: 28 | H23: =+ROUND(D23*E23,2) -> 107053.8 | I23: =+ROUND(D23*F23,2) -> 0 | J23: 107053.8
A24: =A23+0.000001 -> 3.020105 | B24: CORTE Y ELIMINACION DE -12.28 a -15,08 (SOTANO 05) | C24: m3 | D24: 3823.35 | E24: 28 | G24: 28 | H24: =+ROUND(D24*E24,2) -> 107053.8 | I24: =+ROUND(D24*F24,2) -> 0 | J24: 107053.8
A25: =A24+0.000001 -> 3.020106 | B25: CORTE Y ELIMINACION DE -15,08 a -18,28 (SOTANO 06) CON BALDE Y GRUA | C25: m3 | D25: 2847.93 | E25: 38 | G25: 38 | H25: =+ROUND(D25*E25,2) -> 108221.34 | I25: =+ROUND(D25*F25,2) -> 0 | J25: 108221.34
A26: =A19+0.0001 -> 3.0202 | B26: EXCAVACIÓN Y ELIMINACIÓN LOCALIZADA | G26: 0 | H26: =+ROUND(D26*E26,2) -> 0 | I26: =+ROUND(D26*F26,2) -> 0 | J26: 0
A27: =A26+0.000001 -> 3.020201 | B27: EXCAVACION Y ELIIMINACION DE ZAPATAS Y CIMIENTOS (N -20,87) CON BALDE Y GRUA | C27: m3 | D27: 568.11 | E27: 38 | G27: 38 | H27: =+ROUND(D27*E27,2) -> 21588.18 | I27: =+ROUND(D27*F27,2) -> 0 | J27: 21588.18
A28: =A27+0.000001 -> 3.020202 | B28: EXCAVACION Y ELIIMINACION DE CISTERNA Y CUARTO DE BOMBAS (N -20.80) CON BALDE Y GRUA | C28: m3 | D28: 1298.68 | E28: 38 | G28: 38 | H28: =+ROUND(D28*E28,2) -> 49349.84 | I28: =+ROUND(D28*F28,2) -> 0 | J28: 49349.84
A29: =A28+0.000001 -> 3.020203 | B29: EXCAVACION LOCALIZADA PARA VIGAS DE CIMENTACION | C29: m3 | D29: 2.6 | E29: 40.72 | G29: 40.72 | H29: =+ROUND(D29*E29,2) -> 105.87 | I29: =+ROUND(D29*F29,2) -> 0 | J29: 105.87
A30: =A29+0.000001 -> 3.020204 | B30: EXCAVACION LOCALIZADA PARA CIMIENTOS (BATEA DE CIMENTACION) | C30: m3 | D30: 3.49 | E30: 40.72 | G30: 40.72 | H30: =+ROUND(D30*E30,2) -> 142.11 | I30: =+ROUND(D30*F30,2) -> 0 | J30: 142.11
A31: =A30+0.000001 -> 3.020205 | B31: EXCAVACION LOCALIZADA PARA POZO SUMIDERO Y TRAMPA DE GRASA | C31: m3 | D31: 3.74 | E31: 40.72 | G31: 40.72 | H31: =+ROUND(D31*E31,2) -> 152.29 | I31: =+ROUND(D31*F31,2) -> 0 | J31: 152.29
A32: =A31+0.000001 -> 3.020206 | B32: EXCAVACION LOCALIZADA PARA FALSA ZAPATA | C32: m3 | D32: 87.16 | E32: 40.72 | G32: 40.72 | H32: =+ROUND(D32*E32,2) -> 3549.16 | I32: =+ROUND(D32*F32,2) -> 0 | J32: 3549.16
A33: =A31+0.000001 -> 3.020206 | B33: ACARREO Y ELIMINACION DE MATERIAL EXCEDENTE | C33: m3 | D33: 126.09 | E33: 38.52 | G33: 38.52 | H33: =+ROUND(D33*E33,2) -> 4856.99 | I33: =+ROUND(D33*F33,2) -> 0 | J33: 4856.99
A34: =A26+0.0001 -> 3.0203 | B34: ELIMINACIÓN DE CIMENTACIÓN EXISTENTE
A35: =A34+0.000001 -> 3.020301 | B35: DEMOLICIÓN DE CIMENTACIÓN DE VECINOS | C35: ml | D35: 0 | E35: 75 | G35: 75 | H35: =+ROUND(D35*E35,2) -> 0 | I35: =+ROUND(D35*F35,2) -> 0 | J35: 0
A36: =A35+0.000001 -> 3.020302 | B36: ELIMINACIÓN DE CIMENTACIÓN | C36: m3 | D36: 0 | E36: 35 | G36: 35 | H36: =+ROUND(D36*E36,2) -> 0 | I36: =+ROUND(D36*F36,2) -> 0 | J36: 0
A37: =A34+0.0001 -> 3.0204 | B37: RELLENO Y COMPACTACIÓN
A38: =A37+0.000001 -> 3.020401 | B38: RELLENO COMPACTADO CON MATERIAL PROPIO | C38: m3 | D38: 106.37 | E38: 54.02 | G38: 54.02 | H38: =+ROUND(D38*E38,2) -> 5746.11 | I38: =+ROUND(D38*F38,2) -> 0 | J38: 5746.11
A39: =A38+0.000001 -> 3.020402 | B39: RELLENO BAJO RAMPA CON MATERIAL PROPIO | C39: m3 | D39: 238.86 | E39: 54.02 | G39: 54.02 | H39: =+ROUND(D39*E39,2) -> 12903.22 | I39: =+ROUND(D39*F39,2) -> 0 | J39: 12903.22
A40: =A37+0.0001 -> 3.0205 | B40: NIVELACIÓN, APISONADO Y BASE DE AFIRMADO | G40: 0 | H40: =+ROUND(D40*E40,2) -> 0 | I40: =+ROUND(D40*F40,2) -> 0 | J40: 0
A41: =A40+0.000001 -> 3.020501 | B41: NIVELACION Y COMPACTACION DE SUBRASANTE | C41: m2 | D41: 1313.23 | E41: 6.6 | G41: 6.6 | H41: =+ROUND(D41*E41,2) -> 8667.32 | I41: =+ROUND(D41*F41,2) -> 0 | J41: 8667.32
A42: =A41+0.000001 -> 3.020502 | B42: BASE DE AFIRMADO COMPACTADO, E=20CM (conforme a EMS) | C42: m2 | D42: 1313.23 | E42: 40.95 | G42: 40.95 | H42: =+ROUND(D42*E42,2) -> 53776.77 | I42: =+ROUND(D42*F42,2) -> 0 | J42: 53776.77
...

Sheet EST TORRE
A2: ESTRUCTURAS TORRE
A4: Presupuesto | B4: =#REF! -> #REF!
A5: Subpresupuesto | B5: =+$A$2 -> ESTRUCTURAS TORRE
A6: Cliente | B6: =#REF! -> #REF!
A7: Lugar | B7: =#REF! -> #REF!
A8: Fecha | B8: =#REF! -> #REF!
L9: PARTIDAS ABIERTAS
A10: ITEM | B10: DESCRIPCION | C10: UND | D10: METRADO | E10: P.U. (PEN) | F10: P.U. (USD) | G10: P.U. TOTAL (PEN) | H10: PRECIO PARCIAL (PEN) | I10: PRECIO PARCIAL (USD) | J10: PRECIO TOTAL (PEN) | K10: TOTAL | L10: P.U. (PEN) | M10: PRECIO PARCIAL (PEN) | N10: P.U. (PEN) | O10: PRECIO PARCIAL (PEN) | P10: P.U. (USD) | Q10: PRECIO PARCIAL (USD)
A11: 04 | B11: =$A$2 -> ESTRUCTURAS TORRE
A12: =A11+0.01 -> 4.01 | B12: CONCRETO ARMADO | K12: 8736275.2
A13: =A12+0.0001 -> 4.0101 | B13: PLACAS | H13: =IFERROR(IF($D13=0,"",$D13*E13),"") | I13: =IFERROR(IF($D13=0,"",$D13*F13),"")
A14: =A13+0.000001 -> 4.010101 | B14: CONCRETO PREMEZCLADO, CEMENTO TIPO I, PLACAS f'c=210 kg/cm2 | C14: m3 | D14: 0 | E14: 385.27 | G14: 385.27 | H14: =+ROUND(D14*E14,2) -> 0 | I14: =+ROUND(D14*F14,2) -> 0 | J14: 0
A15: =A13+0.000001 -> 4.010101 | B15: CONCRETO PREMEZCLADO, CEMENTO TIPO I, PLACAS f'c=245 kg/cm2 | C15: m3 | D15: 288.37 | E15: 397.9 | G15: 397.9 | H15: =+ROUND(D15*E15,2) -> 114742.42 | I15: =+ROUND(D15*F15,2) -> 0 | J15: 114742.42 | N15: 355.79 | O15: =+N15*D15 -> 102599.16
A16: =A14+0.000001 -> 4.010102 | B16: CONCRETO PREMEZCLADO, CEMENTO TIPO I, PLACAS f'c=280 kg/cm2 | C16: m3 | D16: 561.5 | E16: 414.41 | G16: 414.41 | H16: =+ROUND(D16*E16,2) -> 232691.22 | I16: =+ROUND(D16*F16,2) -> 0 | J16: 232691.22 | N16: 372.3 | O16: =+N16*D16 -> 209046.45
A17: =A15+0.000001 -> 4.010102 | B17: CONCRETO PREMEZCLADO, CEMENTO TIPO I, PLACAS f'c=350 kg/cm2 | C17: m3 | D17: 128.38 | E17: 453.3 | G17: 453.3 | H17: =+ROUND(D17*E17,2) -> 58194.65 | I17: =+ROUND(D17*F17,2) -> 0 | J17: 58194.65 | N17: 411.19 | O17: =+N17*D17 -> 52788.572
A18: =A16+0.000001 -> 4.010103 | B18: CONCRETO PREMEZCLADO, CEMENTO TIPO I, PLACAS f'c=420 kg/cm2 | C18: m3 | D18: 0 | E18: 469.55 | G18: 469.55 | H18: =+ROUND(D18*E18,2) -> 0 | I18: =+ROUND(D18*F18,2) -> 0 | J18: 0 | O18: =+N18*D18 -> 0
A19: =A16+0.000001 -> 4.010103 | B19: ENCOFRADO Y DESENCOFRADO DE MUROS Y PLACAS | C19: m2 | D19: 5184.73 | E19: 43.7 | G19: 43.7 | H19: =+ROUND(D19*E19,2) -> 226572.7 | I19: =+ROUND(D19*F19,2) -> 0 | J19: 226572.7
A20: =A19+0.000001 -> 4.010104 | B20: ENCOFRADO Y DESENCOFRADO DE MUROS Y PLACAS DOBLE ALTURA | C20: m2 | D20: 313.4 | E20: 48.7 | G20: 48.7 | H20: =+ROUND(D20*E20,2) -> 15262.58 | I20: =+ROUND(D20*F20,2) -> 0 | J20: 15262.58
A21: =A19+0.000001 -> 4.010104 | B21: ACERO DE REFUERZO FY= 4200 kg/cm2, GRADO 60 | C21: kg | D21: 109660.91 | E21: 1.15 | F21: 0.94 | G21: 4.68 | H21: =+ROUND(D21*E21,2) -> 126110.05 | I21: =+ROUND(D21*F21,2) -> 103081.26 | J21: 512664.78 | P21: 0.94 | Q21: =+P21*D21 -> 103081.26
A22: =A21+0.000001 -> 4.010105 | B22: CURADO DE ELEMENTOS ESTRUCTURALES EXPUESTOS | C22: m2 | D22: 5498.13 | E22: 1.5 | G22: 1.5 | H22: =+ROUND(D22*E22,2) -> 8247.2 | I22: =+ROUND(D22*F22,2) -> 0 | J22: 8247.2
A23: =A13+0.0001 -> 4.0102 | B23: MUROS P/ JARDINERAS - CORTES TECHO SOTANO 01 | D23: 0
A24: =A23+0.000001 -> 4.010201 | B24: CONCRETO PREMEZCLADO, CEMENTO TIPO I, PISCINA f'c=280 kg/cm2 (W/C=0.50).Por procedimiento constructivo | C24: m3 | D24: 18.69 | E24: 481.45 | G24: 481.45 | H24: =+ROUND(D24*E24,2) -> 8998.3 | I24: =+ROUND(D24*F24,2) -> 0 | J24: 8998.3 | N24: 432.55 | O24: =+N24*D24 -> 8084.3595
A25: =A24+0.000001 -> 4.010202 | B25: ENCOFRADO Y DESENCOFRADO DE MUROS Y PLACAS | C25: m2 | D25: 266.96 | E25: 43.7 | G25: 43.7 | H25: =+ROUND(D25*E25,2) -> 11666.15 | I25: =+ROUND(D25*F25,2) -> 0 | J25: 11666.15
A26: =A25+0.000001 -> 4.010203 | B26: ACERO DE REFUERZO FY= 4200 kg/cm2, GRADO 60 | C26: kg | D26: 2093.41 | E26: 1.15 | F26: 0.94 | G26: 4.68 | H26: =+ROUND(D26*E26,2) -> 2407.42 | I26: =+ROUND(D26*F26,2) -> 1967.81 | J26: 9786.71 | P26: 0.94 | Q26: =+P26*D26 -> 1967.8054
A27: =A26+0.000001 -> 4.010204 | B27: CURADO DE ELEMENTOS ESTRUCTURALES EXPUESTOS | C27: m2 | D27: 266.96 | E27: 1.5 | G27: 1.5 | H27: =+ROUND(D27*E27,2) -> 400.44 | I27: =+ROUND(D27*F27,2) -> 0 | J27: 400.44
A28: =A23+0.0001 -> 4.0103 | B28: COLUMNAS | D28: 0
A29: =A28+0.000001 -> 4.010301 | B29: CONCRETO PREMEZCLADO, CEMENTO TIPO I, COLUMNAS f'c=210 kg/cm2 | C29: m3 | D29: 0 | E29: 387.1 | G29: 387.1 | H29: =+ROUND(D29*E29,2) -> 0 | I29: =+ROUND(D29*F29,2) -> 0 | J29: 0 | O29: =+N29*D29 -> 0
A30: =A28+0.000001 -> 4.010301 | B30: CONCRETO PREMEZCLADO, CEMENTO TIPO I, COLUMNAS f'c=245 kg/cm2 | C30: m3 | D30: 335.96 | E30: 399.73 | G30: 399.73 | H30: =+ROUND(D30*E30,2) -> 134293.29 | I30: =+ROUND(D30*F30,2) -> 0 | J30: 134293.29 | N30: 355.79 | O30: =+N30*D30 -> 119531.21
A31: =A29+0.000001 -> 4.010302 | B31: CONCRETO PREMEZCLADO, CEMENTO TIPO I, COLUMNAS f'c=280 kg/cm2 | C31: m3 | D31: 257.65 | E31: 416.24 | G31: 416.24 | H31: =+ROUND(D31*E31,2) -> 107244.24 | I31: =+ROUND(D31*F31,2) -> 0 | J31: 107244.24 | N31: 372.3 | O31: =+N31*D31 -> 95923.095
A32: =A31+0.000001 -> 4.010303 | B32: CONCRETO PREMEZCLADO, CEMENTO TIPO I, COLUMNAS f'c=350 kg/cm2 | C32: m3 | D32: 173.33 | E32: 455.13 | G32: 455.13 | H32: =+ROUND(D32*E32,2) -> 78887.68 | I32: =+ROUND(D32*F32,2) -> 0 | J32: 78887.68 | N32: 411.19 | O32: =+N32*D32 -> 71271.563
A33: =A32+0.000001 -> 4.010304 | B33: CONCRETO PREMEZCLADO, CEMENTO TIPO I, COLUMNAS f'c=420 kg/cm2 | C33: m3 | D33: 132.64 | E33: 471.38 | G33: 471.38 | H33: =+ROUND(D33*E33,2) -> 62523.84 | I33: =+ROUND(D33*F33,2) -> 0 | J33: 62523.84 | N33: 427.44 | O33: =+N33*D33 -> 56695.642
A34: =A33+0.000001 -> 4.010305 | B34: ENCOFRADO Y DESENCOFRADO DE COLUMNAS | C34: m2 | D34: 5545.95 | E34: 44.6 | G34: 44.6 | H34: =+ROUND(D34*E34,2) -> 247349.37 | I34: =+ROUND(D34*F34,2) -> 0 | J34: 247349.37
A35: =A34+0.000001 -> 4.010306 | B35: ENCOFRADO Y DESENCOFRADO DE COLUMNAS DOBLE ALTURA | C35: m2 | D35: 379.72 | E35: 49.6 | G35: 49.6 | H35: =+ROUND(D35*E35,2) -> 18834.11 | I35: =+ROUND(D35*F35,2) -> 0 | J35: 18834.11
A36: =A35+0.000001 -> 4.010307 | B36: ACERO DE REFUERZO FY= 4200 kg/cm2, GRADO 60 | C36: kg | D36: 261703.74 | E36: 1.15 | F36: 0.94 | G36: 4.68 | H36: =+ROUND(D36*E36,2) -> 300959.3 | I36: =+ROUND(D36*F36,2) -> 246001.52 | J36: 1223465 | P36: 0.94 | Q36: =+P36*D36 -> 246001.52
A37: =A36+0.000001 -> 4.010308 | B37: CURADO DE ELEMENTOS ESTRUCTURALES EXPUESTOS | C37: m2 | D37: 5925.67 | E37: 1.5 | G37: 1.5 | H37: =+ROUND(D37*E37,2) -> 8888.51 | I37: =+ROUND(D37*F37,2) -> 0 | J37: 8888.51
A38: =A28+0.0001 -> 4.0104 | B38: VIGAS | D38: 0
A39: =A38+0.000001 -> 4.010401 | B39: CONCRETO PREMEZCLADO, CEMENTO TIPO I, VIGAS TORRE f'c=245 kg/cm2 | C39: m3 | D39: 1665.61 | E39: 392.8 | G39: 392.8 | H39: =+ROUND(D39*E39,2) -> 654251.61 | I39: =+ROUND(D39*F39,2) -> 0 | J39: 654251.61 | N39: 352.38 | O39: =+N39*D39 -> 586927.65
A40: =A39+0.000001 -> 4.010402 | B40: CONCRETO PREMEZCLADO, CEMENTO TIPO I, VIGAS TORRE f'c=350 kg/cm2 (NUCLEOS) | C40: m3 | D40: 13.45 | E40: 451.61 | G40: 451.61 | H40: =+ROUND(D40*E40,2) -> 6074.15 | I40: =+ROUND(D40*F40,2) -> 0 | J40: 6074.15 | N40: 411.19 | O40: =+N40*D40 -> 5530.5055
A41: =A40+0.000001 -> 4.010403 | B41: CONCRETO PREMEZCLADO, CEMENTO TIPO I, VIGAS TORRE f'c=420 kg/cm2 (NUCLEOS) | C41: m3 | D41: 25.26 | E41: 467.86 | G41: 467.86 | H41: =+ROUND(D41*E41,2) -> 11818.14 | I41: =+ROUND(D41*F41,2) -> 0 | J41: 11818.14 | N41: 427.44 | O41: =+N41*D41 -> 10797.134
A42: =A41+0.000001 -> 4.010404 | B42: ENCOFRADO Y DESENCOFRADO DE VIGAS | C42: m2 | D42: 6882.68 | E42: 54.6 | G42: 54.6 | H42: =+ROUND(D42*E42,2) -> 375794.33 | I42: =+ROUND(D42*F42,2) -> 0 | J42: 375794.33
...

Sheet ARQ SOT
B2: ARQUITECTURA SÓTANOS
B4: Presupuesto | C4: =+#REF! -> #REF!
B5: Subpresupuesto | C5: =$B$2 -> ARQUITECTURA SÓTANOS
B6: Cliente | C6: =+#REF! -> #REF!
B7: Lugar | C7: SAN ISIDRO
B8: Fecha | C8: =+#REF! -> #REF!
M9: Partidas abiertas
B10: ITEM | C10: DESCRIPCION | D10: UND | E10: METRADO | F10: P.U. (PEN) | G10: P.U. (USD) | H10: P.U. TOTAL (PEN) | I10: PRECIO PARCIAL (PEN) | J10: PRECIO PARCIAL (USD) | K10: PARCIAL TOTAL (PEN) | L10: TOTAL | M10: P.U. (PEN) | N10: PRECIO PARCIAL (PEN) | O10: P.U. (USD) | P10: PRECIO PARCIAL (USD)
B11: 05 | C11: =$B$2 -> ARQUITECTURA SÓTANOS
B12: =B11+0.01 -> 5.01 | C12: MUROS Y TABIQUES | I12: =IFERROR(IF($E12=0,"",$E12*F12),"") | J12: =IFERROR(IF($E12=0,"",$E12*G12),"") | L12: 232941.24
B13: =B12+0.0001 -> 5.0101 | C13: MUROS Y TABIQUES SILICO CALCAREOS | I13: =IFERROR(IF($E13=0,"",$E13*F13),"") | J13: =IFERROR(IF($E13=0,"",$E13*G13),"")
B14: =B12+0.0001 -> 5.0101 | C14: ALTURA < 2.60 | I14: =IFERROR(IF($E14=0,"",$E14*F14),"") | J14: =IFERROR(IF($E14=0,"",$E14*G14),"")
B15: =B14+0.000001 -> 5.010101 | C15: LADRILLO SILICO CALCAREO TIPO P7 H<2.6M | D15: m2 | F15: 99.22 | H15: 99.22 | I15: =+ROUND(E15*F15,2) -> 0 | J15: =+ROUND(E15*G15,2) -> 0 | K15: 0 | M15: 99.22 | N15: =+M15*E15 -> 0
B16: =B15+0.000001 -> 5.010102 | C16: LADRILLO SILICO CALCAREO TIPO P10 H<2.6M | D16: m2 | E16: 413.25 | F16: 108.22 | H16: 108.22 | I16: =+ROUND(E16*F16,2) -> 44721.92 | J16: =+ROUND(E16*G16,2) -> 0 | K16: 44721.92 | M16: 108.22 | N16: =+M16*E16 -> 44721.915
B17: =B16+0.000001 -> 5.010103 | C17: LADRILLO SILICO CALCAREO TIPO P12 H<2.6M | D17: m2 | E17: 116.3 | F17: 113.22 | H17: 113.22 | I17: =+ROUND(E17*F17,2) -> 13167.49 | J17: =+ROUND(E17*G17,2) -> 0 | K17: 13167.49 | M17: 113.22 | N17: =+M17*E17 -> 13167.486
B18: =B17+0.000001 -> 5.010104 | C18: LADRILLO SILICO CALCAREO TIPO P14 H<2.6M | D18: m2 | E18: 27.64 | F18: 119.22 | H18: 119.22 | I18: =+ROUND(E18*F18,2) -> 3295.24 | J18: =+ROUND(E18*G18,2) -> 0 | K18: 3295.24 | M18: 119.22 | N18: =+M18*E18 -> 3295.2408
B19: =B18+0.000001 -> 5.010105 | C19: LADRILLO SILICO CALCAREO TIPO P20 H<2.6M | D19: m2 | E19: 40.91 | F19: 198.22 | H19: 198.22 | I19: =+ROUND(E19*F19,2) -> 8109.18 | J19: =+ROUND(E19*G19,2) -> 0 | K19: 8109.18 | M19: 198.22 | N19: =+M19*E19 -> 8109.1802
B20: =B19+0.000001 -> 5.010106 | C20: LADRILLO SILICO CALCAREO TIPO P25 H<2.6M | D20: m2 | E20: 8.62 | F20: 198.22 | H20: 198.22 | I20: =+ROUND(E20*F20,2) -> 1708.66 | J20: =+ROUND(E20*G20,2) -> 0 | K20: 1708.66 | M20: 198.22 | N20: =+M20*E20 -> 1708.6564
B21: =B20+0.000001 -> 5.010107 | C21: LADRILLO SILICO CALCAREO TIPO P30 H<2.6M | D21: m2 | E21: 49.78 | F21: 198.22 | H21: 198.22 | I21: =+ROUND(E21*F21,2) -> 9867.39 | J21: =+ROUND(E21*G21,2) -> 0 | K21: 9867.39 | M21: 198.22 | N21: =+M21*E21 -> 9867.3916
B22: =B21+0.000001 -> 5.010108 | C22: LADRILLO SILICO CALCAREO TIPO P40 H<2.6M | D22: m2 | E22: 53.3 | F22: 236.22 | H22: 236.22 | I22: =+ROUND(E22*F22,2) -> 12590.53 | J22: =+ROUND(E22*G22,2) -> 0 | K22: 12590.53 | M22: 236.22 | N22: =+M22*E22 -> 12590.526
B23: =B14+0.0001 -> 5.0102 | C23: ALTURA > 2.60 | M23: 0 | N23: =+M23*E23 -> 0
B24: =B23+0.000001 -> 5.010201 | C24: LADRILLO SILICO CALCAREO TIPO P7 H>2.6M | D24: m2 | F24: 99.22 | H24: 99.22 | I24: =+ROUND(E24*F24,2) -> 0 | J24: =+ROUND(E24*G24,2) -> 0 | K24: 0 | M24: 99.22 | N24: =+M24*E24 -> 0
B25: =B24+0.000001 -> 5.010202 | C25: LADRILLO SILICO CALCAREO TIPO P10 H>2.6M | D25: m2 | E25: 148.3 | F25: 110.22 | H25: 110.22 | I25: =+ROUND(E25*F25,2) -> 16345.63 | J25: =+ROUND(E25*G25,2) -> 0 | K25: 16345.63 | M25: 110.22 | N25: =+M25*E25 -> 16345.626
B26: =B25+0.000001 -> 5.010203 | C26: LADRILLO SILICO CALCAREO TIPO P12 H>2.6M | D26: m2 | E26: 24.82 | F26: 116.22 | H26: 116.22 | I26: =+ROUND(E26*F26,2) -> 2884.58 | J26: =+ROUND(E26*G26,2) -> 0 | K26: 2884.58 | M26: 116.22 | N26: =+M26*E26 -> 2884.5804
B27: =B26+0.000001 -> 5.010204 | C27: LADRILLO SILICO CALCAREO TIPO P14 H>2.6M | D27: m2 | E27: 5.24 | F27: 124.22 | H27: 124.22 | I27: =+ROUND(E27*F27,2) -> 650.91 | J27: =+ROUND(E27*G27,2) -> 0 | K27: 650.91 | M27: 124.22 | N27: =+M27*E27 -> 650.9128
B28: =B27+0.000001 -> 5.010205 | C28: LADRILLO SILICO CALCAREO TIPO P20 H>2.6M | D28: m2 | E28: 20.83 | F28: 208.22 | H28: 208.22 | I28: =+ROUND(E28*F28,2) -> 4337.22 | J28: =+ROUND(E28*G28,2) -> 0 | K28: 4337.22 | M28: 208.22 | N28: =+M28*E28 -> 4337.2226
B29: =B28+0.000001 -> 5.010206 | C29: LADRILLO SILICO CALCAREO TIPO P40 H>2.6M | D29: m2 | E29: 19.95 | F29: 230.22 | H29: 230.22 | I29: =+ROUND(E29*F29,2) -> 4592.89 | J29: =+ROUND(E29*G29,2) -> 0 | K29: 4592.89 | M29: 230.22 | N29: =+M29*E29 -> 4592.889
B30: =B27+0.0001 -> 5.010304 | C30: CORTAFUEGO < 2.60 | M30: 0 | N30: =+M30*E30 -> 0
B31: =B30+0.000001 -> 5.010305 | C31: LADRILLO SILICO CALCAREO TIPO P10 RF:2 HRS H<2.6M (ALVEOLOS COMPLETAMENTE LLENO) | D31: m2 | E31: 97 | F31: 112.22 | H31: 112.22 | I31: =+ROUND(E31*F31,2) -> 10885.34 | J31: =+ROUND(E31*G31,2) -> 0 | K31: 10885.34 | M31: 112.22 | N31: =+M31*E31 -> 10885.34
B32: =B31+0.000001 -> 5.010306 | C32: LADRILLO SILICO CALCAREO TIPO P12 RF:2 HRS H<2.6M (ALVEOLOS PARCIALMENTE LLENO) | D32: m2 | E32: 281.5 | F32: 113.22 | H32: 113.22 | I32: =+ROUND(E32*F32,2) -> 31871.43 | J32: =+ROUND(E32*G32,2) -> 0 | K32: 31871.43 | M32: 113.22 | N32: =+M32*E32 -> 31871.43
B33: =B32+0.000001 -> 5.010307 | C33: LADRILLO SILICO CALCAREO TIPO P14 RF:2 HRS H<2.6M (ALVEOLOS PARCIALMENTE LLENO) | D33: m2 | E33: 56.01 | F33: 119.22 | H33: 119.22 | I33: =+ROUND(E33*F33,2) -> 6677.51 | J33: =+ROUND(E33*G33,2) -> 0 | K33: 6677.51 | M33: 119.22 | N33: =+M33*E33 -> 6677.5122
B34: =B23+0.0001 -> 5.0103 | C34: CORTAFUEGO > 2.60 | M34: 0 | N34: =+M34*E34 -> 0
B35: =B34+0.000001 -> 5.010301 | C35: LADRILLO SILICO CALCAREO TIPO P10 RF:2 HRS H>2.6M (ALVEOLOS COMPLETAMENTE LLENO) | D35: m2 | E35: 34.42 | F35: 116.22 | H35: 116.22 | I35: =+ROUND(E35*F35,2) -> 4000.29 | J35: =+ROUND(E35*G35,2) -> 0 | K35: 4000.29 | M35: 116.22 | N35: =+M35*E35 -> 4000.2924
B36: =B35+0.000001 -> 5.010302 | C36: LADRILLO SILICO CALCAREO TIPO P12 RF:2 HRS H>2.6M (ALVEOLOS PARCIALMENTE LLENO) | D36: m2 | E36: 233.11 | F36: 116.22 | H36: 116.22 | I36: =+ROUND(E36*F36,2) -> 27092.04 | J36: =+ROUND(E36*G36,2) -> 0 | K36: 27092.04 | M36: 116.22 | N36: =+M36*E36 -> 27092.044
B37: =B36+0.000001 -> 5.010303 | C37: LADRILLO SILICO CALCAREO TIPO P14 RF:2 HRS H>2.6M (ALVEOLOS PARCIALMENTE LLENO) | D37: m2 | E37: 29.36 | F37: 124.22 | H37: 124.22 | I37: =+ROUND(E37*F37,2) -> 3647.1 | J37: =+ROUND(E37*G37,2) -> 0 | K37: 3647.1 | M37: 124.22 | N37: =+M37*E37 -> 3647.0992
B38: =B37+0.000001 -> 5.010304 | C38: LADRILLO SILICO CALCAREO TIPO P30 RF:2 HRS H>2.6M (ALVEOLOS COMPLETAMENTE LLENO) | D38: m2 | E38: 4.46 | F38: 232.44 | H38: 232.44 | I38: =+ROUND(E38*F38,2) -> 1036.68 | J38: =+ROUND(E38*G38,2) -> 0 | K38: 1036.68 | M38: 232.44 | N38: =+M38*E38 -> 1036.6824
B39: =B34+0.0001 -> 5.0104 | C39: ACERO DE REFUERZO
B40: =B39+0.000001 -> 5.010401 | C40: ACERO DE REFUERZO FY= 4200 kg/cm2 GRADO 60 PARA TABIQUERÍA | D40: kg | E40: 2846.85 | F40: 0 | G40: 0.94 | H40: 3.53 | I40: =+ROUND(E40*F40,2) -> 0 | J40: =+ROUND(E40*G40,2) -> 2676.04 | K40: 10035.15 | O40: 0.94 | P40: =+O40*E40 -> 2676.039
B41: =B39+0.0001 -> 5.0105 | C41: DINTELES
B42: =B41+0.000001 -> 5.010501 | C42: DINTELES DE LADRILLOS SILICO CALCAREO | D42: und | E42: 52 | F42: 120 | H42: 120 | I42: =+ROUND(E42*F42,2) -> 6240 | J42: =+ROUND(E42*G42,2) -> 0 | K42: 6240 | M42: 120 | N42: =+M42*E42 -> 6240
...

Sheet ARQ TORRE
B2: ARQUITECTURA TORRE
B4: Presupuesto | C4: =OP!$B$4 -> #REF!
B5: Subpresupuesto | C5: =$B$2 -> ARQUITECTURA TORRE
B6: Cliente | C6: =OP!$B$6 -> #REF!
B7: Lugar | C7: =OP!$B$7 -> #REF!
B8: Fecha | C8: =#REF! -> #REF!
M9: Partidas abiertas
B10: ITEM | C10: DESCRIPCION | D10: UND | E10: METRADO | F10: P.U. (PEN) | G10: P.U. (USD) | H10: P.U. TOTAL (PEN) | I10: PRECIO PARCIAL (PEN) | J10: PRECIO PARCIAL (USD) | K10: PARCIAL TOTAL (PEN) | L10: TOTAL | M10: P.U. (PEN) | N10: PRECIO PARCIAL (PEN) | O10: P.U. (USD) | P10: PRECIO PARCIAL (USD)
B11: 06 | C11: =$B$2 -> ARQUITECTURA TORRE
B12: =B11+0.01 -> 6.01 | C12: MUROS Y TABIQUES | I12: =IFERROR(IF($E12=0,"",$E12*F12),"") | J12: =IFERROR(IF($E12=0,"",$E12*G12),"") | L12: 4448978.1
B13: =B12+0.0001 -> 6.0101 | C13: MUROS Y TABIQUES SILICO CALCAREOS | I13: =IFERROR(IF($E13=0,"",$E13*F13),"") | J13: =IFERROR(IF($E13=0,"",$E13*G13),"")
B14: =B13+0.000001 -> 6.010101 | C14: ALTURA < 2.60 | I14: =IFERROR(IF($E14=0,"",$E14*F14),"") | J14: =IFERROR(IF($E14=0,"",$E14*G14),"")
B15: =B14+0.00000001 -> 6.010101 | C15: LADRILLO SILICO CALCAREO TIPO P7 H<2.6M | D15: m2 | E15: 1213.6 | F15: 99.22 | H15: 99.22 | I15: =+ROUND(E15*F15,2) -> 120413.39 | J15: =+ROUND(E15*G15,2) -> 0 | K15: 120413.39 | M15: 99.22 | N15: =+M15*E15 -> 120413.39
B16: =B15+0.00000001 -> 6.010101 | C16: LADRILLO SILICO CALCAREO TIPO P10 H<2.6M | D16: m2 | E16: 12991.58 | F16: 108.22 | H16: 108.22 | I16: =+ROUND(E16*F16,2) -> 1405948.8 | J16: =+ROUND(E16*G16,2) -> 0 | K16: 1405948.8 | M16: 108.22 | N16: =+M16*E16 -> 1405948.8
B17: =B16+0.00000001 -> 6.010101 | C17: LADRILLO SILICO CALCAREO TIPO P12 H<2.6M | D17: m2 | E17: 79.21 | F17: 113.22 | H17: 113.22 | I17: =+ROUND(E17*F17,2) -> 8968.16 | J17: =+ROUND(E17*G17,2) -> 0 | K17: 8968.16 | M17: 113.22 | N17: =+M17*E17 -> 8968.1562
B18: =B17+0.00000001 -> 6.010101 | C18: LADRILLO SILICO CALCAREO TIPO P14 H<2.6M | D18: m2 | E18: 533.65 | F18: 119.22 | H18: 119.22 | I18: =+ROUND(E18*F18,2) -> 63621.75 | J18: =+ROUND(E18*G18,2) -> 0 | K18: 63621.75 | M18: 119.22 | N18: =+M18*E18 -> 63621.753
B19: =B18+0.00000001 -> 6.010101 | C19: LADRILLO SILICO CALCAREO TIPO P20 H<2.6M | D19: m2 | E19: 47.05 | F19: 198.22 | H19: 198.22 | I19: =+ROUND(E19*F19,2) -> 9326.25 | J19: =+ROUND(E19*G19,2) -> 0 | K19: 9326.25 | M19: 198.22 | N19: =+M19*E19 -> 9326.251
B20: =B19+0.00000001 -> 6.0101011 | C20: LADRILLO SILICO CALCAREO TIPO P25 H<2.6M | D20: m2 | E20: 11.54 | F20: 198.22 | H20: 198.22 | I20: =+ROUND(E20*F20,2) -> 2287.46 | J20: =+ROUND(E20*G20,2) -> 0 | K20: 2287.46 | M20: 198.22 | N20: =+M20*E20 -> 2287.4588
B21: =B20+0.00000001 -> 6.0101011 | C21: LADRILLO SILICO CALCAREO TIPO P30 H<2.6M | D21: m2 | E21: 8.17 | F21: 198.22 | H21: 198.22 | I21: =+ROUND(E21*F21,2) -> 1619.46 | J21: =+ROUND(E21*G21,2) -> 0 | K21: 1619.46 | M21: 198.22 | N21: =+M21*E21 -> 1619.4574
B22: =B21+0.00000001 -> 6.0101011 | C22: LADRILLO SILICO CALCAREO TIPO P40 H<2.6M | D22: m2 | E22: 11.15 | F22: 236.22 | H22: 236.22 | I22: =+ROUND(E22*F22,2) -> 2633.85 | J22: =+ROUND(E22*G22,2) -> 0 | K22: 2633.85 | M22: 236.22 | N22: =+M22*E22 -> 2633.853
B23: =B14+0.000001 -> 6.010102 | C23: ALTURA > 2.60 | E23: 0 | K23: 0 | M23: 0 | N23: =+M23*E23 -> 0
B24: =B23+0.00000001 -> 6.010102 | C24: LADRILLO SILICO CALCAREO TIPO P10 H>2.6M | D24: m2 | E24: 346.42 | F24: 110.22 | H24: 110.22 | I24: =+ROUND(E24*F24,2) -> 38182.41 | J24: =+ROUND(E24*G24,2) -> 0 | K24: 38182.41 | M24: 110.22 | N24: =+M24*E24 -> 38182.412
B25: =B24+0.00000001 -> 6.010102 | C25: LADRILLO SILICO CALCAREO TIPO P12 H>2.6M | D25: m2 | E25: 158.5 | F25: 116.22 | H25: 116.22 | I25: =+ROUND(E25*F25,2) -> 18420.87 | J25: =+ROUND(E25*G25,2) -> 0 | K25: 18420.87 | M25: 116.22 | N25: =+M25*E25 -> 18420.87
B26: =B25+0.00000001 -> 6.010102 | C26: LADRILLO SILICO CALCAREO TIPO P14 H>2.6M | D26: m2 | E26: 97.6 | F26: 124.22 | H26: 124.22 | I26: =+ROUND(E26*F26,2) -> 12123.87 | J26: =+ROUND(E26*G26,2) -> 0 | K26: 12123.87 | M26: 124.22 | N26: =+M26*E26 -> 12123.872
B27: =B26+0.00000001 -> 6.010102 | C27: LADRILLO SILICO CALCAREO TIPO P20 H>2.6M | D27: m2 | E27: 6.75 | F27: 208.22 | H27: 208.22 | I27: =+ROUND(E27*F27,2) -> 1405.49 | J27: =+ROUND(E27*G27,2) -> 0 | K27: 1405.49 | M27: 208.22 | N27: =+M27*E27 -> 1405.485
B28: =B27+0.00000001 -> 6.010102 | C28: LADRILLO SILICO CALCAREO TIPO P25 H>2.6M | D28: m2 | E28: 56.41 | F28: 208.22 | H28: 208.22 | I28: =+ROUND(E28*F28,2) -> 11745.69 | J28: =+ROUND(E28*G28,2) -> 0 | K28: 11745.69 | M28: 208.22 | N28: =+M28*E28 -> 11745.69
B29: =B28+0.00000001 -> 6.0101021 | C29: LADRILLO SILICO CALCAREO TIPO P30 H>2.6M | D29: m2 | E29: 13.85 | F29: 208.22 | H29: 208.22 | I29: =+ROUND(E29*F29,2) -> 2883.85 | J29: =+ROUND(E29*G29,2) -> 0 | K29: 2883.85 | M29: 208.22 | N29: =+M29*E29 -> 2883.847
B30: =B23+0.000001 -> 6.010103 | C30: CORTAFUEGO < 2.60 | E30: 0 | K30: 0 | M30: 0 | N30: =+M30*E30 -> 0
B31: =B30+0.00000001 -> 6.010103 | C31: LADRILLO SILICO CALCAREO TIPO P7 RF:2 HRS H<2.6M (ALVEOLOS COMPLETAMENTE LLENO) | D31: m2 | E31: 4.23 | F31: 105.22 | H31: 105.22 | I31: =+ROUND(E31*F31,2) -> 445.08 | J31: =+ROUND(E31*G31,2) -> 0 | K31: 445.08 | M31: 105.22 | N31: =+M31*E31 -> 445.0806
B32: =B31+0.00000001 -> 6.010103 | C32: LADRILLO SILICO CALCAREO TIPO P10 RF:2 HRS H<2.6M (ALVEOLOS COMPLETAMENTE LLENO) | D32: m2 | E32: 2265.48 | F32: 112.22 | H32: 112.22 | I32: =+ROUND(E32*F32,2) -> 254232.17 | J32: =+ROUND(E32*G32,2) -> 0 | K32: 254232.17 | M32: 112.22 | N32: =+M32*E32 -> 254232.17
B33: =B32+0.00000001 -> 6.010103 | C33: LADRILLO SILICO CALCAREO TIPO P12 RF:2 HRS H<2.6M (ALVEOLOS PARCIALMENTE LLENO) | D33: m2 | E33: 10438.42 | F33: 113.22 | H33: 113.22 | I33: =+ROUND(E33*F33,2) -> 1181837.9 | J33: =+ROUND(E33*G33,2) -> 0 | K33: 1181837.9 | M33: 113.22 | N33: =+M33*E33 -> 1181837.9
B34: =B33+0.00000001 -> 6.010103 | C34: LADRILLO SILICO CALCAREO TIPO P14 RF:2 HRS H<2.6M (ALVEOLOS PARCIALMENTE LLENO) | D34: m2 | E34: 410.97 | F34: 119.22 | H34: 119.22 | I34: =+ROUND(E34*F34,2) -> 48995.84 | J34: =+ROUND(E34*G34,2) -> 0 | K34: 48995.84 | M34: 119.22 | N34: =+M34*E34 -> 48995.843
B35: =B34+0.00000001 -> 6.010103 | C35: LADRILLO SILICO CALCAREO TIPO P20 RF:2 HRS H<2.6M (ALVEOLOS PARCIALMENTE LLENO) | D35: m2 | E35: 327.32 | F35: 210.22 | H35: 210.22 | I35: =+ROUND(E35*F35,2) -> 68809.21 | J35: =+ROUND(E35*G35,2) -> 0 | K35: 68809.21 | M35: 210.22 | N35: =+M35*E35 -> 68809.21
B36: =B35+0.00000001 -> 6.0101031 | C36: LADRILLO SILICO CALCAREO TIPO P30 RF:2 HRS H<2.6M (ALVEOLOS PARCIALMENTE LLENO) | D36: m2 | E36: 130.95 | F36: 210.22 | H36: 210.22 | I36: =+ROUND(E36*F36,2) -> 27528.31 | J36: =+ROUND(E36*G36,2) -> 0 | K36: 27528.31 | M36: 210.22 | N36: =+M36*E36 -> 27528.309
B37: =B36+0.00000001 -> 6.0101031 | C37: LADRILLO SILICO CALCAREO TIPO P35 RF:2 HRS H<2.6M (ALVEOLOS PARCIALMENTE LLENO) | D37: m2 | F37: 224.22 | H37: 224.22 | I37: =+ROUND(E37*F37,2) -> 0 | J37: =+ROUND(E37*G37,2) -> 0 | K37: 0 | M37: 224.22 | N37: =+M37*E37 -> 0
B38: =B37+0.00000001 -> 6.0101031 | C38: LADRILLO SILICO CALCAREO TIPO P40 RF:2 HRS H<2.6M (ALVEOLOS PARCIALMENTE LLENO) | D38: m2 | E38: 2.92 | F38: 224.22 | H38: 224.22 | I38: =+ROUND(E38*F38,2) -> 654.72 | J38: =+ROUND(E38*G38,2) -> 0 | K38: 654.72 | M38: 224.22 | N38: =+M38*E38 -> 654.7224
B39: =B38+0.00000001 -> 6.0101031 | C39: LADRILLO SILICO CALCAREO TIPO P45 RF:2 HRS H<2.6M (ALVEOLOS PARCIALMENTE LLENO) | D39: m2 | F39: 224.22 | H39: 224.22 | I39: =+ROUND(E39*F39,2) -> 0 | J39: =+ROUND(E39*G39,2) -> 0 | K39: 0 | M39: 224.22 | N39: =+M39*E39 -> 0
B40: =B39+0.00000001 -> 6.0101031 | C40: LADRILLO SILICO CALCAREO TIPO P50 RF:2 HRS H<2.6M (ALVEOLOS PARCIALMENTE LLENO) | D40: m2 | F40: 224.22 | H40: 224.22 | I40: =+ROUND(E40*F40,2) -> 0 | J40: =+ROUND(E40*G40,2) -> 0 | K40: 0 | M40: 224.22 | N40: =+M40*E40 -> 0
B41: =B30+0.000001 -> 6.010104 | C41: CORTAFUEGO > 2.60 | K41: 0 | M41: 0 | N41: =+M41*E41 -> 0
B42: =B39+0.00000001 -> 6.0101031 | C42: LADRILLO SILICO CALCAREO TIPO P7 RF:2 HRS H>2.6M (ALVEOLOS COMPLETAMENTE LLENO) | D42: m2 | E42: 4.88 | F42: 105.22 | H42: 105.22 | I42: =+ROUND(E42*F42,2) -> 513.47 | J42: =+ROUND(E42*G42,2) -> 0 | K42: 513.47 | M42: 105.22 | N42: =+M42*E42 -> 513.4736
...

Sheet INSTALACIONES
A2: INSTALACIONES
H3: T.C | I3: 3.75
A4: Presupuesto | B4: JUAN DE ALIAGA 750
A5: Subpresupuesto | B5: INSTALACIONES
A6: Cliente | B6: : V&V Bravo S.A.C
A7: Lugar
A8: ITEM | B8: DESCRIPCION | C8: UND | D8: CANTIDAD | E8: P.U (S/.) | F8: P.U ($.) | G8: PARCIAL (S/.) | H8: PARCIAL ($) | I8: TOTAL
A9: 01.01 | B9: INTERCOMUNICADORES | I9: 15833.975
A10: 1.01.01 | B10: DISPOSITIVOS PRINCIPALES DE COMUNICACIÓN | G10: =+E10*D10 -> 0 | H10: =+F10*D10 -> 0 | I10: 0
A11: 1.01.02 | B11: Central de conserjería de audio/vídeo con pantalla LCD 7" | C11: Und. | D11: 1 | F11: 891.3362 | G11: =+E11*D11 -> 0 | H11: =+F11*D11 -> 891.3362 | I11: 3342.5107
A12: 1.01.03 | B12: Placa de Calle Digital sólo audio | C12: Und. | D12: 1 | F12: 318.3404 | G12: =+E12*D12 -> 0 | H12: =+F12*D12 -> 318.3404 | I12: 1193.7765
A13: 1.01.04 | B13: Intercomunicador tipo telefono Sprint L2 | C13: Und. | D13: 251 | F13: 35.9456 | G13: =+E13*D13 -> 0 | H13: =+F13*D13 -> 9022.3456 | I13: 33833.796
A14: 1.01.05 | B14: COMPLEMENTOS DEL SISTEMA | G14: =+E14*D14 -> 0 | H14: =+F14*D14 -> 0 | I14: 0
A15: 1.01.06 | B15: Interfaz de expansión de anexos/longitud | C15: Und. | D15: 3 | F15: 287.5272 | G15: =+E15*D15 -> 0 | H15: =+F15*D15 -> 862.5816 | I15: 3234.681
A16: 1.01.07 | B16: Fuente de poder de 1.2A para sistemas de audio/video | C16: Und. | D16: 4 | F16: 112.1326 | G16: =+E16*D16 -> 0 | H16: =+F16*D16 -> 448.5304 | I16: 1681.989
A17: 1.01.08 | B17: Configuradores (Paquete de 10 piezas) | C17: Und. | D17: 75 | F17: 8.6668 | G17: =+E17*D17 -> 0 | H17: =+F17*D17 -> 650.01 | I17: 2437.5375
A18: 1.01.09 | B18: MATERIALES | C18: Glb. | D18: 1 | F18: 2451.4354 | G18: =+E18*D18 -> 0 | H18: =+F18*D18 -> 2451.4354 | I18: 9192.8827
A19: 1.01.10 | B19: Cable de par trenzado para difusión sonora | G19: =+E19*D19 -> 0 | H19: =+F19*D19 -> 0 | I19: 0
A20: 1.01.11 | B20: Cable UTP cat. 5e 100% cobre para distribución | G20: =+E20*D20 -> 0 | H20: =+F20*D20 -> 0 | I20: 0
A21: 1.01.12 | B21: Elementos auxiliares para la adecuacion de sistemas (autorroscantes, tarugos, cintillos, terminales, etc) | G21: =+E21*D21 -> 0 | H21: =+F21*D21 -> 0 | I21: 0
A22: 1.01.13 | B22: MANO DE OBRA | C22: Glb. | D22: 1 | F22: 920.2168 | G22: =+E22*D22 -> 0 | H22: =+F22*D22 -> 920.2168 | I22: 3450.813
A23: 1.01.14 | B23: Enrutamiento y verificación de canalizaciones | G23: =+E23*D23 -> 0 | H23: =+F23*D23 -> 0 | I23: 0
A24: 1.01.15 | B24: Cableado de bus de comunicación | G24: =+E24*D24 -> 0 | H24: =+F24*D24 -> 0 | I24: 0
A25: 1.01.16 | B25: Instalación de centralitas | G25: =+E25*D25 -> 0 | H25: =+F25*D25 -> 0 | I25: 0
A26: 1.01.17 | B26: Instalación de portero digital y unidades internas | G26: =+E26*D26 -> 0 | H26: =+F26*D26 -> 0 | I26: 0
A27: 1.01.18 | B27: Instalación de módulo alimentadores y extensiones. | G27: =+E27*D27 -> 0 | H27: =+F27*D27 -> 0 | I27: 0
A28: 1.01.19 | B28: Configuración de aplicación en centralita | G28: =+E28*D28 -> 0 | H28: =+F28*D28 -> 0 | I28: 0
A29: 1.01.20 | B29: Pruebas de funcionamiento y puesta en marcha | G29: =+E29*D29 -> 0 | H29: =+F29*D29 -> 0 | I29: 0
A30: 1.01.21 | B30: Capacitación y manual de uso | G30: =+E30*D30 -> 0 | H30: =+F30*D30 -> 0 | I30: 0
A31: 1.01.22 | B31: TRANSPORTE, SEGUROS Y GASTOS GENERALES | C31: Glb. | D31: 1 | F31: 269.1784 | G31: =+E31*D31 -> 0 | H31: =+F31*D31 -> 269.1784 | I31: 1009.419
A32: 1.01.23 | B32: Examen médico ocupacional, SCTR salud - Pensión y EPPs | G32: =+E32*D32 -> 0 | H32: =+F32*D32 -> 0 | I32: 0
A33: 1.01.24 | B33: Transporte de Personal, Herramientas y Materiales | G33: =+E33*D33 -> 0 | H33: =+F33*D33 -> 0 | I33: 0
A34: 01.02 | B34: DETECCION CONTRAINCENDIOS | I34: 47250.565
A35: 1.02.01 | B35: PANEL DE ALARMA CONTRA INCENDIOS Y COMPLEMENTOS
A36: 1.02.02 | B36: Panel de Detección y Alarma Contra Incendio Direccionable con Certificado UL-864, para sistemas DACI en edificios. | C36: Und. | D36: 1 | F36: 739.7352 | G36: =+E36*D36 -> 0 | H36: =+F36*D36 -> 739.7352 | I36: 2774.007
A37: 1.02.03 | B37: Tarjeta de expasión de direcciones dual 250det/250mod | C37: Und. | D37: 2 | F37: 904.7464 | G37: =+E37*D37 -> 0 | H37: =+F37*D37 -> 1809.4928 | I37: 6785.598
A38: 1.02.04 | B38: Teclado LCD para control remoto | C38: Und. | D38: 2 | F38: 389.3992 | G38: =+E38*D38 -> 0 | H38: =+F38*D38 -> 778.7984 | I38: 2920.494
A39: 1.02.05 | B39: Batería 12 Voltios 17 Amperios | C39: Und. | D39: 2 | F39: 45.6596 | G39: =+E39*D39 -> 0 | H39: =+F39*D39 -> 91.3192 | I39: 342.447
A40: 1.02.06
A41: 1.02.07 | B41: DISPOSITIVOS DE INICIACIÓN
...

Sheet ACIySPC
A2: CUARTO DE BOMBAS - ACI
H3: T.C | I3: 3.75
A4: Presupuesto | B4: JUAN DE ALIAGA 750
A5: Subpresupuesto | B5: EQUIPAMIENTO CUARTO DE BOMBAS
A6: Cliente | B6: : V&V Bravo S.A.C | F6: Costo al | G6: 45538
A7: Lugar
A8: ITEM | B8: DESCRIPCION | C8: UND | D8: CANTIDAD | E8: P.U (S/.) | F8: P.U ($.) | G8: PARCIAL (S/.) | H8: PARCIAL ($) | I8: TOTAL
A9: 1.00 | B9: SISTEMA DE PRESION CONSTANTE Y SUMIDEROS | I9: =SUM(H11:H19) -> 66276.881
A10: 1.01 | B10: SUMINISTRO E INSTALACIÓN SISTEMA DE PRESIÓN CONSTANTE Y VELOCIDAD VARIABLE ALTA PRESIÓN - 03 UND
A11: 1.02 | B11: ELECTROBOMBA MULTIETAPICA VERTICAL MARCA: BARNES MODELO: VSE 20 6-150 PUNTO DE OPERACIÓN: 6.78 lps // 68.5 m Potencia: 15 HP IMPULSOR Y VOLUTA EN INOX 304 TENSION DE TRABAJO : 220 V / TRIFÁSICO / 60 HZ SUCCION (2 1/2") DESCARGA (2 1/2") TABLERO VARIADOR 3X15 HP CON PLC 220 V 3F PLC Marca: Schneider 03 Variadores Marca: LS | C11: Glb | D11: 1 | F11: 14357.304 | G11: =+E11*D11 -> 0 | H11: =+F11*D11 -> 14357.304 | I11: =+G11+(H11*$I$3) -> 53839.89
A12: 1.09 | B12: SUMINISTRO E INSTALACIÓN SISTEMA DE PRESIÓN CONSTANTE Y VELOCIDAD VARIABLE MEDIA PRESIÓN - 03 UND
A13: 1.10 | B13: ELECTROBOMBA MULTIETAPICA VERTICAL MARCA: BARNES MODELO: VSE 15 8-150 PUNTO DE OPERACIÓN: 4.95 lps // 88.16 m Potencia: 15 HP IMPULSOR Y VOLUTA EN INOX 304 TENSION DE TRABAJO : 220 V / TRIFÁSICO / 60 HZ SUCCION (2 1/2") DESCARGA (2 1/2") TABLERO VARIADOR 3X15 HP CON PLC 220 V 3F PLC Marca: Schneider 03 Variadores Marca: LS | C13: Glb | D13: 1 | F13: 13549.401 | G13: =+E13*D13 -> 0 | H13: =+F13*D13 -> 13549.401 | I13: =+G13+(H13*$I$3) -> 50810.253
A14: 1.17 | B14: SUMINISTRO E INSTALACIÓN SISTEMA DE PRESIÓN CONSTANTE Y VELOCIDAD VARIABLE BAJA PRESIÓN - 03 UND
A15: 1.18 | B15: ELECTROBOMBA MULTIETAPICA VERTICAL MARCA: BARNES MODELO: VSE 15 8-150 PUNTO DE OPERACIÓN: 4.63 lps // 107.8 m Potencia: 15 HP IMPULSOR Y VOLUTA EN INOX 304 TENSION DE TRABAJO : 220 V / TRIFÁSICO / 60 HZ SUCCION (2 1/2") DESCARGA (2 1/2") TABLERO VARIADOR 3X15 HP CON PLC 220 V 3F PLC Marca: Schneider 03 Variadores Marca: LS | C15: Glb | D15: 1 | F15: 14619.467 | G15: =+E15*D15 -> 0 | H15: =+F15*D15 -> 14619.467 | I15: =+G15+(H15*$I$3) -> 54823.002
A16: 1.25 | B16: SUMINISTRO E INSTALACIÓN SISTEMA DE BOMBEO DE SUMIDERO - 02 UND
A17: 1.26 | B17: BOMBA SUMERGIBLE PARA AGUAS RESIDUALES MARCA: BARNES MODELO: NHE 3 30-2 PUNTO DE OPERACIÓN: 4.13 lps // 26.4 m Potencia: 3 HP CUERPO, CARCASA, IMPULSOR: Hierro fundido ASTM A-48, Clase 30 CON IMPULSOR DE 5.118" DESCARGA: 3" | C17: Glb | D17: 1 | F17: 3455.4312 | G17: =+E17*D17 -> 0 | H17: =+F17*D17 -> 3455.4312 | I17: =+G17+(H17*$I$3) -> 12957.867
A18: 1.33 | B18: Instalación de sistema de presión constante de 09 bombas con succión de 6", descarga de 4"; manifold de succión de 6", manifold de descarga de 4" - Se considera la succión en Inoxidable 304. - Manifold en Acero Galvanizado. | C18: Glb | D18: 1 | F18: 17568.366 | G18: =+E18*D18 -> 0 | H18: =+F18*D18 -> 17568.366 | I18: =+G18+(H18*$I$3) -> 65881.374
A19: 1.34 | B19: Instalación en sistema de sumidero de 02 bombas, con descarga de 3" | C19: Glb | D19: 1 | F19: 2726.9112 | G19: =+E19*D19 -> 0 | H19: =+F19*D19 -> 2726.9112 | I19: =+G19+(H19*$I$3) -> 10225.917
A20: 2.00 | B20: EQUIPAMIENTO DE AGUA CONTRAINCENDIO - ELECTROBOMBA LISTADA | I20: =SUM(H22:H30) -> 55414.94
A21: 2.01 | B21: Equipo de Bombeo Contraincendios Electrobomba 500GPM @ 245PSI 125HP (LISTADA Y APROBADA)
A22: 2.02 | B22: ElectrobombaContraIncendiosTipoSPLITCASEmarcaPATTERSONmodelo5x3DMDseleccionada a 500GPM a 245 PSI de 125HP 230V 3Ø 60HZ | C22: Glb | D22: 1 | F22: 35945.5 | G22: =+E22*D22 -> 0 | H22: =+F22*D22 -> 35945.5 | I22: =+G22+(H22*$I$3) -> 134795.62
A23: 2.03 | B23: TableroEstrellatrianguloFiretrolUL/FMmodeloFTA1300-AM125A para motor 125HP/230V/3Ø/60HZ | C23: Glb | D23: 1 | F23: 8750 | G23: =+E23*D23 -> 0 | H23: =+F23*D23 -> 8750 | I23: =+G23+(H23*$I$3) -> 32812.5
A24: 2.04 | B24: ElectrobombamultietapicaverticalenaceroinoxtipoJockeymarcaWILOmodeloHelixFIRSTV218de4HP230V 3Ø 60HZ Caudal 5GPM @ 255 PSI | C24: Glb | D24: 1 | F24: 1585.24 | G24: =+E24*D24 -> 0 | H24: =+F24*D24 -> 1585.24 | I24: =+G24+(H24*$I$3) -> 5944.65
A25: 2.05 | B25: TablerodeControldeBombatipoJockeyFIRETROLFTA560F- AG004 A 3Ø/230V | C25: Glb | D25: 1 | F25: 988.13 | G25: =+E25*D25 -> 0 | H25: =+F25*D25 -> 988.13 | I25: =+G25+(H25*$I$3) -> 3705.4875
A26: 2.06 | B26: MedidordeflujoranuradomarcaGlobalVisionmodelo6-500 de 6” UL/FM | C26: Glb | D26: 1 | F26: 1191.38 | G26: =+E26*D26 -> 0 | H26: =+F26*D26 -> 1191.38 | I26: =+G26+(H26*$I$3) -> 4467.675
A27: 2.07
A28: 2.08 | B28: Instalación Equipo de Bombeo contraincendio en sala de Bombas succion de 6", descarga de 6" y retorno de pruebas de 4".
A29: 2.09 | B29: Suministro de materiales Sala de Bombas | C29: Glb | D29: 1 | F29: 4454.69 | G29: =+E29*D29 -> 0 | H29: =+F29*D29 -> 4454.69 | I29: =+G29+(H29*$I$3) -> 16705.087
A30: 2.10 | B30: MontajeelectromecanicodelEquipodeBombeoSaladebombas | C30: Glb | D30: 1 | F30: 2500 | G30: =+E30*D30 -> 0 | H30: =+F30*D30 -> 2500 | I30: =+G30+(H30*$I$3) -> 9375
A31: 3.00 | B31: SISTEMA DE AGUA CONTRAINCENDIO - ROCIADORES Y GABINETES | I31: =SUM(H32:H35) -> 363487.31
A32: 3.01 | B32: Suministro e Instalación de Sistema de la Red de Rociadores y Gabinetes
A33: 3.02 | B33: Suministro de materiales red de Gabinetes y Rociadores. | C33: Glb | D33: 1 | F33: 249987.01 | G33: =+E33*D33 -> 0 | H33: =+F33*D33 -> 249987.01 | I33: =+G33+(H33*$I$3) -> 937451.29
A34: 3.03 | B34: Montaje mecanico del sistema de Gabinetes y Rociadores | C34: Glb | D34: 1 | F34: 98449.28 | G34: =+E34*D34 -> 0 | H34: =+F34*D34 -> 98449.28 | I34: =+G34+(H34*$I$3) -> 369184.8
A35: 3.04 | B35: Gastos generales | C35: Glb | D35: 1 | F35: 15051.02 | G35: =+E35*D35 -> 0 | H35: =+F35*D35 -> 15051.02 | I35: =+G35+(H35*$I$3) -> 56441.325

Sheet OBRA CIVIL ASCENSOR
B2: DESCRIPCIÓN | C2: UND | D2: CANTIDAD | E2: PRECIO | F2: PARCIAL | G2: TOTAL
B3: ASCENSORES | G3: =SUM(F5:F6) -> 103726
B4: OBRAS CIVILES
B5: OBRAS CIVILES PARA LA COLOCACIÓN DE ASCENSOR | C5: und | D5: 1 | E5: 21700 | F5: =+E5*D5 -> 21700
B6: ESTRUCTURAS (DINTELES METÁLICOS/COLUMNAS METÁLICAS) | C6: glb | D6: 1 | E6: 82026 | F6: =+E6*D6 -> 82026

Sheet MECANICAS
A2: INSTALACIONES MECANICAS
H3: T.C | I3: 3.75
A4: Presupuesto | B4: JUAN DE ALIAGA 750
A5: Subpresupuesto | B5: INSTALACIONS MECANICAS
A6: Cliente | B6: : V&V Bravo S.A.C | F6: Costo al | G6: 45538
A7: Lugar
A8: ITEM | B8: DESCRIPCION | C8: UND | D8: CANTIDAD | E8: P.U (S/.) | F8: P.U ($.) | G8: PARCIAL (S/.) | H8: PARCIAL ($) | I8: TOTAL
A9: 1.01 | B9: VENTILACION MECANICA | I9: =SUM(H11:H136) -> 233305.23
A10: 1 | B10: SISTEMA DE EXTRACCION DE MONOXIDO
A11: 1.1 | B11: EQUIPOS DE VENTILACION
A12: 1.1.1 | B12: EXTRACTOR AXIAL . Código: EA-01 Marca: SYSTEMAIR Caudal: 5,700 CFM@0.90" c.a. Tensión: 220 Volt-3F-60Hz | C12: Unid. | D12: 1 | F12: 750 | G12: =+E12*D12 -> 0 | H12: =+F12*D12 -> 750 | I12: =+G12+(H12*$I$3) -> 2812.5
A13: 1.1.2 | B13: EXTRACTOR AXIAL . Código: EA-02 Marca: SYSTEMAIR Caudal: 4,700 CFM@0.90" c.a. Tensión: 220 Volt-3F-60Hz | C13: Unid. | D13: 6 | F13: 750 | G13: =+E13*D13 -> 0 | H13: =+F13*D13 -> 4500 | I13: =+G13+(H13*$I$3) -> 16875
A14: 1.1.3 | B14: EXTRACTOR AXIAL . Código: EA-03 Marca: SYSTEMAIR Caudal: 4,450 CFM@0.90" c.a. Tensión: 220 Volt-3F-60Hz | C14: Unid. | D14: 2 | F14: 750 | G14: =+E14*D14 -> 0 | H14: =+F14*D14 -> 1500 | I14: =+G14+(H14*$I$3) -> 5625
A15: 1.1.4 | B15: EXTRACTOR AXIAL . Código: EA-04 Marca: SYSTEMAIR Caudal: 5,850 CFM@0.90" c.a. Tensión: 220 Volt-3F-60Hz | C15: Unid. | D15: 2 | F15: 750 | G15: =+E15*D15 -> 0 | H15: =+F15*D15 -> 1500 | I15: =+G15+(H15*$I$3) -> 5625
A16: 1.1.5 | B16: INYECTOR AXIAL . Código: IA-01 Marca: SYSYTEM AIR Caudal: 5,700 CFM@0.50" c.a. Tensión: 220 Volt-3F-60Hz | C16: Unid. | D16: 1 | F16: 722.22 | G16: =+E16*D16 -> 0 | H16: =+F16*D16 -> 722.22 | I16: =+G16+(H16*$I$3) -> 2708.325
A17: 1.1.6 | B17: INYECTOR AXIAL . Código: IA-02 Marca: SYSTEMAIR Caudal: 4,700 CFM@0.50" c.a. Tensión: 220 Volt-3F-60Hz | C17: Unid. | D17: 6 | F17: 722.22 | G17: =+E17*D17 -> 0 | H17: =+F17*D17 -> 4333.32 | I17: =+G17+(H17*$I$3) -> 16249.95
A18: 1.1.7 | B18: INYECTOR AXIAL . Código: IA-05 Marca: SYSTEMAIR Caudal: 4,450 CFM@0.50" c.a. Tensión: 220 Volt-3F-60Hz | C18: Unid. | D18: 2 | F18: 722.22 | G18: =+E18*D18 -> 0 | H18: =+F18*D18 -> 1444.44 | I18: =+G18+(H18*$I$3) -> 5416.65
A19: 1.1.8 | B19: EXTRACTOR TIPO JET FAN Código: VTI-01 Marca: SYSTEMAIR Caudal: 4,100 CFM @0.00" C.A. Tensión: 220 Volt-3F-60Hz 300°F por 2 Horas | C19: Unid. | D19: 23 | F19: 1500 | G19: =+E19*D19 -> 0 | H19: =+F19*D19 -> 34500 | I19: =+G19+(H19*$I$3) -> 129375
A20: 1.1.9 | B20: Suministro e instalacion de Sensor de Monoxido, Marca GREYSTONE, CANADA, alimentación 24 VAC/VDC, Señal de 0- 10V/ 4-20mA y Rango lectura 0-200ppm CO, para montaje en pared. | C20: Unid. | D20: 23 | F20: 227.78 | G20: =+E20*D20 -> 0 | H20: =+F20*D20 -> 5238.94 | I20: =+G20+(H20*$I$3) -> 19646.025
A21: 1.2 | B21: DUCTERIA PARA LA VENTILACION
A22: 1.2.1 | B22: Suministro e instalación de ductos fabricados en plancha galvanizada, para Extraccion de Monoxido, según norma internacional SMACNA, incluye anclaje y soporteria. | C22: Kgrs. | D22: 525 | F22: 3 | G22: =+E22*D22 -> 0 | H22: =+F22*D22 -> 1575 | I22: =+G22+(H22*$I$3) -> 5906.25
A23: 1.2.2 | B23: Suministro e instalación de rejillas de extracción de aire de Fabricación Nacional, fabricada en plancha galvanizada pintado al horno y acabado de color blanco o de acuerdo de arquitectura. | C23: Plg2. | D23: 25140 | F23: 0.16 | G23: =+E23*D23 -> 0 | H23: =+F23*D23 -> 4022.4 | I23: =+G23+(H23*$I$3) -> 15084
A24: 1.2.3 | B24: Suministro e instalación de Dampers de Gravedad, de Fabricación Nacional, fabricada en marco de plancha galvanizada y aletas de aluminio. | C24: Unid. | D24: 20 | F24: 166.67 | G24: =+E24*D24 -> 0 | H24: =+F24*D24 -> 3333.4 | I24: =+G24+(H24*$I$3) -> 12500.25
A25: 1.2.4 | B25: Cableado de sensores de monóxido. | C25: Unid. | D25: 23 | F25: 42.22 | G25: =+E25*D25 -> 0 | H25: =+F25*D25 -> 971.06 | I25: =+G25+(H25*$I$3) -> 3641.475
A26: 1.3 | B26: INSTALACION DE VENTILADORES
A27: 1.3.1 | B27: Instalaciòn de equipos de ventilacion. Montaje de equipo incluye anclajes y soporteria. Tablero de control marca Himell. Contactores y Relays, marca Schneider Leds, Pulsadores y MOA. Conexión eléctrica de fuerza ( Punto dejado máx 1 metro del equipo) Pruebas y ajustes. Puesta en marcha. | C27: Globo. | D27: 1 | F27: 11422.22 | G27: =+E27*D27 -> 0 | H27: =+F27*D27 -> 11422.22 | I27: =+G27+(H27*$I$3) -> 42833.325
A28: 2 | B28: SISTEMA DE VESTIBULOS PREVIOS - ESCALERAS
A29: 2.1 | B29: EQUIPOS DE VENTILACION
A30: 2.1.1 | B30: INYECTOR AXIAL. Código: IA-05 Marca: SYSYTEM AIR Caudal: 385 CFM@0.20" c.a. Tensión: 220 Volt-1F-60Hz | C30: Unid. | D30: 25 | F30: 85 | G30: =+E30*D30 -> 0 | H30: =+F30*D30 -> 2125 | I30: =+G30+(H30*$I$3) -> 7968.75
A31: 2.1.2 | B31: EXTRACTOR AXIAL. Código: EA-05 Marca: SYSYTEM AIR Caudal: 580 CFM@0.20" c.a. Tensión: 220 Volt-1F-60Hz | C31: Unid. | D31: 25 | F31: 85 | G31: =+E31*D31 -> 0 | H31: =+F31*D31 -> 2125 | I31: =+G31+(H31*$I$3) -> 7968.75
A32: 2.1.3 | B32: INYECTOR AXIAL. Código: IA-06 Marca: SYSYTEM AIR Caudal: 440 CFM@0.20" c.a. Tensión: 220 Volt-1F-60Hz | C32: Unid. | D32: 25 | F32: 85 | G32: =+E32*D32 -> 0 | H32: =+F32*D32 -> 2125 | I32: =+G32+(H32*$I$3) -> 7968.75
A33: 2.1.4 | B33: EXTRACTOR AXIAL. Código: EA-06 Marca: SYSYTEM AIR Caudal: 330 CFM@0.20" c.a. Tensión: 220 Volt-1F-60Hz | C33: Unid. | D33: 50 | F33: 85 | G33: =+E33*D33 -> 0 | H33: =+F33*D33 -> 4250 | I33: =+G33+(H33*$I$3) -> 15937.5
A34: 2.1.5 | B34: EXTRACTOR CENTRIFUGO. Código: EC-02 Marca: SYSYTEM AIR Caudal: 14,500 CFM@0.70" c.a. Tensión: 220 Volt-3F-60Hz | C34: Unid. | D34: 1 | F34: 3277.78 | G34: =+E34*D34 -> 0 | H34: =+F34*D34 -> 3277.78 | I34: =+G34+(H34*$I$3) -> 12291.675
