Workbook
Name _k: 'RESUMEN ESCENARIO'!$G$5
Name TC: 'RESUMEN ESCENARIO'!$F$6

Sheet RESUMEN ESCENARIO
B3: ="PRESUPUESTO | "&$C$5&" | REV 0"&$F$7 -> PRESUPUESTO | GERMANIA | REV 09
B4: Código S10 | C4: xxxx
B5: Proyecto | C5: GERMANIA | E5: AC : | F5: 780
B6: Presupuesto | C6: =$B$3 -> PRESUPUESTO | GERMANIA | REV 09 | E6: TC : | F6: 3.35
B7: Cliente | C7: VYV INMOBILIARIA | E7: REV : | F7: 9
B8: Lugar | C8: SURQUILLO | E8: AREA CONSTRUIDA TOTAL : | F8: 30873.09 | G8: M2
B9: Fecha | C9: 46090 | E9: PLAZO : | F9: 23 | G9: MESES
I10: =C5 -> GERMANIA
B11: ITEM | C11: DESCRIPCIÓN | E11: MONTO PARCIAL (S/) | F11: MONTO PARCIAL (US$) | G11: TOTAL (S/) | I11: S/ x m2 | J11: $ x m2
B13: 1 | C13: OBRAS PROVISIONALES | E13: =+OP!H13*1 -> 3140623.8 | F13: =+OP!I13*1 -> 11303.6 | G13: =+E13+F13*TC -> 3178490.9 | I13: =+G13/$D$71 -> 102.95344 | J13: =I13/$F$6 -> 30.732371
B14: 2 | C14: SEGURIDAD Y SALUD | E14: =+OP!H117 -> 1028225.6 | G14: =+E14+F14*TC -> 1028225.6 | I14: =+G14/$D$71 -> 33.304915 | J14: =I14/$F$6 -> 9.9417656
C15: MALLAS ANTICAÍDAS Y ENCAPSULADO NUEVO ESTÁNDAR DE SEGURIDAD | E15: =+OP!K133-OP!J125-OP!J30 -> 240929.6 | G15: =+E15+F15*TC -> 240929.6 | I15: =+G15/$D$71 -> 7.8038706 | J15: =I15/$F$6 -> 2.3295136
B16: 3 | C16: ESTRUCTURAS SÓTANO | E16: =+'Est Sotano '!K303 -> 5904035.9 | F16: =+'Est Sotano '!L303 -> 555591.91 | G16: =+E16+F16*TC -> 7765268.8 | I16: =+G16/$D$71 -> 251.52224 | J16: =I16/$F$6 -> 75.081267
B17: 4 | C17: ESTRUCTURAS TORRE | E17: =+'EST TORRE'!J157 -> 6713422.4 | F17: =+'EST TORRE'!K157 -> 841442.12 | G17: =+E17+F17*TC -> 9532253.5 | I17: =+G17/$D$71 -> 308.75605 | J17: =I17/$F$6 -> 92.165986
C18: DETALLE DE FACHADA | E18: =200*(430.59+150)*1 -> 116118 | G18: =+E18+F18*TC -> 116118 | I18: =+G18/$D$71 -> 3.7611396 | J18: =I18/$F$6 -> 1.1227282
C19: DETALLE DE FACHADA EN ESTRUCTURAS | E19: =+'EST TORRE'!J171-E18 -> 151385.38 | F19: =+'EST TORRE'!K171 -> 20323.613 | G19: =+E19+F19*TC -> 219469.49 | I19: =+G19/$D$71 -> 7.1087632 | J19: =I19/$F$6 -> 2.1220189
B20: 5 | C20: ARQUITECTURA SÓTANO | E20: =+'ARQ SOT'!I273 -> 1221097.8 | F20: =+'ARQ SOT'!J273 -> 25709.83 | G20: =+E20+F20*TC -> 1307225.8 | I20: =+G20/$D$71 -> 42.341915 | J20: =I20/$F$6 -> 12.639378
B21: 6 | C21: ARQUITECTURA TORRE | E21: =+'ARQ TORRE'!H1158 -> 16503223 | F21: =+'ARQ TORRE'!I1158 -> 896699.08 | G21: =+E21+F21*TC -> 19507165 | I21: =+G21/$D$71 -> 631.8501 | J21: =I21/$F$6 -> 188.61197
B22: =B21+1 -> 7 | C22: INSTALACIONES ELÉCTRICAS | E22: =+IIEE!G9 -> 2904701.4 | F22: =+IIEE!H9 -> 492473.21 | G22: =+E22+F22*TC -> 4554486.6 | I22: =+G22/$D$71 -> 147.52286 | J22: =I22/$F$6 -> 44.036676
B23: =B22+1 -> 8 | C23: INSTALACIONES SANITARIAS | E23: =+IISS!G9 -> 2015202.8 | F23: =+IISS!H9 -> 54479.171 | G23: =+E23+F23*TC -> 2197708 | I23: =+G23/$D$71 -> 71.18523 | J23: =I23/$F$6 -> 21.249322
B24: =B23+1 -> 9 | C24: EQUIPAMIENTO DE BOMBAS (IISS) | F24: =+'CTO BOMBAS - ACIySPC ACT'!I9 -> 50453.28 | G24: =+E24+F24*TC -> 169018.49 | I24: =+G24/$D$71 -> 5.4746217 | J24: =I24/$F$6 -> 1.6342154
B25: 10 | C25: EQUIPAMIENTO DE PISCINA + REVESTIMIENTO DE LÁMINA (IISS) | E25: =+INSTALACIONES!I71 -> 72039.77 | G25: =+E25+F25*TC -> 72039.77 | I25: =+G25/$D$71 -> 2.3334163 | J25: =I25/$F$6 -> 0.69654217
B27: 11 | C27: SISTEMA DE AGUA CONTRAINCENDIO | F27: =+'CTO BOMBAS - ACIySPC ACT'!H22 -> 481507.87 | G27: =+E27+F27*TC -> 1613051.4 | I27: =+G27/$D$71 -> 52.247811 | J27: =I27/$F$6 -> 15.596361
B28: =B27+1 -> 12 | C28: EQUIPAMIENTO DE AGUA CONTRAINCENDIO | F28: =+'CTO BOMBAS - ACIySPC ACT'!H18 -> 66343.8 | G28: =+E28+F28*TC -> 222251.73 | I28: =+G28/$D$71 -> 7.1988819 | J28: =I28/$F$6 -> 2.14892
B29: =B28+1 -> 13 | C29: SISTEMA DE VENTILACIÓN Y EXTRACCIÓN | F29: =+IIMM!I9 -> 162567.43 | G29: =+E29+F29*TC -> 544600.87 | I29: =+G29/$D$71 -> 17.639986 | J29: =I29/$F$6 -> 5.2656674
B30: =B29+1 -> 14 | C30: SISTEMA DE GAS (2 PTOS DE GAS) GN tub cobre + Pe Al Pe (ingreso dep) | E30: =+INSTALACIONES!I69 -> 426957.93 | G30: =+E30+F30*TC -> 426957.93 | I30: =+G30/$D$71 -> 13.829452 | J30: =I30/$F$6 -> 4.1281948
B31: =B30+1 -> 15 | C31: SISTEMA DE DETECCIÓN Y ALARMA | F31: =+INSTALACIONES!I43 -> 84553.58 | G31: =+E31+F31*TC -> 283254.49 | I31: =+G31/$D$71 -> 9.1748022 | J31: =I31/$F$6 -> 2.7387469
B32: =B31+1 -> 16 | C32: SISTEMA DE CCTV | F32: =+INSTALACIONES!I75 -> 8827 | G32: =+E32+F32*TC -> 29570.45 | I32: =+G32/$D$71 -> 0.95780662 | J32: =I32/$F$6 -> 0.28591242
B33: =B32+1 -> 17 | C33: EQUIPAMIENTO (INTERCOMUNICADORES) | E33: =+INSTALACIONES!I9 -> 90543.89 | G33: =+E33+F33*TC -> 90543.89 | I33: =+G33/$D$71 -> 2.9327771 | J33: =I33/$F$6 -> 0.87545584
B34: =B33+1 -> 18 | C34: GRUPO ELECTROGENO | F34: =+IIMM!I131 -> 21663.56 | G34: =+E34+F34*TC -> 72572.926 | I34: =+G34/$D$71 -> 2.3506855 | J34: =I34/$F$6 -> 0.70169717
B35: =B34+1 -> 19 | C35: ASCENSORES | E35: =+'OBRA CIVIL ASCENSOR'!G3 -> 96048.425 | F35: =+IIMM!I135 -> 300590.71 | G35: =+E35+F35*TC -> 1103027.3 | I35: =+G35/$D$71 -> 35.727791 | J35: =I35/$F$6 -> 10.665012
B36: =B35+1 -> 20 | C36: PLATAFORMA DISCAPACITADOS | E36: 18500 | G36: =+E36+F36*TC -> 18500 | I36: =+G36/$D$71 -> 0.59922735 | J36: =I36/$F$6 -> 0.17887384
B37: =B36+1 -> 21 | C37: OBRAS EXTERIORES (NO SE INCLUYE) | G37: =+E37+F37*TC -> 0 | I37: =+G37/$D$71 -> 0 | J37: =I37/$F$6 -> 0
B38: =B37+1 -> 22 | C38: SISTEMA FOTOVOLTAICO | F38: =+INSTALACIONES!I73 -> 10563.38 | G38: =+E38+F38*TC -> 35387.323 | I38: =+G38/$D$71 -> 1.146219 | J38: =I38/$F$6 -> 0.34215493
C39: COSTO DIRECTO | E39: =SUM(E13:E38) -> 40643056 | F39: =SUM(F12:F38) -> 4085093.1 | G39: =SUM(G13:G38) -> 54328118 | I39: =SUM(I13:I38) -> 1759.724 | J39: =SUM(J13:J38) -> 525.29075
C41: GASTOS GENERALES | D41: =+G41/G39 -> 0.073670319 | E41: =+GG!G86 -> 4002369.8 | G41: =+E41 -> 4002369.8 | I41: =+G41/D71 -> 129.63943 | J41: =+I41/TC -> 38.698337
C42: POLICE SECURITY (VIGILANTE ARMADO A TIEMPO COMPLETO) | E42: =+GG!G89-GG!G72 -> 120954.24 | G42: =+E42+F42*TC -> 120954.24 | I42: =+G42/$D$71 -> 3.9177886 | J42: =I42/$F$6 -> 1.1694891
C43: UTILIDAD CD | D43: 0.054 | E43: =+E39*D43 -> 2194725 | F43: =+F39*D43 -> 220595.03 | G43: =+G39*D43 -> 2933718.4 | I43: =+G43/$D$71 -> 95.025097 | J43: =+I43/TC -> 28.365701
C45: VALOR DE VENTA | E45: =SUM(E39:E43) -> 46961105 | F45: =SUM(F39:F43) -> 4305688.2 | G45: =SUM(G39:G43) -> 61385160 | I45: =SUM(I39:I43) -> 1988.3063 | J45: =SUM(J39:J43) -> 593.52428
C46: IGV | D46: 0.18 | E46: =+E45*$D$46 -> 8452998.9 | F46: =+F45*$D$46 -> 775023.87 | G46: =+D46*G45 -> 11049329 | I46: =+G46/$D$71 -> 357.89514 | J46: =+I46/TC -> 106.83437
...

Sheet OP
A2: OBRAS PROVISIONALES
A4: Presupuesto | B4: ='RESUMEN ESCENARIO'!$C$5 -> GERMANIA
A5: Subpresupuesto | B5: =$A$2 -> OBRAS PROVISIONALES
A6: Cliente | B6: ='RESUMEN ESCENARIO'!$C$7 -> VYV INMOBILIARIA
A7: Lugar | B7: ='RESUMEN ESCENARIO'!$C$8 -> SURQUILLO
A8: Fecha | B8: ='RESUMEN ESCENARIO'!$C$9 -> 46090
A12: ITEM | B12: DESCRIPCION | C12: UND | D12: CANTIDAD | E12: P.U. (PEN) | F12: P.U. (USD) | G12: P.U. (TOTAL) | H12: PRECIO PARCIAL (PEN) | I12: PRECIO PARCIAL (USD) | J12: PRECIO TOTAL (PEN) | K12: TOTAL
A13: 01 | B13: OBRAS PROVISIONALES, TRABAJOS PRELIMINARES | H13: =SUM(H15:H116) -> 3140623.8 | I13: =SUM(I15:I116) -> 11303.6 | K13: =SUM(K14:K116) -> 3178490.9
A14: =A13+0.01 -> 1.01 | B14: CONSTRUCCIONES PROVISIONALES | G14: =IFERROR(IF(D14=0,"",(E14+F14*TC)),"") | H14: =IFERROR(IF(D14=0,"",$D14*E14),"") | I14: =IFERROR(IF(D14=0,"",$D14*F14),"") | J14: =IFERROR(IF(D14<>0,(D14*G14)," "),0) | K14: =SUM(J15:J35) -> 298874.19
A15: =A14+0.0001 -> 1.0101 | B15: OFICINA DE OBRA PARA CONTRATISTA | C15: glb | D15: 1 | E15: 8767.37 | G15: =IFERROR(IF(D15=0,"",(E15+F15*TC)),"") -> 8767.37 | H15: =+ROUND(D15*E15,2) -> 8767.37 | I15: =+ROUND(D15*F15,2) -> 0 | J15: =+ROUND(H15+I15*TC,2) -> 8767.37
A16: =A15+0.0001 -> 1.0102 | B16: OFICINA DE OBRA PARA SUPERVISIÓN | C16: glb | D16: 0 | E16: 8767.37 | G16: =IFERROR(IF(D16=0,"",(E16+F16*TC)),"") | H16: =+ROUND(D16*E16,2) -> 0 | I16: =+ROUND(D16*F16,2) -> 0 | J16: =+ROUND(H16+I16*TC,2) -> 0
A17: =A16+0.0001 -> 1.0103 | B17: OFICINA SALA DE REUNIONES | C17: glb | D17: 1 | E17: 3397.24 | G17: =IFERROR(IF(D17=0,"",(E17+F17*TC)),"") -> 3397.24 | H17: =+ROUND(D17*E17,2) -> 3397.24 | I17: =+ROUND(D17*F17,2) -> 0 | J17: =+ROUND(H17+I17*TC,2) -> 3397.24
A18: =A17+0.0001 -> 1.0104 | B18: ALMACEN DE OBRA | C18: glb | D18: 1 | E18: 10851.51 | G18: =IFERROR(IF(D18=0,"",(E18+F18*TC)),"") -> 10851.51 | H18: =+ROUND(D18*E18,2) -> 10851.51 | I18: =+ROUND(D18*F18,2) -> 0 | J18: =+ROUND(H18+I18*TC,2) -> 10851.51
A19: =A18+0.0001 -> 1.0105 | B19: COMEDOR PERSONAL OBRERO | C19: glb | D19: 1 | E19: 6304.45 | G19: =IFERROR(IF(D19=0,"",(E19+F19*TC)),"") -> 6304.45 | H19: =+ROUND(D19*E19,2) -> 6304.45 | I19: =+ROUND(D19*F19,2) -> 0 | J19: =+ROUND(H19+I19*TC,2) -> 6304.45
A20: =A19+0.0001 -> 1.0106 | B20: VESTUARIO PARA OBREROS | C20: glb | D20: 1 | E20: 7019.17 | G20: =IFERROR(IF(D20=0,"",(E20+F20*TC)),"") -> 7019.17 | H20: =+ROUND(D20*E20,2) -> 7019.17 | I20: =+ROUND(D20*F20,2) -> 0 | J20: =+ROUND(H20+I20*TC,2) -> 7019.17
A21: =A20+0.0001 -> 1.0107 | B21: TRASLADO DE CAMPAMENTO PROVISIONAL A SOTANOS | C21: und | D21: 1 | E21: 5847.24 | G21: =IFERROR(IF(D21=0,"",(E21+F21*TC)),"") -> 5847.24 | H21: =+ROUND(D21*E21,2) -> 5847.24 | I21: =+ROUND(D21*F21,2) -> 0 | J21: =+ROUND(H21+I21*TC,2) -> 5847.24
A22: =A21+0.0001 -> 1.0108 | B22: CASETA PARA GUARDIANIA | C22: glb | D22: 1 | E22: 850 | G22: =IFERROR(IF(D22=0,"",(E22+F22*TC)),"") -> 850 | H22: =+ROUND(D22*E22,2) -> 850 | I22: =+ROUND(D22*F22,2) -> 0 | J22: =+ROUND(H22+I22*TC,2) -> 850
A23: =A22+0.0001 -> 1.0109 | B23: BAÑOS PORTATILES DE OBRA PARA PERSONAL STAFF Y SUPERVISION COMPARTIDOS | C23: mes | D23: 10.5 | E23: 780 | G23: =IFERROR(IF(D23=0,"",(E23+F23*TC)),"") -> 780 | H23: =+ROUND(D23*E23,2) -> 8190 | I23: =+ROUND(D23*F23,2) -> 0 | J23: =+ROUND(H23+I23*TC,2) -> 8190
A24: =A23+0.0001 -> 1.011 | B24: CONSTRUCCION DE SSHH (1ER NIVEL) | C24: glb | D24: 1 | E24: 10162.1 | G24: =IFERROR(IF(D24=0,"",(E24+F24*TC)),"") -> 10162.1 | H24: =+ROUND(D24*E24,2) -> 10162.1 | I24: =+ROUND(D24*F24,2) -> 0 | J24: =+ROUND(H24+I24*TC,2) -> 10162.1
A25: =A24+0.0001 -> 1.0111 | B25: SSHH PORTATILES PARA OBREROS | C25: glb | D25: 1 | E25: 8745 | G25: =IFERROR(IF(D25=0,"",(E25+F25*TC)),"") -> 8745 | H25: =+ROUND(D25*E25,2) -> 8745 | I25: =+ROUND(D25*F25,2) -> 0 | J25: =+ROUND(H25+I25*TC,2) -> 8745
A26: =A25+0.0001 -> 1.0112 | B26: DUCHAS PORTATILES PARA OBREROS | C26: mes | D26: 10.5 | E26: 560 | G26: =IFERROR(IF(D26=0,"",(E26+F26*TC)),"") -> 560 | H26: =+ROUND(D26*E26,2) -> 5880 | I26: =+ROUND(D26*F26,2) -> 0 | J26: =+ROUND(H26+I26*TC,2) -> 5880
A27: =A26+0.0001 -> 1.0113 | B27: ALQUILER LAVAMANOS PARA OBREROS | C27: mes | D27: 10.5 | E27: 660 | G27: =IFERROR(IF(D27=0,"",(E27+F27*TC)),"") -> 660 | H27: =+ROUND(D27*E27,2) -> 6930 | I27: =+ROUND(D27*F27,2) -> 0 | J27: =+ROUND(H27+I27*TC,2) -> 6930
A28: =A27+0.0001 -> 1.0114 | B28: ALQUILER DE ESCUADRAS METÁLICAS | C28: ml | D28: 65.24 | E28: 984.39 | F28: 69.6 | G28: =IFERROR(IF(D28=0,"",(E28+F28*TC)),"") -> 1217.55 | H28: =+ROUND(D28*E28,2) -> 64221.6 | I28: =+ROUND(D28*F28,2) -> 4540.7 | J28: =+ROUND(H28+I28*TC,2) -> 79432.95
A29: =A28+0.0001 -> 1.0115 | B29: VENTILACION PROVISIONAL EN SOTANOS | C29: glb | D29: 1 | E29: 7350 | G29: =IFERROR(IF(D29=0,"",(E29+F29*TC)),"") -> 7350 | H29: =+ROUND(D29*E29,2) -> 7350 | I29: =+ROUND(D29*F29,2) -> 0 | J29: =+ROUND(H29+I29*TC,2) -> 7350
A30: =A29+0.0001 -> 1.0116 | B30: PROTECCIÓN DE VECINOS CON MALLA RASCHEL (ENCAPSULADO) | C30: glb | D30: 1 | E30: 82538 | G30: =IFERROR(IF(D30=0,"",(E30+F30*TC)),"") -> 82538 | H30: =+ROUND(D30*E30,2) -> 82538 | I30: =+ROUND(D30*F30,2) -> 0 | J30: =+ROUND(H30+I30*TC,2) -> 82538
A31: =A30+0.0001 -> 1.0117 | B31: RENOVACIÓN DE MALLA RACHEL | C31: glb | D31: 1 | E31: 13635.52 | G31: =IFERROR(IF(D31=0,"",(E31+F31*TC)),"") -> 13635.52 | H31: =+ROUND(D31*E31,2) -> 13635.52 | I31: =+ROUND(D31*F31,2) -> 0 | J31: =+ROUND(H31+I31*TC,2) -> 13635.52
A32: =A31+0.0001 -> 1.0118 | B32: CERCO METALICO DE OBRA | C32: ml | D32: 0 | E32: 475 | G32: =IFERROR(IF(D32=0,"",(E32+F32*TC)),"") | H32: =+ROUND(D32*E32,2) -> 0 | I32: =+ROUND(D32*F32,2) -> 0 | J32: =+ROUND(H32+I32*TC,2) -> 0
A33: =A32+0.0001 -> 1.0119 | B33: MANTENIMIENTO, BASTIDORES+MALLA Y DESMONTAJE DE CERCO METALICO | C33: ml | D33: 76.3 | E33: 341.07 | G33: =IFERROR(IF(D33=0,"",(E33+F33*TC)),"") -> 341.07 | H33: =+ROUND(D33*E33,2) -> 26023.64 | I33: =+ROUND(D33*F33,2) -> 0 | J33: =+ROUND(H33+I33*TC,2) -> 26023.64
A34: =A33+0.0001 -> 1.012 | B34: PROTECCION PERIMETRAL INICIAL DE VECINOS | C34: glb | D34: 1 | E34: 6250 | G34: =IFERROR(IF(D34=0,"",(E34+F34*TC)),"") -> 6250 | H34: =+ROUND(D34*E34,2) -> 6250 | I34: =+ROUND(D34*F34,2) -> 0 | J34: =+ROUND(H34+I34*TC,2) -> 6250
A35: =A34+0.0001 -> 1.0121 | B35: CARTEL DE OBRA | C35: glb | D35: 1 | E35: 700 | G35: =IFERROR(IF(D35=0,"",(E35+F35*TC)),"") -> 700 | H35: =+ROUND(D35*E35,2) -> 700 | I35: =+ROUND(D35*F35,2) -> 0 | J35: =+ROUND(H35+I35*TC,2) -> 700
A36: =A14+0.01 -> 1.02 | B36: CAMPAMENTO Y SALA DE VENTAS CLIENTE - NO SE CONSIDERA | F36: 0 | K36: =SUM(J37:J40) -> 0
A37: =A36+0.0001 -> 1.0201 | B37: ESCUADRAS Y TABLAS PARA CASETA DE VENTAS EN VOLADIZO | C37: ml | D37: 0 | E37: 984.39 | F37: 69.6 | G37: =IFERROR(IF(D37=0,"",(E37+F37*TC)),"") | H37: =+ROUND(D37*E37,2) -> 0 | I37: =+ROUND(D37*F37,2) -> 0 | J37: =+ROUND(H37+I37*TC,2) -> 0
A38: =A37+0.0001 -> 1.0202 | B38: TRASLADO DE CONTENEDOR SALA DE VENTAS CLIENTE (MOVIMIENTO 1 VEZ) | C38: und | D38: 0 | E38: 1683.26 | F38: 0 | G38: =IFERROR(IF(D38=0,"",(E38+F38*TC)),"") | H38: =+ROUND(D38*E38,2) -> 0 | I38: =+ROUND(D38*F38,2) -> 0 | J38: =+ROUND(H38+I38*TC,2) -> 0
A39: =A38+0.0001 -> 1.0203 | B39: ESCALERA METALICA (1-2 PISO) INGRESO DE SALA VENTAS A DEP PILOTO | C39: glb | D39: 0 | E39: 2400 | F39: 0 | G39: =IFERROR(IF(D39=0,"",(E39+F39*TC)),"") | H39: =+ROUND(D39*E39,2) -> 0 | I39: =+ROUND(D39*F39,2) -> 0 | J39: =+ROUND(H39+I39*TC,2) -> 0
A40: =A39+0.0001 -> 1.0204 | B40: PROTECCION A ACCESO VERTICAL (1- PISO) | C40: glb | D40: 0 | E40: 1500 | F40: 0 | G40: =IFERROR(IF(D40=0,"",(E40+F40*TC)),"") | H40: =+ROUND(D40*E40,2) -> 0 | I40: =+ROUND(D40*F40,2) -> 0 | J40: =+ROUND(H40+I40*TC,2) -> 0
A41: =A36+0.01 -> 1.03 | B41: MOVILIZACION DE CAMPAMENTO, MAQUINARIA Y HERRAMIENTAS | K41: =SUM(J42:J42) -> 48782
A42: =A41+0.0001 -> 1.0301 | B42: MOVILIZACION Y DESMOVILIZACION (FLETES DURANTE LA OBRA) | C42: glb | D42: 1 | E42: 42350 | F42: 1920 | G42: =IFERROR(IF(D42=0,"",(E42+F42*TC)),"") -> 48782 | H42: =+ROUND(D42*E42,2) -> 42350 | I42: =+ROUND(D42*F42,2) -> 1920 | J42: =+ROUND(H42+I42*TC,2) -> 48782
A43: =A41+0.01 -> 1.04 | B43: MAQUINARIA Y HERRAMIENTAS | K43: =SUM(J44:J52) -> 33250
A44: =A43+0.0001 -> 1.0401 | B44: NIVEL TOPOGRAFICO (INC CUADRILLA TOPOGRAFIA) | C44: glb | D44: 0 | G44: =IFERROR(IF(D44=0,"",(E44+F44*TC)),"") | H44: =+ROUND(D44*E44,2) -> 0 | I44: =+ROUND(D44*F44,2) -> 0 | J44: =+ROUND(H44+I44*TC,2) -> 0
A45: =A44+0.0001 -> 1.0402 | B45: TEODOLITO ELECTRICO (INC CUADRILLA TOPOGRAFIA) | C45: glb | D45: 0 | G45: =IFERROR(IF(D45=0,"",(E45+F45*TC)),"") | H45: =+ROUND(D45*E45,2) -> 0 | I45: =+ROUND(D45*F45,2) -> 0 | J45: =+ROUND(H45+I45*TC,2) -> 0
...

Sheet GG
A2: Proyecto | B2: =+'RESUMEN ESCENARIO'!C6 -> PRESUPUESTO | GERMANIA | REV 09 | F2: Lugar | G2: =+'RESUMEN ESCENARIO'!C8 -> SURQUILLO
A3: Subpresupuesto | B3: Gastos Generales | F3: Fecha | G3: =+'RESUMEN ESCENARIO'!C9 -> 46090
A4: Cliente | B4: =+'RESUMEN ESCENARIO'!C7 -> VYV INMOBILIARIA
A6: GASTOS GENERALES
A9: ITEM | B9: DESCRIPCION | C9: UND | D9: CANTIDAD | E9: PRECIO | F9: PARCIAL | G9: Total
A10: 12 | B10: GASTOS GENERALES
A11: 12.01 | B11: PERSONAL STAFF | G11: =SUM(F12:F29) -> 2716500
A12: 12.01.01 | B12: Superintendente | C12: mes | D12: 6.9 | E12: 22500 | F12: =+D12*E12 -> 155250
A13: 12.01.02 | B13: Ingeniero Residente | C13: mes | D13: 24 | E13: 18750 | F13: =+D13*E13 -> 450000
A14: 12.01.03 | B14: Jefe de Oficina Técnica | C14: mes | D14: 24 | E14: 12000 | F14: =+D14*E14 -> 288000
A15: 12.01.04 | B15: Asistente de Oficina Técnica | C15: mes | D15: 17 | E15: 6750 | F15: =+D15*E15 -> 114750
A16: 12.01.05 | B16: Jefe de producción | C16: mes | D16: 17 | E16: 12000 | F16: =+D16*E16 -> 204000
A17: 12.01.06 | B17: Asistente de Producción | C17: mes | D17: 12 | E17: 6750 | F17: =+D17*E17 -> 81000
A18: 12.01.07 | B18: Ingeniero de Calidad | C18: mes | D18: 19 | E18: 9000 | F18: =+D18*E18 -> 171000
A19: 12.01.08 | B19: Asistente de Calidad | C19: mes | D19: 12 | E19: 6750 | F19: =+D19*E19 -> 81000
A20: 12.01.09 | B20: Ingeniero Electromecánico | C20: mes | D20: 19 | E20: 12000 | F20: =+D20*E20 -> 228000
A21: 12.01.11 | B21: Arquitecto de Acabados | C21: mes | D21: 15 | E21: 12000 | F21: =+D21*E21 -> 180000
A22: 12.01.12 | B22: Asistente de Acabados_1 | C22: mes | D22: 12 | E22: 6750 | F22: =+D22*E22 -> 81000
A23: 12.01.14 | B23: Prevencionista de Riesgos | C23: mes | D23: 23 | E23: 6750 | F23: =+D23*E23 -> 155250
... A27: 12.01.19 | B27: Asistente de Almacén | C27: mes | D27: 10 | E27: 5250 | F27: =+D27*E27 -> 52500
A30: 12.02 | B30: PERSONAL TECNICO | G30: =SUM(F31:F32) -> 287793.6
A31: 12.02.03 | B31: Maestro de Obra | C31: mes | D31: 16 | E31: 8097.1 | F31: =+D31*E31 -> 129553.6
A32: 12.02.11 | B32: Guardian de Obra | C32: mes | D32: 23 | E32: 6880 | F32: =+D32*E32 -> 158240
A34: 12.03 | B34: EQUIPO Y MOBILIARIO DE OFICINA | G34: =SUM(F35:F46) -> 145543.34
A35: 12.03.01 | B35: Computadora | C35: mes | D35: 23 | E35: 1078.4348 | F35: =+D35*E35 -> 24804
A36: 12.03.02 | B36: Celular | C36: und | D36: 23 | E36: 744.78261 | F36: =+D36*E36 -> 17130
A37: 12.03.03 | B37: Radio | C37: und | D37: 23 | E37: 685.32609 | F37: =+D37*E37 -> 15762.5
A38: 12.03.04 | B38: IMPRESORA A3 | C38: und | D38: 1 | E38: 2757 | F38: =+D38*E38 -> 2757
A39: 12.03.05 | B39: COMUNICACION TELEFONO EXTERNO / INTERNET | C39: und | D39: 24 | E39: 240 | F39: =+D39*E39 -> 5760
A40: 12.03.06 | B40: ESCRITORIOS Y SILLAS (CONTRATISTA) | C40: und | D40: 15 | E40: 250 | F40: =+D40*E40 -> 3750
A41: 12.03.07 | B41: MESAS DE TRABAJO Y DE REUNION | C41: und | D41: 1 | E41: 1000 | F41: =+D41*E41 -> 1000
A42: 12.03.08 | B42: UTILES DE OFICINA Y ECONOMATO | C42: glb | D42: 1 | E42: 7175 | F42: =+D42*E42 -> 7175
A43: 12.03.09 | B43: LICENCIA SOFWARE S10 | C43: glb | D43: 1 | E43: 17690.75 | F43: =+D43*E43 -> 17690.75
A44: 12.03.10 | B44: LICENCIA MS OFFICE 365 | C44: glb | D44: 1 | E44: 9794.4 | F44: =+D44*E44 -> 9794.4
A45: 12.03.11 | B45: LICENCIA AUTOCAD | C45: glb | D45: 1 | E45: 22772.75 | F45: =+D45*E45 -> 22772.75
A46: 12.03.12 | B46: LICENCIA REVIT | C46: glb | D46: 1 | E46: 17146.938 | F46: =+D46*E46 -> 17146.938
A48: 12.04 | B48: VARIOS | G48: =SUM(F49:F70) -> 610284.79
A49: 12.04.01 | B49: INSUMOS PARA LIMPIEZA | C49: mes | D49: 23 | E49: 250 | F49: =+D49*E49 -> 5750
A50: 12.04.02 | B50: PERSONAL DE LIMPIEZA (OFICINAS) | C50: mes | D50: 23 | E50: 967.5 | F50: =+D50*E50 -> 22252.5
A51: 12.04.03 | B51: FOTOCOPIADO | C51: mes | D51: 23 | E51: 300 | F51: =+D51*E51 -> 6900
...

Sheet Est Sotano 
C3: ESTRUCTURAS SOTANOS
C5: Presupuesto: | D5: =+'RESUMEN ESCENARIO'!C6 -> PRESUPUESTO | GERMANIA | REV 09
C6: Subpresupuesto: | D6: =+C3 -> ESTRUCTURAS SOTANOS
C7: Cliente: | D7: =+'RESUMEN ESCENARIO'!C7 -> VYV INMOBILIARIA
C8: Lugar: | D8: =+'RESUMEN ESCENARIO'!C8 -> SURQUILLO
C10: ITEM | D10: DESCRIPCION | E10: UND | F10: CANTIDAD | G10: CANTIDAD | H10: P.U. (PEN) | I10: P.U. (USD) | J10: P.U. TOTAL (PEN) | K10: PRECIO PARCIAL (PEN) | L10: PRECIO PARCIAL (USD) | M10: PARCIAL TOTAL (PEN) | N10: TOTAL
C11: 02 | D11: ESTRUCTURAS SÓTANO
C12: 02.01 | D12: OBRAS PRELIMINARES MOVIMIENTOS DE TIERRA | N12: =SUM(K12:K20)+SUM(L12:L20)*TC -> 134326.52
C13: 02.01.01 | D13: MOVILIZACION Y DESMOVILIZACION DE EQUIPOS MOVIMIENTO TIERRAS | E13: glb | F13: 1 | G13: 1 | H13: 21000 | I13: 0 | J13: =+ROUND(H13+I13*TC,2) -> 21000 | K13: =H13*G13 -> 21000 | L13: =I13*G13 -> 0 | M13: =+ROUND(K13+L13*TC,2) -> 21000
C14: 02.01.02 | D14: EXTRACCION DE EQUIPOS MOVIMIENTO TIERRAS | E14: glb | F14: 1 | G14: 1 | H14: 26000 | I14: 0 | J14: =+ROUND(H14+I14*TC,2) -> 26000 | K14: =H14*G14 -> 26000 | L14: =I14*G14 -> 0 | M14: =+ROUND(K14+L14*TC,2) -> 26000
C15: 02.01.03 | D15: INSTALACION Y DESISTALACION DE PLATAFORMA | E15: glb | F15: 1 | G15: 1 | H15: 25000 | I15: 0 | J15: =+ROUND(H15+I15*TC,2) -> 25000 | K15: =H15*G15 -> 25000 | L15: =I15*G15 -> 0 | M15: =+ROUND(K15+L15*TC,2) -> 25000
C16: 02.01.04 | D16: EXTRACCION DE EQUIPOS PERFORACION CON GRUAS | E16: glb | F16: 4 | G16: 4 | I16: 720 | J16: =+ROUND(H16+I16*TC,2) -> 2412 | K16: =H16*G16 -> 0 | L16: =I16*G16 -> 2880 | M16: =+ROUND(K16+L16*TC,2) -> 9648
C17: 02.01.05 | D17: Control de polvo durante la excavación masiva. | E17: und | F17: 8 | G17: 8 | H17: 584.81554 | I17: 0 | J17: =+ROUND(H17+I17*TC,2) -> 584.82 | K17: =H17*G17 -> 4678.5243 | L17: =I17*G17 -> 0 | M17: =+ROUND(K17+L17*TC,2) -> 4678.52
D18: Biombo para eliminación en la via pública | E18: glb | F18: 1 | G18: 1 | H18: 4000 | I18: 0 | J18: =+ROUND(H18+I18*TC,2) -> 4000 | K18: =H18*G18 -> 4000 | L18: =I18*G18 -> 0 | M18: =+ROUND(K18+L18*TC,2) -> 4000
D19: Movilización y Desmovilización de Excavadora sobre orugas o neumática para el Proceso de Pasamanos | E19: glb | F19: 1 | G19: 1 | H19: 20000 | I19: 0 | J19: =+ROUND(H19+I19*TC,2) -> 20000 | K19: =H19*G19 -> 20000 | L19: =I19*G19 -> 0 | M19: =+ROUND(K19+L19*TC,2) -> 20000
D20: Movilización y Desmovilizacion de plataforma + escuadras para eliminacion (incluye montaje y desmontaje) | E20: glb | F20: 2 | G20: 2 | H20: 12000 | I20: 0 | J20: =+ROUND(H20+I20*TC,2) -> 12000 | K20: =H20*G20 -> 24000 | L20: =I20*G20 -> 0 | M20: =+ROUND(K20+L20*TC,2) -> 24000
C21: 02.02 | D21: MOVIMIENTO DE TIERRAS | G21: 0 | N21: =SUM(K21:K31)+SUM(L21:L31)*TC -> 1021804
C22: 02.02.01 | D22: EXCAVACIÓN Y ELIMINACION MASIVA POR NIVEL | G22: 0
C23: 02.02.01.01 | D23: Excavacion Masiva y Eliminación del Sótano 01 c/01 Excavadora por Rampa (Material contaminado) (botadero autorizado | E23: m3 | F23: 2000 | G23: 2000 | H23: 37.68 | I23: 0 | J23: =+ROUND(H23+I23*TC,2) -> 37.68 | K23: =H23*G23 -> 75360 | L23: =I23*G23 -> 0 | M23: =+ROUND(K23+L23*TC,2) -> 75360
D24: Excavacion Masiva y Eliminación del Sótano 01 c/01 Excavadora por Rampa (de -0.00 a -3.45 ) | F24: 2329.44 | G24: 2329.44 | H24: 27.68 | J24: =+ROUND(H24+I24*TC,2) -> 27.68 | K24: =H24*G24 -> 64478.899 | L24: =I24*G24 -> 0 | M24: =+ROUND(K24+L24*TC,2) -> 64478.9
C25: 02.02.01.03 | D25: Excavacion Masiva y Eliminación del Sótano 02 c/02 Excavadoras por Rampa (de -3.45 a -6.30) | E25: m3 | F25: 3576.47 | G25: 3576.47 | H25: 27.68 | I25: 0 | J25: =+ROUND(H25+I25*TC,2) -> 27.68 | K25: =H25*G25 -> 98996.69 | L25: =I25*G25 -> 0 | M25: =+ROUND(K25+L25*TC,2) -> 98996.69
C26: 02.02.01.04 | D26: Excavacion Masiva y Eliminación del Sótano 03 c/03 Excavadoras por Rampa y Pasamanos (de -6.30 a -9.15) | E26: m3 | F26: 3576.47 | G26: 3576.47 | H26: 27.68 | I26: 0 | J26: =+ROUND(H26+I26*TC,2) -> 27.68 | K26: =H26*G26 -> 98996.69 | L26: =I26*G26 -> 0 | M26: =+ROUND(K26+L26*TC,2) -> 98996.69
C27: 02.02.01.05 | D27: Excavacion Masiva y Eliminación del sótano 04 c/03 Excavadoras por plataforma + Pasamanos (de -9.15 a -12.00) | E27: m3 | F27: 3576.47 | G27: 3576.47 | H27: 32.68 | I27: 0 | J27: =+ROUND(H27+I27*TC,2) -> 32.68 | K27: =H27*G27 -> 116879.04 | L27: =I27*G27 -> 0 | M27: =+ROUND(K27+L27*TC,2) -> 116879.04
C28: 02.02.01.06 | D28: Excavacion Masiva y Eliminación del sótano 05 c/03 Excavadoras por plataforma + Pasamanos (de -12.00 a -14.85) | E28: m3 | F28: 3576.47 | G28: 3576.47 | H28: 32.68 | I28: 0 | J28: =+ROUND(H28+I28*TC,2) -> 32.68 | K28: =H28*G28 -> 116879.04 | L28: =I28*G28 -> 0 | M28: =+ROUND(K28+L28*TC,2) -> 116879.04
C29: 02.02.01.07 | D29: Excavacion Masiva y Eliminación del sótano 06 c/02 Excavadoras + Grúa Telescópica + balde (de -14.85 a -18.00) | E29: m3 | F29: 3952.95 | G29: 3952.95 | H29: 47.68 | I29: 0 | J29: =+ROUND(H29+I29*TC,2) -> 47.68 | K29: =H29*G29 -> 188476.66 | L29: =I29*G29 -> 0 | M29: =+ROUND(K29+L29*TC,2) -> 188476.66
C30: 02.02.01.09 | D30: Excavacion Masiva y Eliminación del sótano 07 c/02 Excavadoras + Grúa Telescópica + balde (de -18.00 a -19.80) + cisterna -22.82 | E30: m3 | F30: 5489.45 | G30: 5489.45 | H30: 47.68 | I30: 0 | J30: =+ROUND(H30+I30*TC,2) -> 47.68 | K30: =H30*G30 -> 261736.98 | L30: =I30*G30 -> 0 | M30: =+ROUND(K30+L30*TC,2) -> 261736.98
C31: 02.02.01.09 | D31: Excavacion de cisternas y cuarto de bombas (N -23.00) | E31: m3 | F31: 0 | G31: 0 | H31: 0 | I31: 0 | J31: =+ROUND(H31+I31*TC,2) -> 0 | K31: =H31*G31 -> 0 | L31: =I31*G31 -> 0 | M31: =+ROUND(K31+L31*TC,2) -> 0
C32: 02.02.02 | D32: EXCAVACIÓN LOCALIZADA | G32: 0 | H32: 0 | N32: =SUM(K32:K37)+SUM(L32:L37)*TC -> 58723.976
C33: 02.02.02.01 | D33: EXCAVACION Y ELIIMINACION DE ZAPATAS, CIMIENTOS DE MURO ANCLADO CON BALDE Y GRUA | E33: m3 | F33: 1114.73 | G33: 1114.73 | H33: 52.68 | I33: 0 | J33: =+ROUND(H33+I33*TC,2) -> 52.68 | K33: =H33*G33 -> 58723.976 | L33: =I33*G33 -> 0 | M33: =+ROUND(K33+L33*TC,2) -> 58723.98
C34: 02.02.02.02 | D34: EXCAVACION LOCALIZADA PARA VIGAS DE CIMENTACION | E34: m3 | G34: 0 | H34: 41.73 | I34: 0
C35: 02.02.02.01 | D35: EXCAVACION LOCALIZADA PARA PAÑO DE MUROS ANCLADOS BAJO LA LINEA DE TALUD (SEGÚN GRAFICO DEL 29/11 POR CORREO) | E35: m3 | G35: 0 | H35: 35 | I35: 0 | J35: =+ROUND(H35+I35*TC,2) -> 35 | K35: =H35*G35 -> 0 | L35: =I35*G35 -> 0 | M35: =+ROUND(K35+L35*TC,2) -> 0
C36: 02.02.02.03 | D36: EXCAVACION MANUAL PARA CIMIENTOS DE TABIQUES (BATEA DE CIMENTACION) | E36: m3 | G36: 0 | H36: 41.73 | I36: 0 | J36: =+ROUND(H36+I36*TC,2) -> 41.73 | K36: =H36*G36 -> 0 | L36: =I36*G36 -> 0 | M36: =+ROUND(K36+L36*TC,2) -> 0
C37: 02.02.02.03 | D37: EXCAVACION MANUAL PARA CALZADURA FALSA ZAPATA | E37: m3 | G37: 0 | H37: 62.59 | I37: 0 | J37: =+ROUND(H37+I37*TC,2) -> 62.59 | K37: =H37*G37 -> 0 | L37: =I37*G37 -> 0 | M37: =+ROUND(K37+L37*TC,2) -> 0
C38: 02.02.03 | D38: RELLENO Y COMPACTACIÓN | G38: 0 | N38: =SUM(K38:K40)+SUM(L38:L40)*TC -> 78165.476
C39: 02.02.03.01 | D39: RELLENO COMPACTADO CON MATERIAL PROPIO | E39: m3 | F39: 1605.7 | G39: 1605.7 | H39: 48.68 | I39: 0 | J39: =+ROUND(H39+I39*TC,2) -> 48.68 | K39: =H39*G39 -> 78165.476 | L39: =I39*G39 -> 0 | M39: =+ROUND(K39+L39*TC,2) -> 78165.48
C40: 02.02.02.01 | D40: RELLENO COMPACTADO CON MATERIAL PROPIO | E40: m3 | G40: 0 | H40: 43.91 | I40: 0 | J40: =+ROUND(H40+I40*TC,2) -> 43.91 | K40: =H40*G40 -> 0 | L40: =I40*G40 -> 0 | M40: =+ROUND(K40+L40*TC,2) -> 0
C41: 02.02.04 | D41: NIVELACION, APISONADO Y BASE DE AFIRMADO | G41: 0 | N41: =SUM(K41:K44)+SUM(L41:L44)*TC -> 83028.398
C42: 02.02.04.01 | D42: NIVELACION Y COMPACTACION DE SUBRASANTE | E42: m2 | F42: 1235.05 | G42: 1235.05 | H42: 10.68 | I42: 0 | J42: =+ROUND(H42+I42*TC,2) -> 10.68 | K42: =H42*G42 -> 13190.334 | L42: =I42*G42 -> 0 | M42: =+ROUND(K42+L42*TC,2) -> 13190.33
C43: 02.02.04.02 | D43: SUB BASE DE AFIRMADO COMPACTADO, e= 25 cm | E43: m2 | F43: 1235.05 | G43: 1235.05 | H43: 33.68 | I43: 0 | J43: =+ROUND(H43+I43*TC,2) -> 33.68 | K43: =H43*G43 -> 41596.484 | L43: =I43*G43 -> 0 | M43: =+ROUND(K43+L43*TC,2) -> 41596.48
C44: 02.02.04.03 | D44: BASE DE AFIRMADO COMPACTADO, E=15CM (conforme a EMS) | E44: m2 | F44: 1099.75 | G44: 1099.75 | H44: 25.68 | I44: 0 | J44: =+ROUND(H44+I44*TC,2) -> 25.68 | K44: =H44*G44 -> 28241.58 | L44: =I44*G44 -> 0 | M44: =+ROUND(K44+L44*TC,2) -> 28241.58
...

Sheet EST TORRE
B3: ESTRUCTURAS TORRE
B5: Presupuesto: | C5: =+'Est Sotano '!D5 -> PRESUPUESTO | GERMANIA | REV 09
B6: Subpresupuesto: | C6: ESTRUCTURAS TORRE
B7: Cliente: | C7: =+'Est Sotano '!D7 -> VYV INMOBILIARIA
B8: Lugar: | C8: =+'Est Sotano '!D8 -> SURQUILLO
B10: ITEM | C10: DESCRIPCION | D10: UND | E10: CANTIDAD | F10: CANTIDAD | G10: P.U. (PEN) | H10: P.U. (USD) | I10: P.U. TOTAL (PEN) | J10: PRECIO PARCIAL (PEN) | K10: PRECIO PARCIAL (USD) | L10: PARCIAL TOTAL (PEN) | M10: TOTAL
B11: 02 | C11: ESTRUCTURAS TORRE
B12: 02.01.01 | C12: PLACAS | M12: =SUM(J12:J21)+SUM(K12:K21)*TC -> 2036035.3
B13: 02.01.01.01 | C13: CONCRETO PREMEZCLADO, CEMENTO TIPO I, PLACAS f'c=210 kg/cm2 | D13: m3 | G13: 380.32 | H13: 0 | I13: =+ROUND(G13+H13*TC,2) -> 380.32 | J13: =G13*F13 -> 0 | K13: =H13*F13 -> 0 | L13: =+ROUND(J13+K13*TC,2) -> 0
B14: 02.01.01.02 | C14: CONCRETO PREMEZCLADO, CEMENTO TIPO I, PLACAS f'c=280 kg/cm2 | D14: m3 | E14: 1036.8555 | F14: 1036.86 | G14: 408.72 | H14: 0 | I14: =+ROUND(G14+H14*TC,2) -> 408.72 | J14: =G14*F14 -> 423785.42 | K14: =H14*F14 -> 0 | L14: =+ROUND(J14+K14*TC,2) -> 423785.42
B15: 02.01.01.03 | C15: CONCRETO PREMEZCLADO, CEMENTO TIPO I, PLACAS f'c=350 kg/cm2 | D15: m3 | E15: 324.2511 | F15: 324.25 | G15: 447.61 | H15: 0 | I15: =+ROUND(G15+H15*TC,2) -> 447.61 | J15: =G15*F15 -> 145137.54 | K15: =H15*F15 -> 0 | L15: =+ROUND(J15+K15*TC,2) -> 145137.54
B16: 02.01.01.04 | C16: CONCRETO PREMEZCLADO, CEMENTO TIPO I, PLACAS f'c=420 kg/cm2 | D16: m3 | E16: 227.7092 | F16: 227.71 | G16: 463.86 | H16: 0 | I16: =+ROUND(G16+H16*TC,2) -> 463.86 | J16: =G16*F16 -> 105625.56 | K16: =H16*F16 -> 0 | L16: =+ROUND(J16+K16*TC,2) -> 105625.56
B17: 02.01.01.05 | C17: ENCOFRADO Y DESENCOFRADO DE MUROS Y PLACAS | D17: m2 | E17: 8822.9539 | F17: 8822.95 | G17: 50.38 | H17: 0 | I17: =+ROUND(G17+H17*TC,2) -> 50.38 | J17: =G17*F17 -> 444500.22 | K17: =H17*F17 -> 0 | L17: =+ROUND(J17+K17*TC,2) -> 444500.22
B18: 02.01.01.06 | C18: ENCOFRADO Y DESENCOFRADO DE MUROS Y PLACAS DOBLE ALTURA | D18: m2 | E18: 1231.5432 | F18: 1231.54 | G18: 60.63 | H18: 0 | I18: =+ROUND(G18+H18*TC,2) -> 60.63 | J18: =G18*F18 -> 74668.27 | K18: =H18*F18 -> 0 | L18: =+ROUND(J18+K18*TC,2) -> 74668.27
B19: 02.01.01.07 | C19: ACERO DE REFUERZO FY= 4200 kg/cm2, GRADO 60 | D19: kg | E19: 196005.59 | F19: 196005.59 | G19: 1.24 | H19: 0.89 | I19: =+ROUND(G19+H19*TC,2) -> 4.22 | J19: =G19*F19 -> 243046.93 | K19: =H19*F19 -> 174444.98 | L19: =+ROUND(J19+K19*TC,2) -> 827437.6
B20: 02.01.01.08 | C20: CURADO DE ELEMENTOS ESTRUCTURALES EXPUESTOS | D20: m2 | E20: 10054.497 | F20: 10054.5 | G20: 1.48 | H20: 0 | I20: =+ROUND(G20+H20*TC,2) -> 1.48 | J20: =G20*F20 -> 14880.66 | K20: =H20*F20 -> 0 | L20: =+ROUND(J20+K20*TC,2) -> 14880.66
B21: 02.02.01 | C21: MUROS P/ JARDINERAS - - CORTES TECHO SOTANO 01 | F21: 0 | M21: =SUM(J21:J25)+SUM(K21:K25)*TC -> 12222.878
B22: 02.02.01.01 | C22: CONCRETO PREMEZCLADO, CEMENTO TIPO I, PLACAS f'c=210 kg/cm2 | D22: m3 | E22: 6.903428 | F22: 6.9 | G22: 380.32 | H22: 0 | I22: =+ROUND(G22+H22*TC,2) -> 380.32 | J22: =G22*F22 -> 2624.208 | K22: =H22*F22 -> 0 | L22: =+ROUND(J22+K22*TC,2) -> 2624.21
B23: 02.02.01.02 | C23: ENCOFRADO Y DESENCOFRADO DE MUROS Y PLACAS | D23: m2 | E23: 118.4168 | F23: 118.42 | G23: 50.38 | H23: 0 | I23: =+ROUND(G23+H23*TC,2) -> 50.38 | J23: =G23*F23 -> 5965.9996 | K23: =H23*F23 -> 0 | L23: =+ROUND(J23+K23*TC,2) -> 5966
B24: 02.02.01.03 | C24: ACERO DE REFUERZO FY= 4200 kg/cm2, GRADO 60 | D24: kg | E24: 819.0024 | F24: 819 | G24: 1.24 | H24: 0.89 | I24: =+ROUND(G24+H24*TC,2) -> 4.22 | J24: =G24*F24 -> 1015.56 | K24: =H24*F24 -> 728.91 | L24: =+ROUND(J24+K24*TC,2) -> 3457.41
B25: 02.02.01.04 | C25: CURADO DE ELEMENTOS ESTRUCTURALES EXPUESTOS | D25: m2 | E25: 118.4168 | F25: 118.42 | G25: 1.48 | H25: 0 | I25: =+ROUND(G25+H25*TC,2) -> 1.48 | J25: =G25*F25 -> 175.2616 | K25: =H25*F25 -> 0 | L25: =+ROUND(J25+K25*TC,2) -> 175.26
B26: 02.02.01 | C26: MUROS PISCINA | F26: 0 | M26: =SUM(J26:J30)+SUM(K26:K30)*TC -> 25634.017
B27: 02.02.01.01 | C27: CONCRETO PREMEZCLADO, CEMENTO TIPO I, PLACAS f'c=210 kg/cm2 | D27: m3 | E27: 21.86619 | F27: 21.87 | G27: 380.32 | H27: 0 | I27: =+ROUND(G27+H27*TC,2) -> 380.32 | J27: =G27*F27 -> 8317.5984 | K27: =H27*F27 -> 0 | L27: =+ROUND(J27+K27*TC,2) -> 8317.6
B28: 02.02.01.02 | C28: ENCOFRADO Y DESENCOFRADO DE MUROS Y PLACAS | D28: m2 | E28: 206.6775 | F28: 206.68 | G28: 50.38 | H28: 0 | I28: =+ROUND(G28+H28*TC,2) -> 50.38 | J28: =G28*F28 -> 10412.538 | K28: =H28*F28 -> 0 | L28: =+ROUND(J28+K28*TC,2) -> 10412.54
B29: 02.02.01.03 | C29: ACERO DE REFUERZO FY= 4200 kg/cm2, GRADO 60 | D29: kg | E29: 1562.9512 | F29: 1562.95 | G29: 1.24 | H29: 0.89 | I29: =+ROUND(G29+H29*TC,2) -> 4.22 | J29: =G29*F29 -> 1938.058 | K29: =H29*F29 -> 1391.0255 | L29: =+ROUND(J29+K29*TC,2) -> 6597.99
B30: 02.02.01.04 | C30: CURADO DE ELEMENTOS ESTRUCTURALES EXPUESTOS | D30: m2 | E30: 206.6775 | F30: 206.68 | G30: 1.48 | H30: 0 | I30: =+ROUND(G30+H30*TC,2) -> 1.48 | J30: =G30*F30 -> 305.8864 | K30: =H30*F30 -> 0 | L30: =+ROUND(J30+K30*TC,2) -> 305.89
B31: 02.03.01 | C31: COLUMNAS | F31: 0 | M31: =SUM(J31:J39)+SUM(K31:K39)*TC -> 972578.62
B32: 02.03.01.01 | C32: CONCRETO PREMEZCLADO, CEMENTO TIPO I, COLUMNAS f'c=210 kg/cm2 | D32: m3 | F32: 0 | G32: 385.51 | H32: 0 | I32: =+ROUND(G32+H32*TC,2) -> 385.51 | J32: =G32*F32 -> 0 | K32: =H32*F32 -> 0 | L32: =+ROUND(J32+K32*TC,2) -> 0
B33: 02.03.01.02 | C33: CONCRETO PREMEZCLADO, CEMENTO TIPO I, COLUMNAS f'c=280 kg/cm2 | D33: m3 | E33: 365.397 | F33: 365.4 | G33: 408.72 | H33: 0 | I33: =+ROUND(G33+H33*TC,2) -> 408.72 | J33: =G33*F33 -> 149346.29 | K33: =H33*F33 -> 0 | L33: =+ROUND(J33+K33*TC,2) -> 149346.29
B34: 02.03.01.03 | C34: CONCRETO PREMEZCLADO, CEMENTO TIPO I, COLUMNAS f'c=350 kg/cm2 | D34: m3 | E34: 121.2179 | F34: 121.22 | G34: 447.61 | H34: 0 | I34: =+ROUND(G34+H34*TC,2) -> 447.61 | J34: =G34*F34 -> 54259.284 | K34: =H34*F34 -> 0 | L34: =+ROUND(J34+K34*TC,2) -> 54259.28
B35: 02.03.01.04 | C35: CONCRETO PREMEZCLADO, CEMENTO TIPO I, COLUMNAS f'c=420 kg/cm2 | D35: m3 | E35: 86.0719 | F35: 86.07 | G35: 463.86 | H35: 0 | I35: =+ROUND(G35+H35*TC,2) -> 463.86 | J35: =G35*F35 -> 39924.43 | K35: =H35*F35 -> 0 | L35: =+ROUND(J35+K35*TC,2) -> 39924.43
B36: 02.03.01.05 | C36: ENCOFRADO Y DESENCOFRADO DE COLUMNAS | D36: m2 | E36: 2708.41 | F36: 2708.41 | G36: 50.78 | H36: 0 | I36: =+ROUND(G36+H36*TC,2) -> 50.78 | J36: =G36*F36 -> 137533.06 | K36: =H36*F36 -> 0 | L36: =+ROUND(J36+K36*TC,2) -> 137533.06
B37: 02.03.01.06 | C37: ENCOFRADO Y DESENCOFRADO DE COLUMNAS DOBLE ALTURA | D37: m2 | E37: 410.4276 | F37: 410.43 | G37: 61.03 | H37: 0 | I37: =+ROUND(G37+H37*TC,2) -> 61.03 | J37: =G37*F37 -> 25048.543 | K37: =H37*F37 -> 0 | L37: =+ROUND(J37+K37*TC,2) -> 25048.54
B38: 02.03.01.07 | C38: ACERO DE REFUERZO FY= 4200 kg/cm2, GRADO 60 | D38: kg | E38: 133092.77 | F38: 133092.77 | G38: 1.24 | H38: 0.89 | I38: =+ROUND(G38+H38*TC,2) -> 4.22 | J38: =G38*F38 -> 165035.03 | K38: =H38*F38 -> 118452.57 | L38: =+ROUND(J38+K38*TC,2) -> 561851.13
B39: 02.03.01.08 | C39: CURADO DE ELEMENTOS ESTRUCTURALES EXPUESTOS | D39: m2 | E39: 3118.8376 | F39: 3118.84 | G39: 1.48 | H39: 0 | I39: =+ROUND(G39+H39*TC,2) -> 1.48 | J39: =G39*F39 -> 4615.8832 | K39: =H39*F39 -> 0 | L39: =+ROUND(J39+K39*TC,2) -> 4615.88
B40: 02.04.01 | C40: VIGAS | F40: 0 | M40: =SUM(J40:J92)+SUM(K40:K92)*TC -> 5227691.3
B41: 02.04.01.01 | C41: CONCRETO PREMEZCLADO, CEMENTO TIPO I, VIGAS TORRE f'c=280 kg/cm2 | D41: m3 | E41: 1429.3867 | F41: 1429.39 | G41: 415.48 | H41: 0 | I41: =+ROUND(G41+H41*TC,2) -> 415.48 | J41: =G41*F41 -> 593882.96 | K41: =H41*F41 -> 0 | L41: =+ROUND(J41+K41*TC,2) -> 593882.96
B42: 02.04.01.02 | C42: CONCRETO PREMEZCLADO, CEMENTO TIPO I, VIGAS TORRE f'c=210 kg/cm2 | D42: m3 | F42: 0 | G42: 391.63 | H42: 0 | I42: =+ROUND(G42+H42*TC,2) -> 391.63 | J42: =G42*F42 -> 0 | K42: =H42*F42 -> 0 | L42: =+ROUND(J42+K42*TC,2) -> 0
B43: 02.04.01.03 | C43: CONCRETO PREMEZCLADO, CEMENTO TIPO I, VIGAS TORRE f'c=350 kg/cm2 | D43: m3 | E43: 45.8395 | F43: 45.84 | G43: 454.38 | H43: 0 | I43: =+ROUND(G43+H43*TC,2) -> 454.38 | J43: =G43*F43 -> 20828.779 | K43: =H43*F43 -> 0 | L43: =+ROUND(J43+K43*TC,2) -> 20828.78
B44: 02.04.01.03 | C44: CONCRETO PREMEZCLADO, CEMENTO TIPO I, VIGAS TORRE f'c=420 kg/cm2 | D44: m3 | E44: 49.0113 | F44: 49.01 | G44: 470.63 | H44: 0 | I44: =+ROUND(G44+H44*TC,2) -> 470.63 | J44: =G44*F44 -> 23065.576 | K44: =H44*F44 -> 0 | L44: =+ROUND(J44+K44*TC,2) -> 23065.58
...

Sheet ARQ SOT
B2: ARQUITECTURA SÓTANOS
B4: Presupuesto | C4: =+'RESUMEN ESCENARIO'!C6 -> PRESUPUESTO | GERMANIA | REV 09
B5: Subpresupuesto | C5: =$B$2 -> ARQUITECTURA SÓTANOS
B6: Cliente | C6: =+'RESUMEN ESCENARIO'!C7 -> VYV INMOBILIARIA
B7: Lugar | C7: =+'RESUMEN ESCENARIO'!C8 -> SURQUILLO
B8: Fecha | C8: =+'RESUMEN ESCENARIO'!C9 -> 46090
B10: ITEM | C10: DESCRIPCION | D10: UND | E10: METRADO | F10: P.U. (PEN) | G10: P.U. (USD) | H10: P.U. TOTAL (PEN) | I10: PRECIO PARCIAL (PEN) | J10: PRECIO PARCIAL (USD) | K10: PARCIAL TOTAL (PEN) | L10: TOTAL
B11: 05 | C11: =$B$2 -> ARQUITECTURA SÓTANOS
B12: =B11+0.01 -> 5.01 | C12: MUROS Y TABIQUES | H12: =IFERROR(IF(D12<>0,(F12+G12*TC)," ")," ") | I12: =IFERROR(IF($E12=0,"",$E12*F12),"") | J12: =IFERROR(IF($E12=0,"",$E12*G12),"") | K12: =IFERROR(IF(E12<>0,(E12*H12)," "),0) | L12: =SUM(I12:I51)+SUM(J12:J51)*TC -> 244946.95
B13: =B12+0.0001 -> 5.0101 | C13: MUROS Y TABIQUES SILICO CALCAREOS | H13: =IFERROR(IF(D13<>0,(F13+G13*TC)," ")," ") | I13: =IFERROR(IF($E13=0,"",$E13*F13),"") | J13: =IFERROR(IF($E13=0,"",$E13*G13),"") | K13: =IFERROR(IF(E13<>0,(E13*H13)," "),0)
B14: =B12+0.0001 -> 5.0101 | C14: ALTURA < 2.60 | H14: =IFERROR(IF(D14<>0,(F14+G14*TC)," ")," ") | I14: =IFERROR(IF($E14=0,"",$E14*F14),"") | J14: =IFERROR(IF($E14=0,"",$E14*G14),"") | K14: =IFERROR(IF(E14<>0,(E14*H14)," "),0)
B15: =B14+0.000001 -> 5.010101 | C15: LADRILLO SILICO CALCAREO TIPO P7 H<2.6M | D15: m2
B16: =B14+0.000001 -> 5.010101 | C16: LADRILLO SILICO CALCAREO TIPO P10 H<2.6M | D16: m2 | E16: 348.42 | F16: 111.23 | H16: =+ROUND(F16+G16*TC,2) -> 111.23 | I16: =+ROUND(E16*F16,2) -> 38754.76 | J16: =+ROUND(E16*G16,2) -> 0 | K16: =+ROUND(I16+J16*TC,2) -> 38754.76
B17: =B15+0.000001 -> 5.010102 | C17: LADRILLO SILICO CALCAREO TIPO P12 H<2.6M | D17: m2 | E17: 103.8 | F17: 117.23 | H17: =+ROUND(F17+G17*TC,2) -> 117.23 | I17: =+ROUND(E17*F17,2) -> 12168.47 | J17: =+ROUND(E17*G17,2) -> 0 | K17: =+ROUND(I17+J17*TC,2) -> 12168.47
B18: =B17+0.000001 -> 5.010103 | C18: LADRILLO SILICO CALCAREO TIPO P14 H<2.6M | D18: m2 | E18: 1.4 | F18: 125.23 | H18: =+ROUND(F18+G18*TC,2) -> 125.23 | I18: =+ROUND(E18*F18,2) -> 175.32 | J18: =+ROUND(E18*G18,2) -> 0 | K18: =+ROUND(I18+J18*TC,2) -> 175.32
B19: =B18+0.000001 -> 5.010104 | C19: LADRILLO SILICO CALCAREO TIPO P20 H<2.6M | D19: m2 | E19: 0 | F19: 206.23 | H19: =+ROUND(F19+G19*TC,2) -> 206.23 | I19: =+ROUND(E19*F19,2) -> 0 | J19: =+ROUND(E19*G19,2) -> 0 | K19: =+ROUND(I19+J19*TC,2) -> 0
B20: =B14+0.0001 -> 5.0102 | C20: ALTURA > 2.60 | E20: 0
B21: =B20+0.000001 -> 5.010201 | C21: LADRILLO SILICO CALCAREO TIPO P7 H>2.6M | D21: m2 | E21: 6.71 | F21: 113.23 | H21: =+ROUND(F21+G21*TC,2) -> 113.23 | I21: =+ROUND(E21*F21,2) -> 759.77 | J21: =+ROUND(E21*G21,2) -> 0 | K21: =+ROUND(I21+J21*TC,2) -> 759.77
B22: =B21+0.000001 -> 5.010202 | C22: LADRILLO SILICO CALCAREO TIPO P10 H>2.6M | D22: m2 | E22: 767.55 | F22: 120.23 | H22: =+ROUND(F22+G22*TC,2) -> 120.23 | I22: =+ROUND(E22*F22,2) -> 92282.54 | J22: =+ROUND(E22*G22,2) -> 0 | K22: =+ROUND(I22+J22*TC,2) -> 92282.54
B23: =B22+0.000001 -> 5.010203 | C23: LADRILLO SILICO CALCAREO TIPO P12 H>2.6M | D23: m2 | E23: 60.95 | F23: 126.23 | H23: =+ROUND(F23+G23*TC,2) -> 126.23 | I23: =+ROUND(E23*F23,2) -> 7693.72 | J23: =+ROUND(E23*G23,2) -> 0 | K23: =+ROUND(I23+J23*TC,2) -> 7693.72
B24: =B23+0.000001 -> 5.010204 | C24: LADRILLO SILICO CALCAREO TIPO P14 H>2.6M | D24: m2 | E24: 0 | F24: 134.23 | H24: =+ROUND(F24+G24*TC,2) -> 134.23 | I24: =+ROUND(E24*F24,2) -> 0 | J24: =+ROUND(E24*G24,2) -> 0 | K24: =+ROUND(I24+J24*TC,2) -> 0
B25: =B24+0.000001 -> 5.010205 | C25: LADRILLO SILICO CALCAREO TIPO P20 H>2.6M | D25: m2 | E25: 0 | F25: 224.23 | H25: =+ROUND(F25+G25*TC,2) -> 224.23 | I25: =+ROUND(E25*F25,2) -> 0 | J25: =+ROUND(E25*G25,2) -> 0 | K25: =+ROUND(I25+J25*TC,2) -> 0
B26: =B15+0.0001 -> 5.010201 | C26: CORTAFUEGO < 2.60 | E26: 0
B27: =B26+0.000001 -> 5.010202 | C27: LADRILLO SILICO CALCAREO TIPO P10 RF:2 HRS H<2.6M (ALVEOLOS COMPLETAMENTE LLENO) | D27: m2 | E27: 0 | F27: 121.23 | H27: =+ROUND(F27+G27*TC,2) -> 121.23 | I27: =+ROUND(E27*F27,2) -> 0 | J27: =+ROUND(E27*G27,2) -> 0 | K27: =+ROUND(I27+J27*TC,2) -> 0
B28: =B27+0.000001 -> 5.010203 | C28: LADRILLO SILICO CALCAREO TIPO P12 RF:2 HRS H<2.6M (ALVEOLOS PARCIALMENTE LLENO) | D28: m2 | E28: 171.05 | F28: 117.23 | H28: =+ROUND(F28+G28*TC,2) -> 117.23 | I28: =+ROUND(E28*F28,2) -> 20052.19 | J28: =+ROUND(E28*G28,2) -> 0 | K28: =+ROUND(I28+J28*TC,2) -> 20052.19
B29: =B28+0.000001 -> 5.010204 | C29: LADRILLO SILICO CALCAREO TIPO P14 RF:2 HRS H<2.6M (ALVEOLOS PARCIALMENTE LLENO) | D29: m2 | E29: 0 | F29: 125.23 | H29: =+ROUND(F29+G29*TC,2) -> 125.23 | I29: =+ROUND(E29*F29,2) -> 0 | J29: =+ROUND(E29*G29,2) -> 0 | K29: =+ROUND(I29+J29*TC,2) -> 0
B30: =B20+0.0001 -> 5.0103 | C30: CORTAFUEGO > 2.60 | E30: 0
B31: =B30+0.000001 -> 5.010301 | C31: LADRILLO SILICO CALCAREO TIPO P10 RF:2 HRS H>2.6M (ALVEOLOS COMPLETAMENTE LLENO) | D31: m2 | E31: 0 | F31: 130.23 | H31: =+ROUND(F31+G31*TC,2) -> 130.23 | I31: =+ROUND(E31*F31,2) -> 0 | J31: =+ROUND(E31*G31,2) -> 0 | K31: =+ROUND(I31+J31*TC,2) -> 0
B32: =B31+0.000001 -> 5.010302 | C32: LADRILLO SILICO CALCAREO TIPO P12 RF:2 HRS H>2.6M (ALVEOLOS PARCIALMENTE LLENO) | D32: m2 | E32: 407.65 | F32: 126.23 | H32: =+ROUND(F32+G32*TC,2) -> 126.23 | I32: =+ROUND(E32*F32,2) -> 51457.66 | J32: =+ROUND(E32*G32,2) -> 0 | K32: =+ROUND(I32+J32*TC,2) -> 51457.66
B33: =B32+0.000001 -> 5.010303 | C33: LADRILLO SILICO CALCAREO TIPO P14 RF:2 HRS H>2.6M (ALVEOLOS PARCIALMENTE LLENO) | D33: m2 | E33: 0 | F33: 134.23 | H33: =+ROUND(F33+G33*TC,2) -> 134.23 | I33: =+ROUND(E33*F33,2) -> 0 | J33: =+ROUND(E33*G33,2) -> 0 | K33: =+ROUND(I33+J33*TC,2) -> 0
B34: =B33+0.000001 -> 5.010304 | C34: LADRILLO SILICO CALCAREO TIPO P20 RF:2 HRS H>2.6M (ALVEOLOS COMPLETAMENTE LLENO) | D34: m2 | E34: 0 | F34: 244.23 | H34: =+ROUND(F34+G34*TC,2) -> 244.23 | I34: =+ROUND(E34*F34,2) -> 0 | J34: =+ROUND(E34*G34,2) -> 0 | K34: =+ROUND(I34+J34*TC,2) -> 0
B35: =B30+0.0001 -> 5.0104 | C35: ACERO DE REFUERZO | E35: 0
B36: =B35+0.000001 -> 5.010401 | C36: ACERO DE REFUERZO FY= 4200 kg/cm2 GRADO 60 PARA TABIQUERÍA | D36: kg | E36: 2801.295 | F36: 0 | G36: 0.89 | H36: =+ROUND(F36+G36*TC,2) -> 2.98 | I36: =+ROUND(E36*F36,2) -> 0 | J36: =+ROUND(E36*G36,2) -> 2493.15 | K36: =+ROUND(I36+J36*TC,2) -> 8352.05
B37: =B35+0.0001 -> 5.0105 | C37: DINTELES | E37: 0
B38: =B37+0.000001 -> 5.010501 | C38: DINTELES DE LADRILLOS SILICO CALCAREO | D38: und | E38: 50 | F38: 125 | G38: 0 | H38: =+ROUND(F38+G38*TC,2) -> 125 | I38: =+ROUND(E38*F38,2) -> 6250 | J38: =+ROUND(E38*G38,2) -> 0 | K38: =+ROUND(I38+J38*TC,2) -> 6250
B39: =B38+0.000001 -> 5.010502 | C39: DINTELES DE LADRILLO SILICO CALCAREO RF | D39: und | E39: 14 | F39: 130 | G39: 0 | H39: =+ROUND(F39+G39*TC,2) -> 130 | I39: =+ROUND(E39*F39,2) -> 1820 | J39: =+ROUND(E39*G39,2) -> 0 | K39: =+ROUND(I39+J39*TC,2) -> 1820
B40: =B37+0.0001 -> 5.0106 | C40: TRABAJOS COMPLEMENTARIOS DE TABIQUERIA | E40: 0
B41: =B40+0.000001 -> 5.010601 | C41: PASES DE MANGUERA (0.20x20M) DOBLE PLACA DE ROCA DE YESO | D41: und | E41: 7 | F41: 70 | G41: 0 | H41: =+ROUND(F41+G41*TC,2) -> 70 | I41: =+ROUND(E41*F41,2) -> 490 | J41: =+ROUND(E41*G41,2) -> 0 | K41: =+ROUND(I41+J41*TC,2) -> 490
B42: =B13+0.0001 -> 5.0102 | C42: MUROS Y TABIQUES DRYWALL | E42: 0
B43: =B42+0.000001 -> 5.010201 | C43: DINTELES DRYWALL RF. DUCTOS INST. TEC. , H=0.30M APROX. | D43: ml | E43: 0 | G43: 0 | H43: =+ROUND(F43+G43*TC,2) -> 0 | I43: =+ROUND(E43*F43,2) -> 0 | J43: =+ROUND(E43*G43,2) -> 0 | K43: =+ROUND(I43+J43*TC,2) -> 0
...

Sheet ARQ TORRE
B2: ARQUITECTURA TORRE
B4: =+'ARQ SOT'!C4 -> PRESUPUESTO | GERMANIA | REV 09
B5: =+B2 -> ARQUITECTURA TORRE
B6: =+'ARQ SOT'!C6 -> VYV INMOBILIARIA
B7: =+'ARQ SOT'!C7 -> SURQUILLO
B8: =+'ARQ SOT'!C8 -> 46090
B10: DESCRIPCION | C10: UND | D10: METRADO | E10: P.U. (PEN) | F10: P.U. (USD) | G10: P.U. TOTAL (PEN) | H10: PRECIO PARCIAL (PEN) | I10: PRECIO PARCIAL (USD) | J10: PARCIAL TOTAL (PEN) | K10: TOTAL
B11: =#REF! -> #REF!
B12: MUROS Y TABIQUES | G12: =IFERROR(IF(C12<>0,E12+F12*TC," ")," ") | H12: =IFERROR(IF($D12=0,"",$D12*E12),"") | I12: =IFERROR(IF($D12=0,"",$D12*F12),"") | J12: =IFERROR(IF(D12<>0,(D12*G12)," "),0) | K12: =SUM(H12:H106)+SUM(I12:I106)*TC -> 4783846.7
B13: MUROS Y TABIQUES SILICO CALCAREOS | G13: =IFERROR(IF(C13<>0,(E13+F13*TC)," ")," ") | H13: =IFERROR(IF($D13=0,"",$D13*E13),"") | I13: =IFERROR(IF($D13=0,"",$D13*F13),"") | J13: =IFERROR(IF(D13<>0,(D13*G13)," "),0)
B14: ALTURA < 2.60 | G14: =IFERROR(IF(C14<>0,(E14+F14*TC)," ")," ") | H14: =IFERROR(IF($D14=0,"",$D14*E14),"") | I14: =IFERROR(IF($D14=0,"",$D14*F14),"") | J14: =IFERROR(IF(D14<>0,(D14*G14)," "),0)
B15: LADRILLO SILICO CALCAREO TIPO P7 H<2.6M | C15: m2 | D15: 645.25 | E15: 104.23 | F15: 0 | G15: =+ROUND(E15+F15*TC,2) -> 104.23 | H15: =+ROUND(D15*E15,2) -> 67254.41 | I15: =+ROUND(D15*F15,2) -> 0 | J15: =+ROUND(H15+I15*TC,2) -> 67254.41
B16: LADRILLO SILICO CALCAREO TIPO P10 H<2.6M | C16: m2 | D16: 14118.78 | E16: 111.23 | F16: 0 | G16: =+ROUND(E16+F16*TC,2) -> 111.23 | H16: =+ROUND(D16*E16,2) -> 1570431.9 | I16: =+ROUND(D16*F16,2) -> 0 | J16: =+ROUND(H16+I16*TC,2) -> 1570431.9
B17: LADRILLO SILICO CALCAREO TIPO P12 H<2.6M | C17: m2 | D17: 1073.75 | E17: 117.23 | F17: 0 | G17: =+ROUND(E17+F17*TC,2) -> 117.23 | H17: =+ROUND(D17*E17,2) -> 125875.71 | I17: =+ROUND(D17*F17,2) -> 0 | J17: =+ROUND(H17+I17*TC,2) -> 125875.71
B18: LADRILLO SILICO CALCAREO TIPO P14 H<2.6M | C18: m2 | D18: 120.89 | E18: 125.23 | F18: 0 | G18: =+ROUND(E18+F18*TC,2) -> 125.23 | H18: =+ROUND(D18*E18,2) -> 15139.05 | I18: =+ROUND(D18*F18,2) -> 0 | J18: =+ROUND(H18+I18*TC,2) -> 15139.05
B19: LADRILLO SILICO CALCAREO TIPO P20 H<2.6M | C19: m2 | E19: 206.23 | F19: 0 | G19: =+ROUND(E19+F19*TC,2) -> 206.23 | H19: =+ROUND(D19*E19,2) -> 0 | I19: =+ROUND(D19*F19,2) -> 0 | J19: =+ROUND(H19+I19*TC,2) -> 0
B20: LADRILLO SILICO CALCAREO TIPO P25 H<2.6M | C20: m2 | E20: 220.23 | F20: 0 | G20: =+ROUND(E20+F20*TC,2) -> 220.23 | H20: =+ROUND(D20*E20,2) -> 0 | I20: =+ROUND(D20*F20,2) -> 0 | J20: =+ROUND(H20+I20*TC,2) -> 0
B21: LADRILLO SILICO CALCAREO TIPO P30 H<2.6M | C21: m2 | E21: 220.23 | F21: 0 | G21: =+ROUND(E21+F21*TC,2) -> 220.23 | H21: =+ROUND(D21*E21,2) -> 0 | I21: =+ROUND(D21*F21,2) -> 0 | J21: =+ROUND(H21+I21*TC,2) -> 0
B22: LADRILLO SILICO CALCAREO TIPO P40 H<2.6M | C22: m2 | E22: 220.23 | F22: 0 | G22: =+ROUND(E22+F22*TC,2) -> 220.23 | H22: =+ROUND(D22*E22,2) -> 0 | I22: =+ROUND(D22*F22,2) -> 0 | J22: =+ROUND(H22+I22*TC,2) -> 0
B23: ALTURA > 2.60 | J23: =+ROUND(H23+I23*TC,2) -> 0
B24: LADRILLO SILICO CALCAREO TIPO P7 H>2.6M | C24: m2 | D24: 44 | E24: 113.23 | F24: 0 | G24: =+ROUND(E24+F24*TC,2) -> 113.23 | H24: =+ROUND(D24*E24,2) -> 4982.12 | I24: =+ROUND(D24*F24,2) -> 0 | J24: =+ROUND(H24+I24*TC,2) -> 4982.12
B25: LADRILLO SILICO CALCAREO TIPO P10 H>2.6M | C25: m2 | D25: 388.45 | E25: 120.23 | F25: 0 | G25: =+ROUND(E25+F25*TC,2) -> 120.23 | H25: =+ROUND(D25*E25,2) -> 46703.34 | I25: =+ROUND(D25*F25,2) -> 0 | J25: =+ROUND(H25+I25*TC,2) -> 46703.34
B26: LADRILLO SILICO CALCAREO TIPO P12 H>2.6M | C26: m2 | D26: 448.35 | E26: 126.23 | F26: 0 | G26: =+ROUND(E26+F26*TC,2) -> 126.23 | H26: =+ROUND(D26*E26,2) -> 56595.22 | I26: =+ROUND(D26*F26,2) -> 0 | J26: =+ROUND(H26+I26*TC,2) -> 56595.22
B27: LADRILLO SILICO CALCAREO TIPO P14 H>2.6M | C27: m2 | E27: 134.23 | F27: 0 | G27: =+ROUND(E27+F27*TC,2) -> 134.23 | H27: =+ROUND(D27*E27,2) -> 0 | I27: =+ROUND(D27*F27,2) -> 0 | J27: =+ROUND(H27+I27*TC,2) -> 0
B28: LADRILLO SILICO CALCAREO TIPO P20 H>2.6M | C28: m2 | E28: 224.23 | F28: 0 | G28: =+ROUND(E28+F28*TC,2) -> 224.23 | H28: =+ROUND(D28*E28,2) -> 0 | I28: =+ROUND(D28*F28,2) -> 0 | J28: =+ROUND(H28+I28*TC,2) -> 0
B29: LADRILLO SILICO CALCAREO TIPO P25 H>2.6M | C29: m2 | E29: 238.23 | F29: 0 | G29: =+ROUND(E29+F29*TC,2) -> 238.23 | H29: =+ROUND(D29*E29,2) -> 0 | I29: =+ROUND(D29*F29,2) -> 0 | J29: =+ROUND(H29+I29*TC,2) -> 0
B30: LADRILLO SILICO CALCAREO TIPO P55 H>2.6M | C30: m2 | E30: 0 | F30: 0 | G30: =+ROUND(E30+F30*TC,2) -> 0 | H30: =+ROUND(D30*E30,2) -> 0 | I30: =+ROUND(D30*F30,2) -> 0 | J30: =+ROUND(H30+I30*TC,2) -> 0
B31: CORTAFUEGO < 2.60 | J31: =+ROUND(H31+I31*TC,2) -> 0
B32: LADRILLO SILICO CALCAREO TIPO P10 RF:2 HRS H<2.6M (ALVEOLOS COMPLETAMENTE LLENO) | C32: m2 | D32: 1.34 | E32: 121.23 | F32: 0 | G32: =+ROUND(E32+F32*TC,2) -> 121.23 | H32: =+ROUND(D32*E32,2) -> 162.45 | I32: =+ROUND(D32*F32,2) -> 0 | J32: =+ROUND(H32+I32*TC,2) -> 162.45
B33: LADRILLO SILICO CALCAREO TIPO P12 RF:2 HRS H<2.6M (ALVEOLOS PARCIALMENTE LLENO) | C33: m2 | D33: 11970.5 | E33: 117.23 | F33: 0 | G33: =+ROUND(E33+F33*TC,2) -> 117.23 | H33: =+ROUND(D33*E33,2) -> 1403301.7 | I33: =+ROUND(D33*F33,2) -> 0 | J33: =+ROUND(H33+I33*TC,2) -> 1403301.7
B34: LADRILLO SILICO CALCAREO TIPO P14 RF:2 HRS H<2.6M (ALVEOLOS PARCIALMENTE LLENO) | C34: m2 | D34: 741.96 | E34: 125.23 | F34: 0 | G34: =+ROUND(E34+F34*TC,2) -> 125.23 | H34: =+ROUND(D34*E34,2) -> 92915.65 | I34: =+ROUND(D34*F34,2) -> 0 | J34: =+ROUND(H34+I34*TC,2) -> 92915.65
B35: LADRILLO SILICO CALCAREO TIPO P20 RF:2 HRS H<2.6M (ALVEOLOS PARCIALMENTE LLENO) | C35: m2 | E35: 226.23 | F35: 0 | G35: =+ROUND(E35+F35*TC,2) -> 226.23 | H35: =+ROUND(D35*E35,2) -> 0 | I35: =+ROUND(D35*F35,2) -> 0 | J35: =+ROUND(H35+I35*TC,2) -> 0
B36: LADRILLO SILICO CALCAREO TIPO P30 RF:2 HRS H<2.6M (ALVEOLOS PARCIALMENTE LLENO) | C36: m2 | E36: 220.23 | F36: 0 | G36: =+ROUND(E36+F36*TC,2) -> 220.23 | H36: =+ROUND(D36*E36,2) -> 0 | I36: =+ROUND(D36*F36,2) -> 0 | J36: =+ROUND(H36+I36*TC,2) -> 0
B37: LADRILLO SILICO CALCAREO TIPO P35 RF:2 HRS H<2.6M (ALVEOLOS PARCIALMENTE LLENO) | C37: m2 | E37: 220.23 | F37: 0 | G37: =+ROUND(E37+F37*TC,2) -> 220.23 | H37: =+ROUND(D37*E37,2) -> 0 | I37: =+ROUND(D37*F37,2) -> 0 | J37: =+ROUND(H37+I37*TC,2) -> 0
B38: LADRILLO SILICO CALCAREO TIPO P40 RF:2 HRS H<2.6M (ALVEOLOS PARCIALMENTE LLENO) | C38: m2 | E38: 220.23 | F38: 0 | G38: =+ROUND(E38+F38*TC,2) -> 220.23 | H38: =+ROUND(D38*E38,2) -> 0 | I38: =+ROUND(D38*F38,2) -> 0 | J38: =+ROUND(H38+I38*TC,2) -> 0
B39: LADRILLO SILICO CALCAREO TIPO P45 RF:2 HRS H<2.6M (ALVEOLOS PARCIALMENTE LLENO) | C39: m2 | E39: 220.23 | F39: 0 | G39: =+ROUND(E39+F39*TC,2) -> 220.23 | H39: =+ROUND(D39*E39,2) -> 0 | I39: =+ROUND(D39*F39,2) -> 0 | J39: =+ROUND(H39+I39*TC,2) -> 0
B40: LADRILLO SILICO CALCAREO TIPO P50 RF:2 HRS H<2.6M (ALVEOLOS PARCIALMENTE LLENO) | C40: m2 | E40: 220.23 | F40: 0 | G40: =+ROUND(E40+F40*TC,2) -> 220.23 | H40: =+ROUND(D40*E40,2) -> 0 | I40: =+ROUND(D40*F40,2) -> 0 | J40: =+ROUND(H40+I40*TC,2) -> 0
B41: CORTAFUEGO > 2.60 | J41: =+ROUND(H41+I41*TC,2) -> 0
B42: LADRILLO SILICO CALCAREO TIPO P7 RF:2 HRS H>2.6M (ALVEOLOS COMPLETAMENTE LLENO) | C42: m2 | E42: 123.23 | F42: 0 | G42: =+ROUND(E42+F42*TC,2) -> 123.23 | H42: =+ROUND(D42*E42,2) -> 0 | I42: =+ROUND(D42*F42,2) -> 0 | J42: =+ROUND(H42+I42*TC,2) -> 0
B43: LADRILLO SILICO CALCAREO TIPO P10 RF:2 HRS H>2.6M (ALVEOLOS COMPLETAMENTE LLENO) | C43: m2 | E43: 130.23 | F43: 0 | G43: =+ROUND(E43+F43*TC,2) -> 130.23 | H43: =+ROUND(D43*E43,2) -> 0 | I43: =+ROUND(D43*F43,2) -> 0 | J43: =+ROUND(H43+I43*TC,2) -> 0
...

Sheet OFICINAS
B2: DESCRIPCION | C2: UND | D2: METRADO | E2: P.U. (PEN) | F2: P.U. (USD) | G2: P.U. TOTAL (PEN) | H2: PRECIO PARCIAL (PEN) | I2: PRECIO PARCIAL (USD) | J2: PARCIAL TOTAL (PEN) | K2: TOTAL
B3: TABIQUERÍA | K3: =SUM(J4:J7) -> 85652.84
B4: =+'ARQ TORRE'!B44 -> LADRILLO SILICO CALCAREO TIPO P12 RF:2 HRS H>2.6M (ALVEOLOS PARCIALMENTE LLENO) | C4: m2 | D4: 528.65 | E4: 126.23 | G4: =+ROUND(E4+F4*TC,2) -> 126.23 | H4: =+ROUND(D4*E4,2) -> 66731.49 | I4: =+ROUND(D4*F4,2) -> 0 | J4: =+ROUND(H4+I4*TC,2) -> 66731.49
B5: LADRILLO SILICO CALCAREO TIPO P12 H>2.6M | C5: m2 | D5: 127.42 | E5: 126.23 | G5: =+ROUND(E5+F5*TC,2) -> 126.23 | H5: =+ROUND(D5*E5,2) -> 16084.23 | I5: =+ROUND(D5*F5,2) -> 0 | J5: =+ROUND(H5+I5*TC,2) -> 16084.23
B6: ACERO DE REFUERZO | G6: =+ROUND(E6+F6*TC,2) -> 0 | H6: =+ROUND(D6*E6,2) -> 0 | I6: =+ROUND(D6*F6,2) -> 0 | J6: =+ROUND(H6+I6*TC,2) -> 0
B7: ACERO DE REFUERZO FY= 4200 kg/cm2 GRADO 60 PARA TABIQUERÍA | C7: kg | D7: 951.57 | F7: 0.89 | G7: =+ROUND(E7+F7*TC,2) -> 2.98 | H7: =+ROUND(D7*E7,2) -> 0 | I7: =+ROUND(D7*F7,2) -> 846.9 | J7: =+ROUND(H7+I7*TC,2) -> 2837.12
B8: PUERTAS CONTRAPLACADAS | G8: =+ROUND(E8+F8*TC,2) -> 0 | H8: =+ROUND(D8*E8,2) -> 0 | I8: =+ROUND(D8*F8,2) -> 0 | J8: =+ROUND(H8+I8*TC,2) -> 0 | K8: =SUM(J9:J10) -> 2733.9
B9: PS.03(0.8x2.2)P. CONTRAPL. | C9: und | D9: 1 | E9: 124 | F9: 99 | G9: =+ROUND(E9+F9*TC,2) -> 455.65 | H9: =+ROUND(D9*E9,2) -> 124 | I9: =+ROUND(D9*F9,2) -> 99 | J9: =+ROUND(H9+I9*TC,2) -> 455.65
B10: PS.05(0.8x2.2)P. CONTRAPL. | C10: und | D10: 5 | E10: 124 | F10: 99 | G10: =+ROUND(E10+F10*TC,2) -> 455.65 | H10: =+ROUND(D10*E10,2) -> 620 | I10: =+ROUND(D10*F10,2) -> 495 | J10: =+ROUND(H10+I10*TC,2) -> 2278.25
B11: MAMPARAS | G11: =+ROUND(E11+F11*TC,2) -> 0 | H11: =+ROUND(D11*E11,2) -> 0 | I11: =+ROUND(D11*F11,2) -> 0 | J11: =+ROUND(H11+I11*TC,2) -> 0 | K11: =SUM(J12:J50) -> 179499.96
B12: MZ.11 (3.9x3.7)MAMP DE VIDRIO , MARCO ALUMN | C12: und | D12: 1 | E12: 7212.4131 | F12: 0 | G12: =+ROUND(E12+F12*TC,2) -> 7212.41 | H12: =+ROUND(D12*E12,2) -> 7212.41 | I12: =+ROUND(D12*F12,2) -> 0 | J12: =+ROUND(H12+I12*TC,2) -> 7212.41
B13: MZ.12 (4.26x3.7)MAMP DE VIDRIO , MARCO ALUMN | C13: und | D13: 1 | E13: 7878.1709 | F13: 0 | G13: =+ROUND(E13+F13*TC,2) -> 7878.17 | H13: =+ROUND(D13*E13,2) -> 7878.17 | I13: =+ROUND(D13*F13,2) -> 0 | J13: =+ROUND(H13+I13*TC,2) -> 7878.17
B14: MZ.13 (4.36x3.7)MAMP DE VIDRIO , MARCO ALUMN | C14: und | D14: 1 | E14: 8063.1093 | F14: 0 | G14: =+ROUND(E14+F14*TC,2) -> 8063.11 | H14: =+ROUND(D14*E14,2) -> 8063.11 | I14: =+ROUND(D14*F14,2) -> 0 | J14: =+ROUND(H14+I14*TC,2) -> 8063.11
B15: MZ.14 (5.46x3.7)MAMP DE VIDRIO , MARCO ALUMN | C15: und | D15: 1 | E15: 10097.38 | F15: 0 | G15: =+ROUND(E15+F15*TC,2) -> 10097.38 | H15: =+ROUND(D15*E15,2) -> 10097.38 | I15: =+ROUND(D15*F15,2) -> 0 | J15: =+ROUND(H15+I15*TC,2) -> 10097.38
B16: MZ.15 (3.6x3.7)MAMP DE VIDRIO , MARCO ALUMN | C16: und | D16: 1 | E16: 8773.8933 | F16: 0 | G16: =+ROUND(E16+F16*TC,2) -> 8773.89 | H16: =+ROUND(D16*E16,2) -> 8773.89 | I16: =+ROUND(D16*F16,2) -> 0 | J16: =+ROUND(H16+I16*TC,2) -> 8773.89
B17: MZ.16 (4.78x3.7)MAMP DE VIDRIO , MARCO ALUMN | C17: und | D17: 1 | E17: 8839.83 | F17: 0 | G17: =+ROUND(E17+F17*TC,2) -> 8839.83 | H17: =+ROUND(D17*E17,2) -> 8839.83 | I17: =+ROUND(D17*F17,2) -> 0 | J17: =+ROUND(H17+I17*TC,2) -> 8839.83
B18: MZ.17 (4.42x3.41)MAMP DE VIDRIO , MARCO ALUMN | C18: und | D18: 1 | E18: 8174.0723 | F18: 0 | G18: =+ROUND(E18+F18*TC,2) -> 8174.07 | H18: =+ROUND(D18*E18,2) -> 8174.07 | I18: =+ROUND(D18*F18,2) -> 0 | J18: =+ROUND(H18+I18*TC,2) -> 8174.07
B19: MZ.18' (2.78x3.41)MAMP DE VIDRIO , MARCO ALUMN | C19: und | D19: 1 | E19: 4373.2811 | F19: 0 | G19: =+ROUND(E19+F19*TC,2) -> 4373.28 | H19: =+ROUND(D19*E19,2) -> 4373.28 | I19: =+ROUND(D19*F19,2) -> 0 | J19: =+ROUND(H19+I19*TC,2) -> 4373.28
B20: MZ.18 (2.59x3.41)MAMP DE VIDRIO , MARCO ALUMN | C20: und | D20: 1 | E20: 2583.444 | F20: 0 | G20: =+ROUND(E20+F20*TC,2) -> 2583.44 | H20: =+ROUND(D20*E20,2) -> 2583.44 | I20: =+ROUND(D20*F20,2) -> 0 | J20: =+ROUND(H20+I20*TC,2) -> 2583.44
B21: MZ.19 (1.53x3.41)MAMP DE VIDRIO , MARCO ALUMN | C21: und | D21: 1 | E21: 9135.7212 | F21: 0 | G21: =+ROUND(E21+F21*TC,2) -> 9135.72 | H21: =+ROUND(D21*E21,2) -> 9135.72 | I21: =+ROUND(D21*F21,2) -> 0 | J21: =+ROUND(H21+I21*TC,2) -> 9135.72
B22: MZ.20 (4.94x3.7)MAMP DE VIDRIO , MARCO ALUMN | C22: und | D22: 1 | E22: 2780.4351 | F22: 0 | G22: =+ROUND(E22+F22*TC,2) -> 2780.44 | H22: =+ROUND(D22*E22,2) -> 2780.44 | I22: =+ROUND(D22*F22,2) -> 0 | J22: =+ROUND(H22+I22*TC,2) -> 2780.44
B23: MZ.21 (1.82x3.7)MAMP DE VIDRIO , MARCO ALUMN | C23: und | D23: 1 | E23: 6158.295 | F23: 0 | G23: =+ROUND(E23+F23*TC,2) -> 6158.29 | H23: =+ROUND(D23*E23,2) -> 6158.29 | I23: =+ROUND(D23*F23,2) -> 0 | J23: =+ROUND(H23+I23*TC,2) -> 6158.29
... B28: MZ.26 (3.25x3.52)MAMP DE VIDRIO , MARCO ALUMN | C28: und | D28: 1 | E28: 5012.6907 | F28: 0 | G28: =+ROUND(E28+F28*TC,2) -> 5012.69 | H28: =+ROUND(D28*E28,2) -> 5012.69 | I28: =+ROUND(D28*F28,2) -> 0 | J28: =+ROUND(H28+I28*TC,2) -> 5012.69
B29: PUERTAS VENTANAS | F29: 1 | G29: =+ROUND(E29+F29*TC,2) -> 3.35 | H29: =+ROUND(D29*E29,2) -> 0 | I29: =+ROUND(D29*F29,2) -> 0 | J29: =+ROUND(H29+I29*TC,2) -> 0
B30: PZ.01 (1.05x2.1)P. CONTRAPL. BATIENTE | C30: und | D30: 2 | E30: 1923.728 | F30: 0 | G30: =+ROUND(E30+F30*TC,2) -> 1923.73 | H30: =+ROUND(D30*E30,2) -> 3847.46 | I30: =+ROUND(D30*F30,2) -> 0 | J30: =+ROUND(H30+I30*TC,2) -> 3847.46
B31: PZ.02 (1.5x2.1)P. CONTRAPL. BATIENTE | C31: und | E31: 2451.0891 | F31: 0 | G31: =+ROUND(E31+F31*TC,2) -> 2451.09 | H31: =+ROUND(D31*E31,2) -> 0 | I31: =+ROUND(D31*F31,2) -> 0 | J31: =+ROUND(H31+I31*TC,2) -> 0
B32: PZ.04 (0.8x2.1)P. CONTRAPL. BATIENTE | C32: und | D32: 2 | E32: 1465.6982 | F32: 0 | G32: =+ROUND(E32+F32*TC,2) -> 1465.7 | H32: =+ROUND(D32*E32,2) -> 2931.4 | I32: =+ROUND(D32*F32,2) -> 0 | J32: =+ROUND(H32+I32*TC,2) -> 2931.4
B33: PZ.06 (1.06x2.1)P. CONTRAPL. BATIENTE | C33: und | D33: 1 | E33: 1960.3675 | F33: 0 | G33: =+ROUND(E33+F33*TC,2) -> 1960.37 | H33: =+ROUND(D33*E33,2) -> 1960.37 | I33: =+ROUND(D33*F33,2) -> 0 | J33: =+ROUND(H33+I33*TC,2) -> 1960.37
B34: PZ.07 (1.1x2.1)P. CONTRAPL. BATIENTE | C34: und | D34: 1 | E34: 2015.337 | F34: 0 | G34: =+ROUND(E34+F34*TC,2) -> 2015.34 | H34: =+ROUND(D34*E34,2) -> 2015.34 | I34: =+ROUND(D34*F34,2) -> 0 | J34: =+ROUND(H34+I34*TC,2) -> 2015.34
B35: PZ.08 (5.52x2.1)P. CONTRAPL. BATIENTE | C35: und | D35: 1 | E35: 7926.6583 | F35: 0 | G35: =+ROUND(E35+F35*TC,2) -> 7926.66 | H35: =+ROUND(D35*E35,2) -> 7926.66 | I35: =+ROUND(D35*F35,2) -> 0 | J35: =+ROUND(H35+I35*TC,2) -> 7926.66
B36: PZ.09 (4.44x2.1)P. CONTRAPL. BATIENTE | C36: und | D36: 1 | E36: 5801.3925 | F36: 0 | G36: =+ROUND(E36+F36*TC,2) -> 5801.39 | H36: =+ROUND(D36*E36,2) -> 5801.39 | I36: =+ROUND(D36*F36,2) -> 0 | J36: =+ROUND(H36+I36*TC,2) -> 5801.39
B37: PZ.10 (2.63x2.1)P. CONTRAPL. BATIENTE | C37: und | D37: 1 | E37: 4297.5649 | F37: 0 | G37: =+ROUND(E37+F37*TC,2) -> 4297.56 | H37: =+ROUND(D37*E37,2) -> 4297.56 | I37: =+ROUND(D37*F37,2) -> 0 | J37: =+ROUND(H37+I37*TC,2) -> 4297.56
B38: PZ.11 (2.63x2.1)P. CONTRAPL. BATIENTE | C38: und | D38: 1 | E38: 5947.9608 | F38: 0 | G38: =+ROUND(E38+F38*TC,2) -> 5947.96 | H38: =+ROUND(D38*E38,2) -> 5947.96 | I38: =+ROUND(D38*F38,2) -> 0 | J38: =+ROUND(H38+I38*TC,2) -> 5947.96
B39: PZ.12 (6.98x2.1)P. CONTRAPL. BATIENTE | C39: und | D39: 1 | E39: 8640.6885 | F39: 0 | G39: =+ROUND(E39+F39*TC,2) -> 8640.69 | H39: =+ROUND(D39*E39,2) -> 8640.69 | I39: =+ROUND(D39*F39,2) -> 0 | J39: =+ROUND(H39+I39*TC,2) -> 8640.69
B40: PZ.13 (1.52x2.2)P. CONTRAPL. BATIENTE | C40: und | D40: 1 | E40: 2483.7657 | F40: 0 | G40: =+ROUND(E40+F40*TC,2) -> 2483.77 | H40: =+ROUND(D40*E40,2) -> 2483.77 | I40: =+ROUND(D40*F40,2) -> 0 | J40: =+ROUND(H40+I40*TC,2) -> 2483.77
B41: PZ.14 (1.73x2.2)P. CONTRAPL. BATIENTE | C41: und | D41: 1 | E41: 3083.9143 | F41: 0 | G41: =+ROUND(E41+F41*TC,2) -> 3083.91 | H41: =+ROUND(D41*E41,2) -> 3083.91 | I41: =+ROUND(D41*F41,2) -> 0 | J41: =+ROUND(H41+I41*TC,2) -> 3083.91
B42: PZ.15 (6.69x2.2)P. CONTRAPL. BATIENTE | C42: und | D42: 1 | E42: 9606.7612 | F42: 0 | G42: =+ROUND(E42+F42*TC,2) -> 9606.76 | H42: =+ROUND(D42*E42,2) -> 9606.76 | I42: =+ROUND(D42*F42,2) -> 0 | J42: =+ROUND(H42+I42*TC,2) -> 9606.76
B43: PZ.16 (4.61x2.2)P. CONTRAPL. BATIENTE | C43: und | D43: 1 | E43: 5250.2741 | F43: 0 | G43: =+ROUND(E43+F43*TC,2) -> 5250.27 | H43: =+ROUND(D43*E43,2) -> 5250.27 | I43: =+ROUND(D43*F43,2) -> 0 | J43: =+ROUND(H43+I43*TC,2) -> 5250.27
B44: PUERTAS MELAMINE
B45: PC.04 (1.25 x 2.10m) | C45: und | D45: 1 | E45: 600 | F45: 0 | G45: =+ROUND(E45+F45*TC,2) -> 600 | H45: =+ROUND(D45*E45,2) -> 600 | I45: =+ROUND(D45*F45,2) -> 0 | J45: =+ROUND(H45+I45*TC,2) -> 600
...

Sheet CTO BOMBAS - ACIySPC ACT
A2: CUARTO DE BOMBAS - ACI
H3: T.C | I3: 3.35
A4: Presupuesto | B4: GERMANIA
A5: Subpresupuesto | B5: EQUIPAMIENTO
A6: Cliente | B6: : V&V Bravo S.A.C | F6: Costo al | G6: 46133
A7: Lugar
A8: ITEM | B8: DESCRIPCION | C8: UND | D8: CANTIDAD | E8: P.U (S/.) | F8: P.U ($.) | G8: PARCIAL (S/.) | H8: PARCIAL ($) | I8: TOTAL
